Workbook
Name Slicer_District: #N/A
Name Slicer_District1: #N/A
Name Slicer_District11: #N/A
Name Slicer_District2: #N/A
Name Slicer_District3: #N/A
Name Slicer_District4: #N/A
Name Slicer_District5: #N/A

Sheet Sunday
B2: Minimum Hours WTD - KEY | E2: District | F2: Cars | G2: LHC | H2: Allowed Hours | I2: Actual Hours | J2: Hours Variance
B3: Sunday | C3: 20 | E3: Baton Rouge North | F3: =SUM(G15:G22) -> 75 | G3: 0.79 | H3: =SUM(I15:I22) -> 59.25 | I3: =SUM(K15:K22) -> 123.8 | J3: =SUM(L15:L22) -> -16.2
B4: Monday | C4: 45.3 | E4: Baton Rouge South | F4: =SUM(G23:G29) -> 69 | G4: 0.79 | H4: =SUM(I23:I29) -> 54.51 | I4: =SUM(K23:K29) -> 116.16 | J4: =SUM(L23:L29) -> -23.84
B5: Tuesday | C5: 70.6 | E5: Gulf Coast North | F5: =SUM(G30:G38) -> 206 | G5: 0.79 | H5: =SUM(I30:I38) -> 162.74 | I5: =SUM(K30:K38) -> 202 | J5: =SUM(L30:L38) -> -2.53
B6: Wednesday | C6: 95.93 | E6: Lafayette | F6: =SUM(G39:G46) -> 204 | G6: 0.79 | H6: =SUM(I39:I46) -> 161.16 | I6: =SUM(K39:K46) -> 164.31 | J6: =SUM(L39:L46) -> -24.96
B7: Thursday | C7: 121.23 | E7: Gulf Coast West | F7: =SUM(G47:G53) -> 97 | G7: 0.79 | H7: =SUM(I47:I53) -> 76.63 | I7: =SUM(K47:K53) -> 113.51 | J7: =SUM(L47:L53) -> -26.49
B8: Friday | C8: 146.53 | E8: Nola North | F8: =SUM(G54:G62) -> 258 | G8: 0.79 | H8: =SUM(I54:I62) -> 203.82 | I8: =SUM(K54:K62) -> 208.55 | J8: =SUM(L54:L62) -> -6.54
B9: Saturday | C9: 171.8 | E9: Nola South | F9: =SUM(G63:G71) -> 203 | G9: 0.79 | H9: =SUM(I63:I71) -> 160.37 | I9: =SUM(K63:K71) -> 208.8 | J9: =SUM(L63:L71) -> 8.22
E10: Region | F10: =SUM(F3:F9) -> 1112 | G10: 0.79 | H10: =SUM(H3:H9) -> 878.48 | I10: =SUM(I3:I9) -> 1137.13 | J10: =SUM(J3:J9) -> -92.34
E14: District | F14: Store | G14: Cars WTD (EDIT) | H14: LHC | I14: Allowed Hours | J14: Adj Allowed Hrs | K14: Actual Hours (EDIT) | L14: Hours Variance
E15: Baton Rouge North | F15: 17 | G15: 12 | H15: 0.79 | I15: =Table1[[#This Row],[LHC]]*Table1[[#This Row],[Cars WTD (EDIT)]] -> 9.48 | J15: {=_xlfn.IFS(Table1[[#This Row],[Allowed Hours]]=0,0,Table1[[#This Row],[Allowed Hours]]<20,20,Table1[[#This Row],[Allowed Hours]]>20,Table1[[#This Row],[Allowed Hours]])} -> 20 | K15: 16.98 | L15: =K15-Table1[[#This Row],[Adj Allowed Hrs]] -> -3.02
E16: Baton Rouge North | F16: 22 | G16: 19 | H16: 0.79 | I16: =Table1[[#This Row],[LHC]]*Table1[[#This Row],[Cars WTD (EDIT)]] -> 15.01 | J16: {=_xlfn.IFS(Table1[[#This Row],[Allowed Hours]]=0,0,Table1[[#This Row],[Allowed Hours]]<20,20,Table1[[#This Row],[Allowed Hours]]>20,Table1[[#This Row],[Allowed Hours]])} -> 20 | K16: 22.79 | L16: =K16-Table1[[#This Row],[Adj Allowed Hrs]] -> 2.79
E17: Baton Rouge North | F17: 641 | G17: 9 | H17: 0.79 | I17: =Table1[[#This Row],[LHC]]*Table1[[#This Row],[Cars WTD (EDIT)]] -> 7.11 | J17: {=_xlfn.IFS(Table1[[#This Row],[Allowed Hours]]=0,0,Table1[[#This Row],[Allowed Hours]]<20,20,Table1[[#This Row],[Allowed Hours]]>20,Table1[[#This Row],[Allowed Hours]])} -> 20 | K17: 16.75 | L17: =K17-Table1[[#This Row],[Adj Allowed Hrs]] -> -3.25
E18: Baton Rouge North | F18: 717 | G18: 18 | H18: 0.79 | I18: =Table1[[#This Row],[LHC]]*Table1[[#This Row],[Cars WTD (EDIT)]] -> 14.22 | J18: {=_xlfn.IFS(Table1[[#This Row],[Allowed Hours]]=0,0,Table1[[#This Row],[Allowed Hours]]<20,20,Table1[[#This Row],[Allowed Hours]]>20,Table1[[#This Row],[Allowed Hours]])} -> 20 | K18: 22.96 | L18: =K18-Table1[[#This Row],[Adj Allowed Hrs]] -> 2.96
E19: Baton Rouge North | F19: 843 | G19: 2 | H19: 0.79 | I19: =Table1[[#This Row],[LHC]]*Table1[[#This Row],[Cars WTD (EDIT)]] -> 1.58 | J19: {=_xlfn.IFS(Table1[[#This Row],[Allowed Hours]]=0,0,Table1[[#This Row],[Allowed Hours]]<20,20,Table1[[#This Row],[Allowed Hours]]>20,Table1[[#This Row],[Allowed Hours]])} -> 20 | K19: 15.43 | L19: =K19-Table1[[#This Row],[Adj Allowed Hrs]] -> -4.57
E20: Baton Rouge North | F20: 881 | G20: 9 | H20: 0.79 | I20: =Table1[[#This Row],[LHC]]*Table1[[#This Row],[Cars WTD (EDIT)]] -> 7.11 | J20: {=_xlfn.IFS(Table1[[#This Row],[Allowed Hours]]=0,0,Table1[[#This Row],[Allowed Hours]]<20,20,Table1[[#This Row],[Allowed Hours]]>20,Table1[[#This Row],[Allowed Hours]])} -> 20 | K20: 12.92 | L20: =K20-Table1[[#This Row],[Adj Allowed Hrs]] -> -7.08
E21: Baton Rouge North | F21: 953 | G21: 6 | H21: 0.79 | I21: =Table1[[#This Row],[LHC]]*Table1[[#This Row],[Cars WTD (EDIT)]] -> 4.74 | J21: {=_xlfn.IFS(Table1[[#This Row],[Allowed Hours]]=0,0,Table1[[#This Row],[Allowed Hours]]<20,20,Table1[[#This Row],[Allowed Hours]]>20,Table1[[#This Row],[Allowed Hours]])} -> 20 | K21: 15.97 | L21: =K21-Table1[[#This Row],[Adj Allowed Hrs]] -> -4.03
E22: Baton Rouge North | F22: 3040 | H22: 0.79 | I22: =Table1[[#This Row],[LHC]]*Table1[[#This Row],[Cars WTD (EDIT)]] -> 0 | J22: {=_xlfn.IFS(Table1[[#This Row],[Allowed Hours]]=0,0,Table1[[#This Row],[Allowed Hours]]<20,20,Table1[[#This Row],[Allowed Hours]]>20,Table1[[#This Row],[Allowed Hours]])} -> 0 | L22: =K22-Table1[[#This Row],[Adj Allowed Hrs]] -> 0
E23: Baton Rouge South | F23: 18 | G23: 14 | H23: 0.79 | I23: =Table1[[#This Row],[LHC]]*Table1[[#This Row],[Cars WTD (EDIT)]] -> 11.06 | J23: {=_xlfn.IFS(Table1[[#This Row],[Allowed Hours]]=0,0,Table1[[#This Row],[Allowed Hours]]<20,20,Table1[[#This Row],[Allowed Hours]]>20,Table1[[#This Row],[Allowed Hours]])} -> 20 | K23: 11.34 | L23: =K23-Table1[[#This Row],[Adj Allowed Hrs]] -> -8.66
E24: Baton Rouge South | F24: 19 | G24: 6 | H24: 0.79 | I24: =Table1[[#This Row],[LHC]]*Table1[[#This Row],[Cars WTD (EDIT)]] -> 4.74 | J24: {=_xlfn.IFS(Table1[[#This Row],[Allowed Hours]]=0,0,Table1[[#This Row],[Allowed Hours]]<20,20,Table1[[#This Row],[Allowed Hours]]>20,Table1[[#This Row],[Allowed Hours]])} -> 20 | K24: 18.61 | L24: =K24-Table1[[#This Row],[Adj Allowed Hrs]] -> -1.39
E25: Baton Rouge South | F25: 282 | G25: 6 | H25: 0.79 | I25: =Table1[[#This Row],[LHC]]*Table1[[#This Row],[Cars WTD (EDIT)]] -> 4.74 | J25: {=_xlfn.IFS(Table1[[#This Row],[Allowed Hours]]=0,0,Table1[[#This Row],[Allowed Hours]]<20,20,Table1[[#This Row],[Allowed Hours]]>20,Table1[[#This Row],[Allowed Hours]])} -> 20 | K25: 7.56 | L25: =K25-Table1[[#This Row],[Adj Allowed Hrs]] -> -12.44
E26: Baton Rouge South | F26: 447 | G26: 7 | H26: 0.79 | I26: =Table1[[#This Row],[LHC]]*Table1[[#This Row],[Cars WTD (EDIT)]] -> 5.53 | J26: {=_xlfn.IFS(Table1[[#This Row],[Allowed Hours]]=0,0,Table1[[#This Row],[Allowed Hours]]<20,20,Table1[[#This Row],[Allowed Hours]]>20,Table1[[#This Row],[Allowed Hours]])} -> 20 | K26: 16.73 | L26: =K26-Table1[[#This Row],[Adj Allowed Hrs]] -> -3.27
E27: Baton Rouge South | F27: 448 | G27: 21 | H27: 0.79 | I27: =Table1[[#This Row],[LHC]]*Table1[[#This Row],[Cars WTD (EDIT)]] -> 16.59 | J27: {=_xlfn.IFS(Table1[[#This Row],[Allowed Hours]]=0,0,Table1[[#This Row],[Allowed Hours]]<20,20,Table1[[#This Row],[Allowed Hours]]>20,Table1[[#This Row],[Allowed Hours]])} -> 20 | K27: 24.31 | L27: =K27-Table1[[#This Row],[Adj Allowed Hrs]] -> 4.31
E28: Baton Rouge South | F28: 531 | G28: 6 | H28: 0.79 | I28: =Table1[[#This Row],[LHC]]*Table1[[#This Row],[Cars WTD (EDIT)]] -> 4.74 | J28: {=_xlfn.IFS(Table1[[#This Row],[Allowed Hours]]=0,0,Table1[[#This Row],[Allowed Hours]]<20,20,Table1[[#This Row],[Allowed Hours]]>20,Table1[[#This Row],[Allowed Hours]])} -> 20 | K28: 18.5 | L28: =K28-Table1[[#This Row],[Adj Allowed Hrs]] -> -1.5
E29: Baton Rouge South | F29: 832 | G29: 9 | H29: 0.79 | I29: =Table1[[#This Row],[LHC]]*Table1[[#This Row],[Cars WTD (EDIT)]] -> 7.11 | J29: {=_xlfn.IFS(Table1[[#This Row],[Allowed Hours]]=0,0,Table1[[#This Row],[Allowed Hours]]<20,20,Table1[[#This Row],[Allowed Hours]]>20,Table1[[#This Row],[Allowed Hours]])} -> 20 | K29: 19.11 | L29: =K29-Table1[[#This Row],[Adj Allowed Hrs]] -> -0.89
E30: Gulf Coast North | F30: 3 | G30: 10 | H30: 0.79 | I30: =Table1[[#This Row],[LHC]]*Table1[[#This Row],[Cars WTD (EDIT)]] -> 7.9 | J30: {=_xlfn.IFS(Table1[[#This Row],[Allowed Hours]]=0,0,Table1[[#This Row],[Allowed Hours]]<20,20,Table1[[#This Row],[Allowed Hours]]>20,Table1[[#This Row],[Allowed Hours]])} -> 20 | K30: 18 | L30: =K30-Table1[[#This Row],[Adj Allowed Hrs]] -> -2
E31: Gulf Coast North | F31: 5 | G31: 22 | H31: 0.79 | I31: =Table1[[#This Row],[LHC]]*Table1[[#This Row],[Cars WTD (EDIT)]] -> 17.38 | J31: {=_xlfn.IFS(Table1[[#This Row],[Allowed Hours]]=0,0,Table1[[#This Row],[Allowed Hours]]<20,20,Table1[[#This Row],[Allowed Hours]]>20,Table1[[#This Row],[Allowed Hours]])} -> 20 | K31: 28 | L31: =K31-Table1[[#This Row],[Adj Allowed Hrs]] -> 8
E32: Gulf Coast North | F32: 11 | G32: 10 | H32: 0.79 | I32: =Table1[[#This Row],[LHC]]*Table1[[#This Row],[Cars WTD (EDIT)]] -> 7.9 | J32: {=_xlfn.IFS(Table1[[#This Row],[Allowed Hours]]=0,0,Table1[[#This Row],[Allowed Hours]]<20,20,Table1[[#This Row],[Allowed Hours]]>20,Table1[[#This Row],[Allowed Hours]])} -> 20 | K32: 17 | L32: =K32-Table1[[#This Row],[Adj Allowed Hrs]] -> -3
E33: Gulf Coast North | F33: 14 | G33: 18 | H33: 0.79 | I33: =Table1[[#This Row],[LHC]]*Table1[[#This Row],[Cars WTD (EDIT)]] -> 14.22 | J33: {=_xlfn.IFS(Table1[[#This Row],[Allowed Hours]]=0,0,Table1[[#This Row],[Allowed Hours]]<20,20,Table1[[#This Row],[Allowed Hours]]>20,Table1[[#This Row],[Allowed Hours]])} -> 20 | K33: 18 | L33: =K33-Table1[[#This Row],[Adj Allowed Hrs]] -> -2
E34: Gulf Coast North | F34: 20 | G34: 20 | H34: 0.79 | I34: =Table1[[#This Row],[LHC]]*Table1[[#This Row],[Cars WTD (EDIT)]] -> 15.8 | J34: {=_xlfn.IFS(Table1[[#This Row],[Allowed Hours]]=0,0,Table1[[#This Row],[Allowed Hours]]<20,20,Table1[[#This Row],[Allowed Hours]]>20,Table1[[#This Row],[Allowed Hours]])} -> 20 | K34: 24 | L34: =K34-Table1[[#This Row],[Adj Allowed Hrs]] -> 4
... E71: NOLA South | F71: 3004 | G71: 9 | H71: 0.79 | I71: =Table1[[#This Row],[LHC]]*Table1[[#This Row],[Cars WTD (EDIT)]] -> 7.11 | J71: {=_xlfn.IFS(Table1[[#This Row],[Allowed Hours]]=0,0,Table1[[#This Row],[Allowed Hours]]<20,20,Table1[[#This Row],[Allowed Hours]]>20,Table1[[#This Row],[Allowed Hours]])} -> 20 | K71: 20.11 | L71: =K71-Table1[[#This Row],[Adj Allowed Hrs]] -> 0.11

Sheet Monday
B2: Minimum Hours WTD - KEY | E2: District | F2: Cars | G2: LHC | H2: Allowed Hours | I2: Actual Hours | J2: Hours Variance
B3: Sunday | C3: 20 | E3: Baton Rouge North | F3: =SUM(G14:G21) -> 144 | G3: 0.79 | H3: =SUM(I14:I21) -> 113.76 | I3: =SUM(K14:K21) -> 166.01 | J3: =SUM(L14:L21) -> -11.09
B4: Monday | C4: 45.3 | E4: Baton Rouge South | F4: =SUM(G22:G28) -> 193 | G4: 0.79 | H4: =SUM(I22:I28) -> 152.47 | I4: =SUM(K22:K28) -> 198.7 | J4: =SUM(L22:L28) -> 6.63
B5: Tuesday | C5: 70.6 | E5: Gulf Coast North | F5: =SUM(G29:G37) -> 305 | G5: 0.79 | H5: =SUM(I29:I37) -> 240.95 | I5: =SUM(K29:K37) -> 265 | J5: =SUM(L29:L37) -> -3.7
B6: Wednesday | C6: 95.93 | E6: Lafayette | F6: =SUM(G38:G45) -> 228 | G6: 0.79 | H6: =SUM(I38:I45) -> 180.12 | I6: =SUM(K38:K45) -> 220.53 | J6: =SUM(L38:L45) -> 1.58
B7: Thursday | C7: 121.23 | E7: Gulf Coast West | F7: =SUM(G46:G52) -> 206 | G7: 0.79 | H7: =SUM(I46:I52) -> 162.74 | I7: =SUM(K46:K52) -> 188.84 | J7: =SUM(L46:L52) -> 2.3
B8: Friday | C8: 146.53 | E8: Nola North | F8: =SUM(G53:G61) -> 404 | G8: 0.79 | H8: =SUM(I53:I61) -> 319.16 | I8: =SUM(K53:K61) -> 340.28 | J8: =SUM(L53:L61) -> 9.23
B9: Saturday | C9: 171.8 | E9: Nola South | F9: =SUM(G62:G70) -> 334 | G9: 0.79 | H9: =SUM(I62:I70) -> 263.86 | I9: =SUM(K62:K70) -> 314.3 | J9: =SUM(L62:L70) -> 17.99
E10: Region | F10: =SUM(F3:F9) -> 1814 | G10: 0.79 | H10: =SUM(H3:H9) -> 1433.06 | I10: =SUM(I3:I9) -> 1693.66 | J10: =SUM(J3:J9) -> 22.94
E13: District | F13: Store | G13: Cars WTD (EDIT) | H13: LHC | I13: Allowed Hours | J13: Adj Allowed Hrs | K13: Actual Hours (EDIT) | L13: Hours Variance
E14: Baton Rouge North | F14: 17 | G14: 20 | H14: 0.79 | I14: =Table13[[#This Row],[LHC]]*Table13[[#This Row],[Cars WTD (EDIT)]] -> 15.8 | J14: {=_xlfn.IFS(Table13[[#This Row],[Allowed Hours]]=0,0,Table13[[#This Row],[Allowed Hours]]<25.3,25.3,Table13[[#This Row],[Allowed Hours]]>25.3,Table13[[#This Row],[Allowed Hours]])} -> 25.3 | K14: 16.75 | L14: =K14-Table13[[#This Row],[Adj Allowed Hrs]] -> -8.55
E15: Baton Rouge North | F15: 22 | G15: 31 | H15: 0.79 | I15: =Table13[[#This Row],[LHC]]*Table13[[#This Row],[Cars WTD (EDIT)]] -> 24.49 | J15: {=_xlfn.IFS(Table13[[#This Row],[Allowed Hours]]=0,0,Table13[[#This Row],[Allowed Hours]]<25.3,25.3,Table13[[#This Row],[Allowed Hours]]>25.3,Table13[[#This Row],[Allowed Hours]])} -> 25.3 | K15: 19.89 | L15: =K15-Table13[[#This Row],[Adj Allowed Hrs]] -> -5.41
E16: Baton Rouge North | F16: 641 | G16: 24 | H16: 0.79 | I16: =Table13[[#This Row],[LHC]]*Table13[[#This Row],[Cars WTD (EDIT)]] -> 18.96 | J16: {=_xlfn.IFS(Table13[[#This Row],[Allowed Hours]]=0,0,Table13[[#This Row],[Allowed Hours]]<25.3,25.3,Table13[[#This Row],[Allowed Hours]]>25.3,Table13[[#This Row],[Allowed Hours]])} -> 25.3 | K16: 25.41 | L16: =K16-Table13[[#This Row],[Adj Allowed Hrs]] -> 0.11
E17: Baton Rouge North | F17: 717 | G17: 25 | H17: 0.79 | I17: =Table13[[#This Row],[LHC]]*Table13[[#This Row],[Cars WTD (EDIT)]] -> 19.75 | J17: {=_xlfn.IFS(Table13[[#This Row],[Allowed Hours]]=0,0,Table13[[#This Row],[Allowed Hours]]<25.3,25.3,Table13[[#This Row],[Allowed Hours]]>25.3,Table13[[#This Row],[Allowed Hours]])} -> 25.3 | K17: 23.39 | L17: =K17-Table13[[#This Row],[Adj Allowed Hrs]] -> -1.91
E18: Baton Rouge North | F18: 843 | G18: 7 | H18: 0.79 | I18: =Table13[[#This Row],[LHC]]*Table13[[#This Row],[Cars WTD (EDIT)]] -> 5.53 | J18: {=_xlfn.IFS(Table13[[#This Row],[Allowed Hours]]=0,0,Table13[[#This Row],[Allowed Hours]]<25.3,25.3,Table13[[#This Row],[Allowed Hours]]>25.3,Table13[[#This Row],[Allowed Hours]])} -> 25.3 | K18: 22.13 | L18: =K18-Table13[[#This Row],[Adj Allowed Hrs]] -> -3.17
E19: Baton Rouge North | F19: 881 | G19: 19 | H19: 0.79 | I19: =Table13[[#This Row],[LHC]]*Table13[[#This Row],[Cars WTD (EDIT)]] -> 15.01 | J19: {=_xlfn.IFS(Table13[[#This Row],[Allowed Hours]]=0,0,Table13[[#This Row],[Allowed Hours]]<25.3,25.3,Table13[[#This Row],[Allowed Hours]]>25.3,Table13[[#This Row],[Allowed Hours]])} -> 25.3 | K19: 17.31 | L19: =K19-Table13[[#This Row],[Adj Allowed Hrs]] -> -7.99
E20: Baton Rouge North | F20: 953 | G20: 18 | H20: 0.79 | I20: =Table13[[#This Row],[LHC]]*Table13[[#This Row],[Cars WTD (EDIT)]] -> 14.22 | J20: {=_xlfn.IFS(Table13[[#This Row],[Allowed Hours]]=0,0,Table13[[#This Row],[Allowed Hours]]<25.3,25.3,Table13[[#This Row],[Allowed Hours]]>25.3,Table13[[#This Row],[Allowed Hours]])} -> 25.3 | K20: 21.01 | L20: =K20-Table13[[#This Row],[Adj Allowed Hrs]] -> -4.29
E21: Baton Rouge North | F21: 3040 | H21: 0.79 | I21: =Table13[[#This Row],[LHC]]*Table13[[#This Row],[Cars WTD (EDIT)]] -> 0 | J21: {=_xlfn.IFS(Table13[[#This Row],[Allowed Hours]]=0,0,Table13[[#This Row],[Allowed Hours]]<25.3,25.3,Table13[[#This Row],[Allowed Hours]]>25.3,Table13[[#This Row],[Allowed Hours]])} -> 0 | K21: 20.12 | L21: =K21-Table13[[#This Row],[Adj Allowed Hrs]] -> 20.12
E22: Baton Rouge South | F22: 18 | G22: 36 | H22: 0.79 | I22: =Table13[[#This Row],[LHC]]*Table13[[#This Row],[Cars WTD (EDIT)]] -> 28.44 | J22: {=_xlfn.IFS(Table13[[#This Row],[Allowed Hours]]=0,0,Table13[[#This Row],[Allowed Hours]]<25.3,25.3,Table13[[#This Row],[Allowed Hours]]>25.3,Table13[[#This Row],[Allowed Hours]])} -> 28.44 | K22: 35.38 | L22: =K22-Table13[[#This Row],[Adj Allowed Hrs]] -> 6.94
E23: Baton Rouge South | F23: 19 | G23: 27 | H23: 0.79 | I23: =Table13[[#This Row],[LHC]]*Table13[[#This Row],[Cars WTD (EDIT)]] -> 21.33 | J23: {=_xlfn.IFS(Table13[[#This Row],[Allowed Hours]]=0,0,Table13[[#This Row],[Allowed Hours]]<25.3,25.3,Table13[[#This Row],[Allowed Hours]]>25.3,Table13[[#This Row],[Allowed Hours]])} -> 25.3 | K23: 41 | L23: =K23-Table13[[#This Row],[Adj Allowed Hrs]] -> 15.7
E24: Baton Rouge South | F24: 282 | G24: 14 | H24: 0.79 | I24: =Table13[[#This Row],[LHC]]*Table13[[#This Row],[Cars WTD (EDIT)]] -> 11.06 | J24: {=_xlfn.IFS(Table13[[#This Row],[Allowed Hours]]=0,0,Table13[[#This Row],[Allowed Hours]]<25.3,25.3,Table13[[#This Row],[Allowed Hours]]>25.3,Table13[[#This Row],[Allowed Hours]])} -> 25.3 | K24: 8.47 | L24: =K24-Table13[[#This Row],[Adj Allowed Hrs]] -> -16.83
E25: Baton Rouge South | F25: 447 | G25: 29 | H25: 0.79 | I25: =Table13[[#This Row],[LHC]]*Table13[[#This Row],[Cars WTD (EDIT)]] -> 22.91 | J25: {=_xlfn.IFS(Table13[[#This Row],[Allowed Hours]]=0,0,Table13[[#This Row],[Allowed Hours]]<25.3,25.3,Table13[[#This Row],[Allowed Hours]]>25.3,Table13[[#This Row],[Allowed Hours]])} -> 25.3 | K25: 29.19 | L25: =K25-Table13[[#This Row],[Adj Allowed Hrs]] -> 3.89
E26: Baton Rouge South | F26: 448 | G26: 47 | H26: 0.79 | I26: =Table13[[#This Row],[LHC]]*Table13[[#This Row],[Cars WTD (EDIT)]] -> 37.13 | J26: {=_xlfn.IFS(Table13[[#This Row],[Allowed Hours]]=0,0,Table13[[#This Row],[Allowed Hours]]<25.3,25.3,Table13[[#This Row],[Allowed Hours]]>25.3,Table13[[#This Row],[Allowed Hours]])} -> 37.13 | K26: 35.44 | L26: =K26-Table13[[#This Row],[Adj Allowed Hrs]] -> -1.69
E27: Baton Rouge South | F27: 531 | G27: 17 | H27: 0.79 | I27: =Table13[[#This Row],[LHC]]*Table13[[#This Row],[Cars WTD (EDIT)]] -> 13.43 | J27: {=_xlfn.IFS(Table13[[#This Row],[Allowed Hours]]=0,0,Table13[[#This Row],[Allowed Hours]]<25.3,25.3,Table13[[#This Row],[Allowed Hours]]>25.3,Table13[[#This Row],[Allowed Hours]])} -> 25.3 | K27: 30.19 | L27: =K27-Table13[[#This Row],[Adj Allowed Hrs]] -> 4.89
E28: Baton Rouge South | F28: 832 | G28: 23 | H28: 0.79 | I28: =Table13[[#This Row],[LHC]]*Table13[[#This Row],[Cars WTD (EDIT)]] -> 18.17 | J28: {=_xlfn.IFS(Table13[[#This Row],[Allowed Hours]]=0,0,Table13[[#This Row],[Allowed Hours]]<25.3,25.3,Table13[[#This Row],[Allowed Hours]]>25.3,Table13[[#This Row],[Allowed Hours]])} -> 25.3 | K28: 19.03 | L28: =K28-Table13[[#This Row],[Adj Allowed Hrs]] -> -6.27
E29: Gulf Coast North | F29: 3 | G29: 15 | H29: 0.79 | I29: =Table13[[#This Row],[LHC]]*Table13[[#This Row],[Cars WTD (EDIT)]] -> 11.85 | J29: {=_xlfn.IFS(Table13[[#This Row],[Allowed Hours]]=0,0,Table13[[#This Row],[Allowed Hours]]<25.3,25.3,Table13[[#This Row],[Allowed Hours]]>25.3,Table13[[#This Row],[Allowed Hours]])} -> 25.3 | K29: 26 | L29: =K29-Table13[[#This Row],[Adj Allowed Hrs]] -> 0.7
E30: Gulf Coast North | F30: 5 | G30: 34 | H30: 0.79 | I30: =Table13[[#This Row],[LHC]]*Table13[[#This Row],[Cars WTD (EDIT)]] -> 26.86 | J30: {=_xlfn.IFS(Table13[[#This Row],[Allowed Hours]]=0,0,Table13[[#This Row],[Allowed Hours]]<25.3,25.3,Table13[[#This Row],[Allowed Hours]]>25.3,Table13[[#This Row],[Allowed Hours]])} -> 26.86 | K30: 32 | L30: =K30-Table13[[#This Row],[Adj Allowed Hrs]] -> 5.14
E31: Gulf Coast North | F31: 11 | G31: 23 | H31: 0.79 | I31: =Table13[[#This Row],[LHC]]*Table13[[#This Row],[Cars WTD (EDIT)]] -> 18.17 | J31: {=_xlfn.IFS(Table13[[#This Row],[Allowed Hours]]=0,0,Table13[[#This Row],[Allowed Hours]]<25.3,25.3,Table13[[#This Row],[Allowed Hours]]>25.3,Table13[[#This Row],[Allowed Hours]])} -> 25.3 | K31: 30 | L31: =K31-Table13[[#This Row],[Adj Allowed Hrs]] -> 4.7
E32: Gulf Coast North | F32: 14 | G32: 26 | H32: 0.79 | I32: =Table13[[#This Row],[LHC]]*Table13[[#This Row],[Cars WTD (EDIT)]] -> 20.54 | J32: {=_xlfn.IFS(Table13[[#This Row],[Allowed Hours]]=0,0,Table13[[#This Row],[Allowed Hours]]<25.3,25.3,Table13[[#This Row],[Allowed Hours]]>25.3,Table13[[#This Row],[Allowed Hours]])} -> 25.3 | K32: 25 | L32: =K32-Table13[[#This Row],[Adj Allowed Hrs]] -> -0.3
E33: Gulf Coast North | F33: 20 | G33: 32 | H33: 0.79 | I33: =Table13[[#This Row],[LHC]]*Table13[[#This Row],[Cars WTD (EDIT)]] -> 25.28 | J33: {=_xlfn.IFS(Table13[[#This Row],[Allowed Hours]]=0,0,Table13[[#This Row],[Allowed Hours]]<25.3,25.3,Table13[[#This Row],[Allowed Hours]]>25.3,Table13[[#This Row],[Allowed Hours]])} -> 25.3 | K33: 22 | L33: =K33-Table13[[#This Row],[Adj Allowed Hrs]] -> -3.3
... E70: NOLA South | F70: 3004 | G70: 14 | H70: 0.79 | I70: =Table13[[#This Row],[LHC]]*Table13[[#This Row],[Cars WTD (EDIT)]] -> 11.06 | J70: {=_xlfn.IFS(Table13[[#This Row],[Allowed Hours]]=0,0,Table13[[#This Row],[Allowed Hours]]<25.3,25.3,Table13[[#This Row],[Allowed Hours]]>25.3,Table13[[#This Row],[Allowed Hours]])} -> 25.3 | K70: 27.63 | L70: =K70-Table13[[#This Row],[Adj Allowed Hrs]] -> 2.33

Sheet Tuesday
B2: Minimum Hours WTD - KEY | E2: District | F2: Cars | G2: LHC | H2: Allowed Hours | I2: Actual Hours | J2: Hours Variance
B3: Sunday | C3: 20 | E3: Baton Rouge North | F3: =SUM(G14:G21) -> 143 | G3: 0.79 | H3: =SUM(I14:I21) -> 112.97 | I3: =SUM(K14:K21) -> 188 | J3: =SUM(L14:L21) -> 10.9
B4: Monday | C4: 45.3 | E4: Baton Rouge South | F4: =SUM(G22:G28) -> 165 | G4: 0.79 | H4: =SUM(I22:I28) -> 130.35 | I4: =SUM(K22:K28) -> 211.78 | J4: =SUM(L22:L28) -> 33.12
B5: Tuesday | C5: 70.6 | E5: Gulf Coast North | F5: =SUM(G29:G37) -> 321 | G5: 0.79 | H5: =SUM(I29:I37) -> 253.59 | I5: =SUM(K29:K37) -> 268 | J5: =SUM(L29:L37) -> -20.43
B6: Wednesday | C6: 95.93 | E6: Lafayette | F6: =SUM(G38:G45) -> 177 | G6: 0.79 | H6: =SUM(I38:I45) -> 139.83 | I6: =SUM(K38:K45) -> 206.21 | J6: =SUM(L38:L45) -> -11.97
B7: Thursday | C7: 121.23 | E7: Gulf Coast West | F7: =SUM(G46:G52) -> 160 | G7: 0.79 | H7: =SUM(I46:I52) -> 126.4 | I7: =SUM(K46:K52) -> 178.69 | J7: =SUM(L46:L52) -> -1.55
B8: Friday | C8: 146.53 | E8: Nola North | F8: =SUM(G53:G61) -> 374 | G8: 0.79 | H8: =SUM(I53:I61) -> 295.46 | I8: =SUM(K53:K61) -> 317 | J8: =SUM(L53:L61) -> 19.94
B9: Saturday | C9: 171.8 | E9: Nola South | F9: =SUM(G62:G70) -> 328 | G9: 0.79 | H9: =SUM(I62:I70) -> 259.12 | I9: =SUM(K62:K70) -> 287.44 | J9: =SUM(L62:L70) -> 6.91
E10: Region | F10: =SUM(F3:F9) -> 1668 | G10: 0.79 | H10: =SUM(H3:H9) -> 1317.72 | I10: =SUM(I3:I9) -> 1657.12 | J10: =SUM(J3:J9) -> 36.92
E13: District | F13: Store | G13: Cars WTD (EDIT) | H13: LHC | I13: Allowed Hours | J13: Adj Allowed Hrs | K13: Actual Hours (EDIT) | L13: Hours Variance
E14: Baton Rouge North | F14: 17 | G14: 23 | H14: 0.79 | I14: =Table138[[#This Row],[LHC]]*Table138[[#This Row],[Cars WTD (EDIT)]] -> 18.17 | J14: {=_xlfn.IFS(Table138[[#This Row],[Allowed Hours]]=0,0,Table138[[#This Row],[Allowed Hours]]<25.3,25.3,Table138[[#This Row],[Allowed Hours]]>25.3,Table138[[#This Row],[Allowed Hours]])} -> 25.3 | K14: 24.3 | L14: =K14-Table138[[#This Row],[Adj Allowed Hrs]] -> -1
E15: Baton Rouge North | F15: 22 | G15: 23 | H15: 0.79 | I15: =Table138[[#This Row],[LHC]]*Table138[[#This Row],[Cars WTD (EDIT)]] -> 18.17 | J15: {=_xlfn.IFS(Table138[[#This Row],[Allowed Hours]]=0,0,Table138[[#This Row],[Allowed Hours]]<25.3,25.3,Table138[[#This Row],[Allowed Hours]]>25.3,Table138[[#This Row],[Allowed Hours]])} -> 25.3 | K15: 43.37 | L15: =K15-Table138[[#This Row],[Adj Allowed Hrs]] -> 18.07
E16: Baton Rouge North | F16: 641 | G16: 31 | H16: 0.79 | I16: =Table138[[#This Row],[LHC]]*Table138[[#This Row],[Cars WTD (EDIT)]] -> 24.49 | J16: {=_xlfn.IFS(Table138[[#This Row],[Allowed Hours]]=0,0,Table138[[#This Row],[Allowed Hours]]<25.3,25.3,Table138[[#This Row],[Allowed Hours]]>25.3,Table138[[#This Row],[Allowed Hours]])} -> 25.3 | K16: 25.14 | L16: =K16-Table138[[#This Row],[Adj Allowed Hrs]] -> -0.16
E17: Baton Rouge North | F17: 717 | G17: 25 | H17: 0.79 | I17: =Table138[[#This Row],[LHC]]*Table138[[#This Row],[Cars WTD (EDIT)]] -> 19.75 | J17: {=_xlfn.IFS(Table138[[#This Row],[Allowed Hours]]=0,0,Table138[[#This Row],[Allowed Hours]]<25.3,25.3,Table138[[#This Row],[Allowed Hours]]>25.3,Table138[[#This Row],[Allowed Hours]])} -> 25.3 | K17: 25.84 | L17: =K17-Table138[[#This Row],[Adj Allowed Hrs]] -> 0.54
E18: Baton Rouge North | F18: 843 | G18: 6 | H18: 0.79 | I18: =Table138[[#This Row],[LHC]]*Table138[[#This Row],[Cars WTD (EDIT)]] -> 4.74 | J18: {=_xlfn.IFS(Table138[[#This Row],[Allowed Hours]]=0,0,Table138[[#This Row],[Allowed Hours]]<25.3,25.3,Table138[[#This Row],[Allowed Hours]]>25.3,Table138[[#This Row],[Allowed Hours]])} -> 25.3 | K18: 15.65 | L18: =K18-Table138[[#This Row],[Adj Allowed Hrs]] -> -9.65
E19: Baton Rouge North | F19: 881 | G19: 20 | H19: 0.79 | I19: =Table138[[#This Row],[LHC]]*Table138[[#This Row],[Cars WTD (EDIT)]] -> 15.8 | J19: {=_xlfn.IFS(Table138[[#This Row],[Allowed Hours]]=0,0,Table138[[#This Row],[Allowed Hours]]<25.3,25.3,Table138[[#This Row],[Allowed Hours]]>25.3,Table138[[#This Row],[Allowed Hours]])} -> 25.3 | K19: 19.2 | L19: =K19-Table138[[#This Row],[Adj Allowed Hrs]] -> -6.1
E20: Baton Rouge North | F20: 953 | G20: 15 | H20: 0.79 | I20: =Table138[[#This Row],[LHC]]*Table138[[#This Row],[Cars WTD (EDIT)]] -> 11.85 | J20: {=_xlfn.IFS(Table138[[#This Row],[Allowed Hours]]=0,0,Table138[[#This Row],[Allowed Hours]]<25.3,25.3,Table138[[#This Row],[Allowed Hours]]>25.3,Table138[[#This Row],[Allowed Hours]])} -> 25.3 | K20: 18.77 | L20: =K20-Table138[[#This Row],[Adj Allowed Hrs]] -> -6.53
E21: Baton Rouge North | F21: 3040 | H21: 0.79 | I21: =Table138[[#This Row],[LHC]]*Table138[[#This Row],[Cars WTD (EDIT)]] -> 0 | J21: {=_xlfn.IFS(Table138[[#This Row],[Allowed Hours]]=0,0,Table138[[#This Row],[Allowed Hours]]<25.3,25.3,Table138[[#This Row],[Allowed Hours]]>25.3,Table138[[#This Row],[Allowed Hours]])} -> 0 | K21: 15.73 | L21: =K21-Table138[[#This Row],[Adj Allowed Hrs]] -> 15.73
E22: Baton Rouge South | F22: 18 | G22: 34 | H22: 0.79 | I22: =Table138[[#This Row],[LHC]]*Table138[[#This Row],[Cars WTD (EDIT)]] -> 26.86 | J22: {=_xlfn.IFS(Table138[[#This Row],[Allowed Hours]]=0,0,Table138[[#This Row],[Allowed Hours]]<25.3,25.3,Table138[[#This Row],[Allowed Hours]]>25.3,Table138[[#This Row],[Allowed Hours]])} -> 26.86 | K22: 36.26 | L22: =K22-Table138[[#This Row],[Adj Allowed Hrs]] -> 9.4
E23: Baton Rouge South | F23: 19 | G23: 29 | H23: 0.79 | I23: =Table138[[#This Row],[LHC]]*Table138[[#This Row],[Cars WTD (EDIT)]] -> 22.91 | J23: {=_xlfn.IFS(Table138[[#This Row],[Allowed Hours]]=0,0,Table138[[#This Row],[Allowed Hours]]<25.3,25.3,Table138[[#This Row],[Allowed Hours]]>25.3,Table138[[#This Row],[Allowed Hours]])} -> 25.3 | K23: 32.01 | L23: =K23-Table138[[#This Row],[Adj Allowed Hrs]] -> 6.71
E24: Baton Rouge South | F24: 282 | G24: 9 | H24: 0.79 | I24: =Table138[[#This Row],[LHC]]*Table138[[#This Row],[Cars WTD (EDIT)]] -> 7.11 | J24: {=_xlfn.IFS(Table138[[#This Row],[Allowed Hours]]=0,0,Table138[[#This Row],[Allowed Hours]]<25.3,25.3,Table138[[#This Row],[Allowed Hours]]>25.3,Table138[[#This Row],[Allowed Hours]])} -> 25.3 | K24: 17.86 | L24: =K24-Table138[[#This Row],[Adj Allowed Hrs]] -> -7.44
E25: Baton Rouge South | F25: 447 | G25: 22 | H25: 0.79 | I25: =Table138[[#This Row],[LHC]]*Table138[[#This Row],[Cars WTD (EDIT)]] -> 17.38 | J25: {=_xlfn.IFS(Table138[[#This Row],[Allowed Hours]]=0,0,Table138[[#This Row],[Allowed Hours]]<25.3,25.3,Table138[[#This Row],[Allowed Hours]]>25.3,Table138[[#This Row],[Allowed Hours]])} -> 25.3 | K25: 32.98 | L25: =K25-Table138[[#This Row],[Adj Allowed Hrs]] -> 7.68
E26: Baton Rouge South | F26: 448 | G26: 28 | H26: 0.79 | I26: =Table138[[#This Row],[LHC]]*Table138[[#This Row],[Cars WTD (EDIT)]] -> 22.12 | J26: {=_xlfn.IFS(Table138[[#This Row],[Allowed Hours]]=0,0,Table138[[#This Row],[Allowed Hours]]<25.3,25.3,Table138[[#This Row],[Allowed Hours]]>25.3,Table138[[#This Row],[Allowed Hours]])} -> 25.3 | K26: 35.82 | L26: =K26-Table138[[#This Row],[Adj Allowed Hrs]] -> 10.52
E27: Baton Rouge South | F27: 531 | G27: 13 | H27: 0.79 | I27: =Table138[[#This Row],[LHC]]*Table138[[#This Row],[Cars WTD (EDIT)]] -> 10.27 | J27: {=_xlfn.IFS(Table138[[#This Row],[Allowed Hours]]=0,0,Table138[[#This Row],[Allowed Hours]]<25.3,25.3,Table138[[#This Row],[Allowed Hours]]>25.3,Table138[[#This Row],[Allowed Hours]])} -> 25.3 | K27: 33.71 | L27: =K27-Table138[[#This Row],[Adj Allowed Hrs]] -> 8.41
E28: Baton Rouge South | F28: 832 | G28: 30 | H28: 0.79 | I28: =Table138[[#This Row],[LHC]]*Table138[[#This Row],[Cars WTD (EDIT)]] -> 23.7 | J28: {=_xlfn.IFS(Table138[[#This Row],[Allowed Hours]]=0,0,Table138[[#This Row],[Allowed Hours]]<25.3,25.3,Table138[[#This Row],[Allowed Hours]]>25.3,Table138[[#This Row],[Allowed Hours]])} -> 25.3 | K28: 23.14 | L28: =K28-Table138[[#This Row],[Adj Allowed Hrs]] -> -2.16
E29: Gulf Coast North | F29: 3 | G29: 26 | H29: 0.79 | I29: =Table138[[#This Row],[LHC]]*Table138[[#This Row],[Cars WTD (EDIT)]] -> 20.54 | J29: {=_xlfn.IFS(Table138[[#This Row],[Allowed Hours]]=0,0,Table138[[#This Row],[Allowed Hours]]<25.3,25.3,Table138[[#This Row],[Allowed Hours]]>25.3,Table138[[#This Row],[Allowed Hours]])} -> 25.3 | K29: 19 | L29: =K29-Table138[[#This Row],[Adj Allowed Hrs]] -> -6.3
E30: Gulf Coast North | F30: 5 | G30: 41 | H30: 0.79 | I30: =Table138[[#This Row],[LHC]]*Table138[[#This Row],[Cars WTD (EDIT)]] -> 32.39 | J30: {=_xlfn.IFS(Table138[[#This Row],[Allowed Hours]]=0,0,Table138[[#This Row],[Allowed Hours]]<25.3,25.3,Table138[[#This Row],[Allowed Hours]]>25.3,Table138[[#This Row],[Allowed Hours]])} -> 32.39 | K30: 34 | L30: =K30-Table138[[#This Row],[Adj Allowed Hrs]] -> 1.61
E31: Gulf Coast North | F31: 11 | G31: 19 | H31: 0.79 | I31: =Table138[[#This Row],[LHC]]*Table138[[#This Row],[Cars WTD (EDIT)]] -> 15.01 | J31: {=_xlfn.IFS(Table138[[#This Row],[Allowed Hours]]=0,0,Table138[[#This Row],[Allowed Hours]]<25.3,25.3,Table138[[#This Row],[Allowed Hours]]>25.3,Table138[[#This Row],[Allowed Hours]])} -> 25.3 | K31: 27 | L31: =K31-Table138[[#This Row],[Adj Allowed Hrs]] -> 1.7
E32: Gulf Coast North | F32: 14 | G32: 16 | H32: 0.79 | I32: =Table138[[#This Row],[LHC]]*Table138[[#This Row],[Cars WTD (EDIT)]] -> 12.64 | J32: {=_xlfn.IFS(Table138[[#This Row],[Allowed Hours]]=0,0,Table138[[#This Row],[Allowed Hours]]<25.3,25.3,Table138[[#This Row],[Allowed Hours]]>25.3,Table138[[#This Row],[Allowed Hours]])} -> 25.3 | K32: 18 | L32: =K32-Table138[[#This Row],[Adj Allowed Hrs]] -> -7.3
E33: Gulf Coast North | F33: 20 | G33: 36 | H33: 0.79 | I33: =Table138[[#This Row],[LHC]]*Table138[[#This Row],[Cars WTD (EDIT)]] -> 28.44 | J33: {=_xlfn.IFS(Table138[[#This Row],[Allowed Hours]]=0,0,Table138[[#This Row],[Allowed Hours]]<25.3,25.3,Table138[[#This Row],[Allowed Hours]]>25.3,Table138[[#This Row],[Allowed Hours]])} -> 28.44 | K33: 25 | L33: =K33-Table138[[#This Row],[Adj Allowed Hrs]] -> -3.44
... E70: NOLA South | F70: 3004 | G70: 13 | H70: 0.79 | I70: =Table138[[#This Row],[LHC]]*Table138[[#This Row],[Cars WTD (EDIT)]] -> 10.27 | J70: {=_xlfn.IFS(Table138[[#This Row],[Allowed Hours]]=0,0,Table138[[#This Row],[Allowed Hours]]<25.3,25.3,Table138[[#This Row],[Allowed Hours]]>25.3,Table138[[#This Row],[Allowed Hours]])} -> 25.3 | K70: 20.19 | L70: =K70-Table138[[#This Row],[Adj Allowed Hrs]] -> -5.11

Sheet Wednesday
B2: Minimum Hours WTD - KEY | E2: District | F2: Cars | G2: LHC | H2: Allowed Hours | I2: Actual Hours | J2: Hours Variance
B3: Sunday | C3: 20 | E3: Baton Rouge North | F3: =SUM(G14:G21) -> 117 | G3: 0.79 | H3: =SUM(I14:I21) -> 92.43 | I3: =SUM(K14:K21) -> 205.96 | J3: =SUM(L14:L21) -> 28.86
B4: Monday | C4: 45.3 | E4: Baton Rouge South | F4: =SUM(G22:G28) -> 153 | G4: 0.79 | H4: =SUM(I22:I28) -> 120.87 | I4: =SUM(K22:K28) -> 221.02 | J4: =SUM(L22:L28) -> 43.92
B5: Tuesday | C5: 70.6 | E5: Gulf Coast North | F5: =SUM(G29:G37) -> 321 | G5: 0.79 | H5: =SUM(I29:I37) -> 253.59 | I5: =SUM(K29:K37) -> 279 | J5: =SUM(L29:L37) -> -1.55
B6: Wednesday | C6: 95.93 | E6: Lafayette | F6: =SUM(G38:G45) -> 188 | G6: 0.79 | H6: =SUM(I38:I45) -> 148.52 | I6: =SUM(K38:K45) -> 206.67 | J6: =SUM(L38:L45) -> 14.62
B7: Thursday | C7: 121.23 | E7: Gulf Coast West | F7: =SUM(G46:G52) -> 179 | G7: 0.79 | H7: =SUM(I46:I52) -> 141.41 | I7: =SUM(K46:K52) -> 178.08 | J7: =SUM(L46:L52) -> -6.09
B8: Friday | C8: 146.53 | E8: Nola North | F8: =SUM(G53:G61) -> 368 | G8: 0.79 | H8: =SUM(I53:I61) -> 290.72 | I8: =SUM(K53:K61) -> 322.99 | J8: =SUM(L53:L61) -> 25.14
B9: Saturday | C9: 171.8 | E9: Nola South | F9: =SUM(G62:G70) -> 329 | G9: 0.79 | H9: =SUM(I62:I70) -> 259.91 | I9: =SUM(K62:K70) -> 321.68 | J9: =SUM(L62:L70) -> 28.53
E10: Region | F10: =SUM(F3:F9) -> 1655 | G10: 0.79 | H10: =SUM(H3:H9) -> 1307.45 | I10: =SUM(I3:I9) -> 1735.4 | J10: =SUM(J3:J9) -> 133.43
E13: District | F13: Store | G13: Cars WTD (EDIT) | H13: LHC | I13: Allowed Hours | J13: Adj Allowed Hrs | K13: Actual Hours (EDIT) | L13: Hours Variance
E14: Baton Rouge North | F14: 17 | G14: 15 | H14: 0.79 | I14: =Table13813[[#This Row],[LHC]]*Table13813[[#This Row],[Cars WTD (EDIT)]] -> 11.85 | J14: {=_xlfn.IFS(Table13813[[#This Row],[Allowed Hours]]=0,0,Table13813[[#This Row],[Allowed Hours]]<25.3,25.3,Table13813[[#This Row],[Allowed Hours]]>25.3,Table13813[[#This Row],[Allowed Hours]])} -> 25.3 | K14: 19.88 | L14: =K14-Table13813[[#This Row],[Adj Allowed Hrs]] -> -5.42
E15: Baton Rouge North | F15: 22 | G15: 24 | H15: 0.79 | I15: =Table13813[[#This Row],[LHC]]*Table13813[[#This Row],[Cars WTD (EDIT)]] -> 18.96 | J15: {=_xlfn.IFS(Table13813[[#This Row],[Allowed Hours]]=0,0,Table13813[[#This Row],[Allowed Hours]]<25.3,25.3,Table13813[[#This Row],[Allowed Hours]]>25.3,Table13813[[#This Row],[Allowed Hours]])} -> 25.3 | K15: 29.3 | L15: =K15-Table13813[[#This Row],[Adj Allowed Hrs]] -> 4
E16: Baton Rouge North | F16: 641 | G16: 20 | H16: 0.79 | I16: =Table13813[[#This Row],[LHC]]*Table13813[[#This Row],[Cars WTD (EDIT)]] -> 15.8 | J16: {=_xlfn.IFS(Table13813[[#This Row],[Allowed Hours]]=0,0,Table13813[[#This Row],[Allowed Hours]]<25.3,25.3,Table13813[[#This Row],[Allowed Hours]]>25.3,Table13813[[#This Row],[Allowed Hours]])} -> 25.3 | K16: 37.17 | L16: =K16-Table13813[[#This Row],[Adj Allowed Hrs]] -> 11.87
E17: Baton Rouge North | F17: 717 | G17: 22 | H17: 0.79 | I17: =Table13813[[#This Row],[LHC]]*Table13813[[#This Row],[Cars WTD (EDIT)]] -> 17.38 | J17: {=_xlfn.IFS(Table13813[[#This Row],[Allowed Hours]]=0,0,Table13813[[#This Row],[Allowed Hours]]<25.3,25.3,Table13813[[#This Row],[Allowed Hours]]>25.3,Table13813[[#This Row],[Allowed Hours]])} -> 25.3 | K17: 34.87 | L17: =K17-Table13813[[#This Row],[Adj Allowed Hrs]] -> 9.57
E18: Baton Rouge North | F18: 843 | G18: 1 | H18: 0.79 | I18: =Table13813[[#This Row],[LHC]]*Table13813[[#This Row],[Cars WTD (EDIT)]] -> 0.79 | J18: {=_xlfn.IFS(Table13813[[#This Row],[Allowed Hours]]=0,0,Table13813[[#This Row],[Allowed Hours]]<25.3,25.3,Table13813[[#This Row],[Allowed Hours]]>25.3,Table13813[[#This Row],[Allowed Hours]])} -> 25.3 | K18: 23.99 | L18: =K18-Table13813[[#This Row],[Adj Allowed Hrs]] -> -1.31
E19: Baton Rouge North | F19: 881 | G19: 15 | H19: 0.79 | I19: =Table13813[[#This Row],[LHC]]*Table13813[[#This Row],[Cars WTD (EDIT)]] -> 11.85 | J19: {=_xlfn.IFS(Table13813[[#This Row],[Allowed Hours]]=0,0,Table13813[[#This Row],[Allowed Hours]]<25.3,25.3,Table13813[[#This Row],[Allowed Hours]]>25.3,Table13813[[#This Row],[Allowed Hours]])} -> 25.3 | K19: 33.69 | L19: =K19-Table13813[[#This Row],[Adj Allowed Hrs]] -> 8.39
E20: Baton Rouge North | F20: 953 | G20: 20 | H20: 0.79 | I20: =Table13813[[#This Row],[LHC]]*Table13813[[#This Row],[Cars WTD (EDIT)]] -> 15.8 | J20: {=_xlfn.IFS(Table13813[[#This Row],[Allowed Hours]]=0,0,Table13813[[#This Row],[Allowed Hours]]<25.3,25.3,Table13813[[#This Row],[Allowed Hours]]>25.3,Table13813[[#This Row],[Allowed Hours]])} -> 25.3 | K20: 16.64 | L20: =K20-Table13813[[#This Row],[Adj Allowed Hrs]] -> -8.66
E21: Baton Rouge North | F21: 3040 | H21: 0.79 | I21: =Table13813[[#This Row],[LHC]]*Table13813[[#This Row],[Cars WTD (EDIT)]] -> 0 | J21: {=_xlfn.IFS(Table13813[[#This Row],[Allowed Hours]]=0,0,Table13813[[#This Row],[Allowed Hours]]<25.3,25.3,Table13813[[#This Row],[Allowed Hours]]>25.3,Table13813[[#This Row],[Allowed Hours]])} -> 0 | K21: 10.42 | L21: =K21-Table13813[[#This Row],[Adj Allowed Hrs]] -> 10.42
E22: Baton Rouge South | F22: 18 | G22: 30 | H22: 0.79 | I22: =Table13813[[#This Row],[LHC]]*Table13813[[#This Row],[Cars WTD (EDIT)]] -> 23.7 | J22: {=_xlfn.IFS(Table13813[[#This Row],[Allowed Hours]]=0,0,Table13813[[#This Row],[Allowed Hours]]<25.3,25.3,Table13813[[#This Row],[Allowed Hours]]>25.3,Table13813[[#This Row],[Allowed Hours]])} -> 25.3 | K22: 37.34 | L22: =K22-Table13813[[#This Row],[Adj Allowed Hrs]] -> 12.04
E23: Baton Rouge South | F23: 19 | G23: 18 | H23: 0.79 | I23: =Table13813[[#This Row],[LHC]]*Table13813[[#This Row],[Cars WTD (EDIT)]] -> 14.22 | J23: {=_xlfn.IFS(Table13813[[#This Row],[Allowed Hours]]=0,0,Table13813[[#This Row],[Allowed Hours]]<25.3,25.3,Table13813[[#This Row],[Allowed Hours]]>25.3,Table13813[[#This Row],[Allowed Hours]])} -> 25.3 | K23: 23.98 | L23: =K23-Table13813[[#This Row],[Adj Allowed Hrs]] -> -1.32
E24: Baton Rouge South | F24: 282 | G24: 9 | H24: 0.79 | I24: =Table13813[[#This Row],[LHC]]*Table13813[[#This Row],[Cars WTD (EDIT)]] -> 7.11 | J24: {=_xlfn.IFS(Table13813[[#This Row],[Allowed Hours]]=0,0,Table13813[[#This Row],[Allowed Hours]]<25.3,25.3,Table13813[[#This Row],[Allowed Hours]]>25.3,Table13813[[#This Row],[Allowed Hours]])} -> 25.3 | K24: 18.57 | L24: =K24-Table13813[[#This Row],[Adj Allowed Hrs]] -> -6.73
E25: Baton Rouge South | F25: 447 | G25: 23 | H25: 0.79 | I25: =Table13813[[#This Row],[LHC]]*Table13813[[#This Row],[Cars WTD (EDIT)]] -> 18.17 | J25: {=_xlfn.IFS(Table13813[[#This Row],[Allowed Hours]]=0,0,Table13813[[#This Row],[Allowed Hours]]<25.3,25.3,Table13813[[#This Row],[Allowed Hours]]>25.3,Table13813[[#This Row],[Allowed Hours]])} -> 25.3 | K25: 31.71 | L25: =K25-Table13813[[#This Row],[Adj Allowed Hrs]] -> 6.41
E26: Baton Rouge South | F26: 448 | G26: 28 | H26: 0.79 | I26: =Table13813[[#This Row],[LHC]]*Table13813[[#This Row],[Cars WTD (EDIT)]] -> 22.12 | J26: {=_xlfn.IFS(Table13813[[#This Row],[Allowed Hours]]=0,0,Table13813[[#This Row],[Allowed Hours]]<25.3,25.3,Table13813[[#This Row],[Allowed Hours]]>25.3,Table13813[[#This Row],[Allowed Hours]])} -> 25.3 | K26: 47.07 | L26: =K26-Table13813[[#This Row],[Adj Allowed Hrs]] -> 21.77
E27: Baton Rouge South | F27: 531 | G27: 19 | H27: 0.79 | I27: =Table13813[[#This Row],[LHC]]*Table13813[[#This Row],[Cars WTD (EDIT)]] -> 15.01 | J27: {=_xlfn.IFS(Table13813[[#This Row],[Allowed Hours]]=0,0,Table13813[[#This Row],[Allowed Hours]]<25.3,25.3,Table13813[[#This Row],[Allowed Hours]]>25.3,Table13813[[#This Row],[Allowed Hours]])} -> 25.3 | K27: 36.22 | L27: =K27-Table13813[[#This Row],[Adj Allowed Hrs]] -> 10.92
E28: Baton Rouge South | F28: 832 | G28: 26 | H28: 0.79 | I28: =Table13813[[#This Row],[LHC]]*Table13813[[#This Row],[Cars WTD (EDIT)]] -> 20.54 | J28: {=_xlfn.IFS(Table13813[[#This Row],[Allowed Hours]]=0,0,Table13813[[#This Row],[Allowed Hours]]<25.3,25.3,Table13813[[#This Row],[Allowed Hours]]>25.3,Table13813[[#This Row],[Allowed Hours]])} -> 25.3 | K28: 26.13 | L28: =K28-Table13813[[#This Row],[Adj Allowed Hrs]] -> 0.83
E29: Gulf Coast North | F29: 3 | G29: 28 | H29: 0.79 | I29: =Table13813[[#This Row],[LHC]]*Table13813[[#This Row],[Cars WTD (EDIT)]] -> 22.12 | J29: {=_xlfn.IFS(Table13813[[#This Row],[Allowed Hours]]=0,0,Table13813[[#This Row],[Allowed Hours]]<25.3,25.3,Table13813[[#This Row],[Allowed Hours]]>25.3,Table13813[[#This Row],[Allowed Hours]])} -> 25.3 | K29: 5 | L29: =K29-Table13813[[#This Row],[Adj Allowed Hrs]] -> -20.3
E30: Gulf Coast North | F30: 5 | G30: 30 | H30: 0.79 | I30: =Table13813[[#This Row],[LHC]]*Table13813[[#This Row],[Cars WTD (EDIT)]] -> 23.7 | J30: {=_xlfn.IFS(Table13813[[#This Row],[Allowed Hours]]=0,0,Table13813[[#This Row],[Allowed Hours]]<25.3,25.3,Table13813[[#This Row],[Allowed Hours]]>25.3,Table13813[[#This Row],[Allowed Hours]])} -> 25.3 | K30: 46 | L30: =K30-Table13813[[#This Row],[Adj Allowed Hrs]] -> 20.7
E31: Gulf Coast North | F31: 11 | G31: 22 | H31: 0.79 | I31: =Table13813[[#This Row],[LHC]]*Table13813[[#This Row],[Cars WTD (EDIT)]] -> 17.38 | J31: {=_xlfn.IFS(Table13813[[#This Row],[Allowed Hours]]=0,0,Table13813[[#This Row],[Allowed Hours]]<25.3,25.3,Table13813[[#This Row],[Allowed Hours]]>25.3,Table13813[[#This Row],[Allowed Hours]])} -> 25.3 | K31: 28 | L31: =K31-Table13813[[#This Row],[Adj Allowed Hrs]] -> 2.7
E32: Gulf Coast North | F32: 14 | G32: 22 | H32: 0.79 | I32: =Table13813[[#This Row],[LHC]]*Table13813[[#This Row],[Cars WTD (EDIT)]] -> 17.38 | J32: {=_xlfn.IFS(Table13813[[#This Row],[Allowed Hours]]=0,0,Table13813[[#This Row],[Allowed Hours]]<25.3,25.3,Table13813[[#This Row],[Allowed Hours]]>25.3,Table13813[[#This Row],[Allowed Hours]])} -> 25.3 | K32: 23 | L32: =K32-Table13813[[#This Row],[Adj Allowed Hrs]] -> -2.3
E33: Gulf Coast North | F33: 20 | G33: 36 | H33: 0.79 | I33: =Table13813[[#This Row],[LHC]]*Table13813[[#This Row],[Cars WTD (EDIT)]] -> 28.44 | J33: {=_xlfn.IFS(Table13813[[#This Row],[Allowed Hours]]=0,0,Table13813[[#This Row],[Allowed Hours]]<25.3,25.3,Table13813[[#This Row],[Allowed Hours]]>25.3,Table13813[[#This Row],[Allowed Hours]])} -> 28.44 | K33: 41 | L33: =K33-Table13813[[#This Row],[Adj Allowed Hrs]] -> 12.56
... E70: NOLA South | F70: 3004 | G70: 7 | H70: 0.79 | I70: =Table13813[[#This Row],[LHC]]*Table13813[[#This Row],[Cars WTD (EDIT)]] -> 5.53 | J70: {=_xlfn.IFS(Table13813[[#This Row],[Allowed Hours]]=0,0,Table13813[[#This Row],[Allowed Hours]]<25.3,25.3,Table13813[[#This Row],[Allowed Hours]]>25.3,Table13813[[#This Row],[Allowed Hours]])} -> 25.3 | K70: 28.31 | L70: =K70-Table13813[[#This Row],[Adj Allowed Hrs]] -> 3.01

Sheet Thursday
B2: Minimum Hours WTD - KEY | E2: District | F2: Cars | G2: LHC | H2: Allowed Hours | I2: Actual Hours | J2: Hours Variance
B3: Sunday | C3: 20 | E3: Baton Rouge North | F3: =SUM(G14:G21) -> 112 | G3: 0.79 | H3: =SUM(I14:I21) -> 88.48 | I3: =SUM(K14:K21) -> 153.95 | J3: =SUM(L14:L21) -> -23.15
B4: Monday | C4: 45.3 | E4: Baton Rouge South | F4: =SUM(G22:G28) -> 109 | G4: 0.79 | H4: =SUM(I22:I28) -> 86.11 | I4: =SUM(K22:K28) -> 188.54 | J4: =SUM(L22:L28) -> 11.44
B5: Tuesday | C5: 70.6 | E5: Gulf Coast North | F5: =SUM(G29:G37) -> 254 | G5: 0.79 | H5: =SUM(I29:I37) -> 200.66 | I5: =SUM(K29:K37) -> 257 | J5: =SUM(L29:L37) -> 1.69
B6: Wednesday | C6: 95.93 | E6: Lafayette | F6: =SUM(G38:G45) -> 154 | G6: 0.79 | H6: =SUM(I38:I45) -> 121.66 | I6: =SUM(K38:K45) -> 184.26 | J6: =SUM(L38:L45) -> -18.14
B7: Thursday | C7: 121.23 | E7: Gulf Coast West | F7: =SUM(G46:G52) -> 175 | G7: 0.79 | H7: =SUM(I46:I52) -> 138.25 | I7: =SUM(K46:K52) -> 159.6 | J7: =SUM(L46:L52) -> -21.43
B8: Friday | C8: 146.53 | E8: Nola North | F8: =SUM(G53:G61) -> 296 | G8: 0.79 | H8: =SUM(I53:I61) -> 233.84 | I8: =SUM(K53:K61) -> 286.3 | J8: =SUM(L53:L61) -> 20.78
B9: Saturday | C9: 171.8 | E9: Nola South | F9: =SUM(G62:G70) -> 270 | G9: 0.79 | H9: =SUM(I62:I70) -> 213.3 | I9: =SUM(K62:K70) -> 278.14 | J9: =SUM(L62:L70) -> 34.72
E10: Region | F10: =SUM(F3:F9) -> 1370 | G10: 0.79 | H10: =SUM(H3:H9) -> 1082.3 | I10: =SUM(I3:I9) -> 1507.79 | J10: =SUM(J3:J9) -> 5.91
E13: District | F13: Store | G13: Cars WTD (EDIT) | H13: LHC | I13: Allowed Hours | J13: Adj Allowed Hrs | K13: Actual Hours (EDIT) | L13: Hours Variance
E14: Baton Rouge North | F14: 17 | G14: 21 | H14: 0.79 | I14: =Table1381314[[#This Row],[LHC]]*Table1381314[[#This Row],[Cars WTD (EDIT)]] -> 16.59 | J14: {=_xlfn.IFS(Table1381314[[#This Row],[Allowed Hours]]=0,0,Table1381314[[#This Row],[Allowed Hours]]<25.3,25.3,Table1381314[[#This Row],[Allowed Hours]]>25.3,Table1381314[[#This Row],[Allowed Hours]])} -> 25.3 | K14: 22.13 | L14: =K14-Table1381314[[#This Row],[Adj Allowed Hrs]] -> -3.17
E15: Baton Rouge North | F15: 22 | G15: 25 | H15: 0.79 | I15: =Table1381314[[#This Row],[LHC]]*Table1381314[[#This Row],[Cars WTD (EDIT)]] -> 19.75 | J15: {=_xlfn.IFS(Table1381314[[#This Row],[Allowed Hours]]=0,0,Table1381314[[#This Row],[Allowed Hours]]<25.3,25.3,Table1381314[[#This Row],[Allowed Hours]]>25.3,Table1381314[[#This Row],[Allowed Hours]])} -> 25.3 | K15: 26.76 | L15: =K15-Table1381314[[#This Row],[Adj Allowed Hrs]] -> 1.46
E16: Baton Rouge North | F16: 641 | G16: 27 | H16: 0.79 | I16: =Table1381314[[#This Row],[LHC]]*Table1381314[[#This Row],[Cars WTD (EDIT)]] -> 21.33 | J16: {=_xlfn.IFS(Table1381314[[#This Row],[Allowed Hours]]=0,0,Table1381314[[#This Row],[Allowed Hours]]<25.3,25.3,Table1381314[[#This Row],[Allowed Hours]]>25.3,Table1381314[[#This Row],[Allowed Hours]])} -> 25.3 | K16: 23.42 | L16: =K16-Table1381314[[#This Row],[Adj Allowed Hrs]] -> -1.88
E17: Baton Rouge North | F17: 717 | G17: 16 | H17: 0.79 | I17: =Table1381314[[#This Row],[LHC]]*Table1381314[[#This Row],[Cars WTD (EDIT)]] -> 12.64 | J17: {=_xlfn.IFS(Table1381314[[#This Row],[Allowed Hours]]=0,0,Table1381314[[#This Row],[Allowed Hours]]<25.3,25.3,Table1381314[[#This Row],[Allowed Hours]]>25.3,Table1381314[[#This Row],[Allowed Hours]])} -> 25.3 | K17: 24.29 | L17: =K17-Table1381314[[#This Row],[Adj Allowed Hrs]] -> -1.01
E18: Baton Rouge North | F18: 843 | G18: 2 | H18: 0.79 | I18: =Table1381314[[#This Row],[LHC]]*Table1381314[[#This Row],[Cars WTD (EDIT)]] -> 1.58 | J18: {=_xlfn.IFS(Table1381314[[#This Row],[Allowed Hours]]=0,0,Table1381314[[#This Row],[Allowed Hours]]<25.3,25.3,Table1381314[[#This Row],[Allowed Hours]]>25.3,Table1381314[[#This Row],[Allowed Hours]])} -> 25.3 | K18: 1.46 | L18: =K18-Table1381314[[#This Row],[Adj Allowed Hrs]] -> -23.84
E19: Baton Rouge North | F19: 881 | G19: 12 | H19: 0.79 | I19: =Table1381314[[#This Row],[LHC]]*Table1381314[[#This Row],[Cars WTD (EDIT)]] -> 9.48 | J19: {=_xlfn.IFS(Table1381314[[#This Row],[Allowed Hours]]=0,0,Table1381314[[#This Row],[Allowed Hours]]<25.3,25.3,Table1381314[[#This Row],[Allowed Hours]]>25.3,Table1381314[[#This Row],[Allowed Hours]])} -> 25.3 | K19: 19.73 | L19: =K19-Table1381314[[#This Row],[Adj Allowed Hrs]] -> -5.57
E20: Baton Rouge North | F20: 953 | G20: 9 | H20: 0.79 | I20: =Table1381314[[#This Row],[LHC]]*Table1381314[[#This Row],[Cars WTD (EDIT)]] -> 7.11 | J20: {=_xlfn.IFS(Table1381314[[#This Row],[Allowed Hours]]=0,0,Table1381314[[#This Row],[Allowed Hours]]<25.3,25.3,Table1381314[[#This Row],[Allowed Hours]]>25.3,Table1381314[[#This Row],[Allowed Hours]])} -> 25.3 | K20: 20.71 | L20: =K20-Table1381314[[#This Row],[Adj Allowed Hrs]] -> -4.59
E21: Baton Rouge North | F21: 3040 | H21: 0.79 | I21: =Table1381314[[#This Row],[LHC]]*Table1381314[[#This Row],[Cars WTD (EDIT)]] -> 0 | J21: {=_xlfn.IFS(Table1381314[[#This Row],[Allowed Hours]]=0,0,Table1381314[[#This Row],[Allowed Hours]]<25.3,25.3,Table1381314[[#This Row],[Allowed Hours]]>25.3,Table1381314[[#This Row],[Allowed Hours]])} -> 0 | K21: 15.45 | L21: =K21-Table1381314[[#This Row],[Adj Allowed Hrs]] -> 15.45
E22: Baton Rouge South | F22: 18 | G22: 23 | H22: 0.79 | I22: =Table1381314[[#This Row],[LHC]]*Table1381314[[#This Row],[Cars WTD (EDIT)]] -> 18.17 | J22: {=_xlfn.IFS(Table1381314[[#This Row],[Allowed Hours]]=0,0,Table1381314[[#This Row],[Allowed Hours]]<25.3,25.3,Table1381314[[#This Row],[Allowed Hours]]>25.3,Table1381314[[#This Row],[Allowed Hours]])} -> 25.3 | K22: 24.84 | L22: =K22-Table1381314[[#This Row],[Adj Allowed Hrs]] -> -0.46
E23: Baton Rouge South | F23: 19 | G23: 32 | H23: 0.79 | I23: =Table1381314[[#This Row],[LHC]]*Table1381314[[#This Row],[Cars WTD (EDIT)]] -> 25.28 | J23: {=_xlfn.IFS(Table1381314[[#This Row],[Allowed Hours]]=0,0,Table1381314[[#This Row],[Allowed Hours]]<25.3,25.3,Table1381314[[#This Row],[Allowed Hours]]>25.3,Table1381314[[#This Row],[Allowed Hours]])} -> 25.3 | K23: 33.43 | L23: =K23-Table1381314[[#This Row],[Adj Allowed Hrs]] -> 8.13
E24: Baton Rouge South | F24: 282 | G24: 3 | H24: 0.79 | I24: =Table1381314[[#This Row],[LHC]]*Table1381314[[#This Row],[Cars WTD (EDIT)]] -> 2.37 | J24: {=_xlfn.IFS(Table1381314[[#This Row],[Allowed Hours]]=0,0,Table1381314[[#This Row],[Allowed Hours]]<25.3,25.3,Table1381314[[#This Row],[Allowed Hours]]>25.3,Table1381314[[#This Row],[Allowed Hours]])} -> 25.3 | K24: 10.89 | L24: =K24-Table1381314[[#This Row],[Adj Allowed Hrs]] -> -14.41
E25: Baton Rouge South | F25: 447 | G25: 13 | H25: 0.79 | I25: =Table1381314[[#This Row],[LHC]]*Table1381314[[#This Row],[Cars WTD (EDIT)]] -> 10.27 | J25: {=_xlfn.IFS(Table1381314[[#This Row],[Allowed Hours]]=0,0,Table1381314[[#This Row],[Allowed Hours]]<25.3,25.3,Table1381314[[#This Row],[Allowed Hours]]>25.3,Table1381314[[#This Row],[Allowed Hours]])} -> 25.3 | K25: 32.88 | L25: =K25-Table1381314[[#This Row],[Adj Allowed Hrs]] -> 7.58
E26: Baton Rouge South | F26: 448 | G26: 14 | H26: 0.79 | I26: =Table1381314[[#This Row],[LHC]]*Table1381314[[#This Row],[Cars WTD (EDIT)]] -> 11.06 | J26: {=_xlfn.IFS(Table1381314[[#This Row],[Allowed Hours]]=0,0,Table1381314[[#This Row],[Allowed Hours]]<25.3,25.3,Table1381314[[#This Row],[Allowed Hours]]>25.3,Table1381314[[#This Row],[Allowed Hours]])} -> 25.3 | K26: 35.14 | L26: =K26-Table1381314[[#This Row],[Adj Allowed Hrs]] -> 9.84
E27: Baton Rouge South | F27: 531 | G27: 13 | H27: 0.79 | I27: =Table1381314[[#This Row],[LHC]]*Table1381314[[#This Row],[Cars WTD (EDIT)]] -> 10.27 | J27: {=_xlfn.IFS(Table1381314[[#This Row],[Allowed Hours]]=0,0,Table1381314[[#This Row],[Allowed Hours]]<25.3,25.3,Table1381314[[#This Row],[Allowed Hours]]>25.3,Table1381314[[#This Row],[Allowed Hours]])} -> 25.3 | K27: 23.39 | L27: =K27-Table1381314[[#This Row],[Adj Allowed Hrs]] -> -1.91
E28: Baton Rouge South | F28: 832 | G28: 11 | H28: 0.79 | I28: =Table1381314[[#This Row],[LHC]]*Table1381314[[#This Row],[Cars WTD (EDIT)]] -> 8.69 | J28: {=_xlfn.IFS(Table1381314[[#This Row],[Allowed Hours]]=0,0,Table1381314[[#This Row],[Allowed Hours]]<25.3,25.3,Table1381314[[#This Row],[Allowed Hours]]>25.3,Table1381314[[#This Row],[Allowed Hours]])} -> 25.3 | K28: 27.97 | L28: =K28-Table1381314[[#This Row],[Adj Allowed Hrs]] -> 2.67
E29: Gulf Coast North | F29: 3 | G29: 16 | H29: 0.79 | I29: =Table1381314[[#This Row],[LHC]]*Table1381314[[#This Row],[Cars WTD (EDIT)]] -> 12.64 | J29: {=_xlfn.IFS(Table1381314[[#This Row],[Allowed Hours]]=0,0,Table1381314[[#This Row],[Allowed Hours]]<25.3,25.3,Table1381314[[#This Row],[Allowed Hours]]>25.3,Table1381314[[#This Row],[Allowed Hours]])} -> 25.3 | K29: 15 | L29: =K29-Table1381314[[#This Row],[Adj Allowed Hrs]] -> -10.3
E30: Gulf Coast North | F30: 5 | G30: 24 | H30: 0.79 | I30: =Table1381314[[#This Row],[LHC]]*Table1381314[[#This Row],[Cars WTD (EDIT)]] -> 18.96 | J30: {=_xlfn.IFS(Table1381314[[#This Row],[Allowed Hours]]=0,0,Table1381314[[#This Row],[Allowed Hours]]<25.3,25.3,Table1381314[[#This Row],[Allowed Hours]]>25.3,Table1381314[[#This Row],[Allowed Hours]])} -> 25.3 | K30: 35 | L30: =K30-Table1381314[[#This Row],[Adj Allowed Hrs]] -> 9.7
E31: Gulf Coast North | F31: 11 | G31: 16 | H31: 0.79 | I31: =Table1381314[[#This Row],[LHC]]*Table1381314[[#This Row],[Cars WTD (EDIT)]] -> 12.64 | J31: {=_xlfn.IFS(Table1381314[[#This Row],[Allowed Hours]]=0,0,Table1381314[[#This Row],[Allowed Hours]]<25.3,25.3,Table1381314[[#This Row],[Allowed Hours]]>25.3,Table1381314[[#This Row],[Allowed Hours]])} -> 25.3 | K31: 26 | L31: =K31-Table1381314[[#This Row],[Adj Allowed Hrs]] -> 0.7
E32: Gulf Coast North | F32: 14 | G32: 24 | H32: 0.79 | I32: =Table1381314[[#This Row],[LHC]]*Table1381314[[#This Row],[Cars WTD (EDIT)]] -> 18.96 | J32: {=_xlfn.IFS(Table1381314[[#This Row],[Allowed Hours]]=0,0,Table1381314[[#This Row],[Allowed Hours]]<25.3,25.3,Table1381314[[#This Row],[Allowed Hours]]>25.3,Table1381314[[#This Row],[Allowed Hours]])} -> 25.3 | K32: 32 | L32: =K32-Table1381314[[#This Row],[Adj Allowed Hrs]] -> 6.7
E33: Gulf Coast North | F33: 20 | G33: 25 | H33: 0.79 | I33: =Table1381314[[#This Row],[LHC]]*Table1381314[[#This Row],[Cars WTD (EDIT)]] -> 19.75 | J33: {=_xlfn.IFS(Table1381314[[#This Row],[Allowed Hours]]=0,0,Table1381314[[#This Row],[Allowed Hours]]<25.3,25.3,Table1381314[[#This Row],[Allowed Hours]]>25.3,Table1381314[[#This Row],[Allowed Hours]])} -> 25.3 | K33: 25 | L33: =K33-Table1381314[[#This Row],[Adj Allowed Hrs]] -> -0.3
... E70: NOLA South | F70: 3004 | G70: 17 | H70: 0.79 | I70: =Table1381314[[#This Row],[LHC]]*Table1381314[[#This Row],[Cars WTD (EDIT)]] -> 13.43 | J70: {=_xlfn.IFS(Table1381314[[#This Row],[Allowed Hours]]=0,0,Table1381314[[#This Row],[Allowed Hours]]<25.3,25.3,Table1381314[[#This Row],[Allowed Hours]]>25.3,Table1381314[[#This Row],[Allowed Hours]])} -> 25.3 | K70: 21.49 | L70: =K70-Table1381314[[#This Row],[Adj Allowed Hrs]] -> -3.81

Sheet Friday
B2: Minimum Hours WTD - KEY | E2: District | F2: Cars | G2: LHC | H2: Allowed Hours | I2: Actual Hours | J2: Hours Variance
B3: Sunday | C3: 20 | E3: Baton Rouge North | F3: =SUM(G14:G21) -> 0 | G3: 0.79 | H3: =SUM(I14:I21) -> 0 | I3: =SUM(K14:K21) -> 0 | J3: =SUM(L14:L21) -> 0
B4: Monday | C4: 45.3 | E4: Baton Rouge South | F4: =SUM(G22:G28) -> 188 | G4: 0.79 | H4: =SUM(I22:I28) -> 148.52 | I4: =SUM(K22:K28) -> 211.5 | J4: =SUM(L22:L28) -> 29.7
B5: Tuesday | C5: 70.6 | E5: Gulf Coast North | F5: =SUM(G29:G37) -> 365 | G5: 0.79 | H5: =SUM(I29:I37) -> 288.35 | I5: =SUM(K29:K37) -> 295 | J5: =SUM(L29:L37) -> -12.39
B6: Wednesday | C6: 95.93 | E6: Lafayette | F6: =SUM(G38:G45) -> 236 | G6: 0.79 | H6: =SUM(I38:I45) -> 186.44 | I6: =SUM(K38:K45) -> 177.95 | J6: =SUM(L38:L45) -> -44.93
B7: Thursday | C7: 121.23 | E7: Gulf Coast West | F7: =SUM(G46:G52) -> 0 | G7: 0.79 | H7: =SUM(I46:I52) -> 0 | I7: =SUM(K46:K52) -> 0 | J7: =SUM(L46:L52) -> 0
B8: Friday | C8: 146.53 | E8: Nola North | F8: =SUM(G53:G61) -> 415 | G8: 0.79 | H8: =SUM(I53:I61) -> 327.85 | I8: =SUM(K53:K61) -> 319.8 | J8: =SUM(L53:L61) -> -12.83
B9: Saturday | C9: 171.8 | E9: Nola South | F9: =SUM(G62:G70) -> 0 | G9: 0.79 | H9: =SUM(I62:I70) -> 0 | I9: =SUM(K62:K70) -> 0 | J9: =SUM(L62:L70) -> 0
E10: Region | F10: =SUM(F3:F9) -> 1204 | G10: 0.79 | H10: =SUM(H3:H9) -> 951.16 | I10: =SUM(I3:I9) -> 1004.25 | J10: =SUM(J3:J9) -> -40.45
E13: District | F13: Store | G13: Cars WTD (EDIT) | H13: LHC | I13: Allowed Hours | J13: Adj Allowed Hrs | K13: Actual Hours (EDIT) | L13: Hours Variance
E14: Baton Rouge North | F14: 17 | H14: 0.79 | I14: =Table13813141516[[#This Row],[LHC]]*Table13813141516[[#This Row],[Cars WTD (EDIT)]] -> 0 | J14: {=_xlfn.IFS(Table13813141516[[#This Row],[Allowed Hours]]=0,0,Table13813141516[[#This Row],[Allowed Hours]]<25.3,25.3,Table13813141516[[#This Row],[Allowed Hours]]>25.3,Table13813141516[[#This Row],[Allowed Hours]])} -> 0 | L14: =K14-Table13813141516[[#This Row],[Adj Allowed Hrs]] -> 0
E15: Baton Rouge North | F15: 22 | H15: 0.79 | I15: =Table13813141516[[#This Row],[LHC]]*Table13813141516[[#This Row],[Cars WTD (EDIT)]] -> 0 | J15: {=_xlfn.IFS(Table13813141516[[#This Row],[Allowed Hours]]=0,0,Table13813141516[[#This Row],[Allowed Hours]]<25.3,25.3,Table13813141516[[#This Row],[Allowed Hours]]>25.3,Table13813141516[[#This Row],[Allowed Hours]])} -> 0 | L15: =K15-Table13813141516[[#This Row],[Adj Allowed Hrs]] -> 0
E16: Baton Rouge North | F16: 641 | H16: 0.79 | I16: =Table13813141516[[#This Row],[LHC]]*Table13813141516[[#This Row],[Cars WTD (EDIT)]] -> 0 | J16: {=_xlfn.IFS(Table13813141516[[#This Row],[Allowed Hours]]=0,0,Table13813141516[[#This Row],[Allowed Hours]]<25.3,25.3,Table13813141516[[#This Row],[Allowed Hours]]>25.3,Table13813141516[[#This Row],[Allowed Hours]])} -> 0 | L16: =K16-Table13813141516[[#This Row],[Adj Allowed Hrs]] -> 0
E17: Baton Rouge North | F17: 717 | H17: 0.79 | I17: =Table13813141516[[#This Row],[LHC]]*Table13813141516[[#This Row],[Cars WTD (EDIT)]] -> 0 | J17: {=_xlfn.IFS(Table13813141516[[#This Row],[Allowed Hours]]=0,0,Table13813141516[[#This Row],[Allowed Hours]]<25.3,25.3,Table13813141516[[#This Row],[Allowed Hours]]>25.3,Table13813141516[[#This Row],[Allowed Hours]])} -> 0 | L17: =K17-Table13813141516[[#This Row],[Adj Allowed Hrs]] -> 0
E18: Baton Rouge North | F18: 843 | H18: 0.79 | I18: =Table13813141516[[#This Row],[LHC]]*Table13813141516[[#This Row],[Cars WTD (EDIT)]] -> 0 | J18: {=_xlfn.IFS(Table13813141516[[#This Row],[Allowed Hours]]=0,0,Table13813141516[[#This Row],[Allowed Hours]]<25.3,25.3,Table13813141516[[#This Row],[Allowed Hours]]>25.3,Table13813141516[[#This Row],[Allowed Hours]])} -> 0 | L18: =K18-Table13813141516[[#This Row],[Adj Allowed Hrs]] -> 0
E19: Baton Rouge North | F19: 881 | H19: 0.79 | I19: =Table13813141516[[#This Row],[LHC]]*Table13813141516[[#This Row],[Cars WTD (EDIT)]] -> 0 | J19: {=_xlfn.IFS(Table13813141516[[#This Row],[Allowed Hours]]=0,0,Table13813141516[[#This Row],[Allowed Hours]]<25.3,25.3,Table13813141516[[#This Row],[Allowed Hours]]>25.3,Table13813141516[[#This Row],[Allowed Hours]])} -> 0 | L19: =K19-Table13813141516[[#This Row],[Adj Allowed Hrs]] -> 0
E20: Baton Rouge North | F20: 953 | H20: 0.79 | I20: =Table13813141516[[#This Row],[LHC]]*Table13813141516[[#This Row],[Cars WTD (EDIT)]] -> 0 | J20: {=_xlfn.IFS(Table13813141516[[#This Row],[Allowed Hours]]=0,0,Table13813141516[[#This Row],[Allowed Hours]]<25.3,25.3,Table13813141516[[#This Row],[Allowed Hours]]>25.3,Table13813141516[[#This Row],[Allowed Hours]])} -> 0 | L20: =K20-Table13813141516[[#This Row],[Adj Allowed Hrs]] -> 0
E21: Baton Rouge North | F21: 3040 | H21: 0.79 | I21: =Table13813141516[[#This Row],[LHC]]*Table13813141516[[#This Row],[Cars WTD (EDIT)]] -> 0 | J21: {=_xlfn.IFS(Table13813141516[[#This Row],[Allowed Hours]]=0,0,Table13813141516[[#This Row],[Allowed Hours]]<25.3,25.3,Table13813141516[[#This Row],[Allowed Hours]]>25.3,Table13813141516[[#This Row],[Allowed Hours]])} -> 0 | L21: =K21-Table13813141516[[#This Row],[Adj Allowed Hrs]] -> 0
E22: Baton Rouge South | F22: 18 | G22: 36 | H22: 0.79 | I22: =Table13813141516[[#This Row],[LHC]]*Table13813141516[[#This Row],[Cars WTD (EDIT)]] -> 28.44 | J22: {=_xlfn.IFS(Table13813141516[[#This Row],[Allowed Hours]]=0,0,Table13813141516[[#This Row],[Allowed Hours]]<25.3,25.3,Table13813141516[[#This Row],[Allowed Hours]]>25.3,Table13813141516[[#This Row],[Allowed Hours]])} -> 28.44 | K22: 30.93 | L22: =K22-Table13813141516[[#This Row],[Adj Allowed Hrs]] -> 2.49
E23: Baton Rouge South | F23: 19 | G23: 24 | H23: 0.79 | I23: =Table13813141516[[#This Row],[LHC]]*Table13813141516[[#This Row],[Cars WTD (EDIT)]] -> 18.96 | J23: {=_xlfn.IFS(Table13813141516[[#This Row],[Allowed Hours]]=0,0,Table13813141516[[#This Row],[Allowed Hours]]<25.3,25.3,Table13813141516[[#This Row],[Allowed Hours]]>25.3,Table13813141516[[#This Row],[Allowed Hours]])} -> 25.3 | K23: 33.07 | L23: =K23-Table13813141516[[#This Row],[Adj Allowed Hrs]] -> 7.77
E24: Baton Rouge South | F24: 282 | G24: 12 | H24: 0.79 | I24: =Table13813141516[[#This Row],[LHC]]*Table13813141516[[#This Row],[Cars WTD (EDIT)]] -> 9.48 | J24: {=_xlfn.IFS(Table13813141516[[#This Row],[Allowed Hours]]=0,0,Table13813141516[[#This Row],[Allowed Hours]]<25.3,25.3,Table13813141516[[#This Row],[Allowed Hours]]>25.3,Table13813141516[[#This Row],[Allowed Hours]])} -> 25.3 | K24: 13.3 | L24: =K24-Table13813141516[[#This Row],[Adj Allowed Hrs]] -> -12
E25: Baton Rouge South | F25: 447 | G25: 27 | H25: 0.79 | I25: =Table13813141516[[#This Row],[LHC]]*Table13813141516[[#This Row],[Cars WTD (EDIT)]] -> 21.33 | J25: {=_xlfn.IFS(Table13813141516[[#This Row],[Allowed Hours]]=0,0,Table13813141516[[#This Row],[Allowed Hours]]<25.3,25.3,Table13813141516[[#This Row],[Allowed Hours]]>25.3,Table13813141516[[#This Row],[Allowed Hours]])} -> 25.3 | K25: 28.39 | L25: =K25-Table13813141516[[#This Row],[Adj Allowed Hrs]] -> 3.09
E26: Baton Rouge South | F26: 448 | G26: 34 | H26: 0.79 | I26: =Table13813141516[[#This Row],[LHC]]*Table13813141516[[#This Row],[Cars WTD (EDIT)]] -> 26.86 | J26: {=_xlfn.IFS(Table13813141516[[#This Row],[Allowed Hours]]=0,0,Table13813141516[[#This Row],[Allowed Hours]]<25.3,25.3,Table13813141516[[#This Row],[Allowed Hours]]>25.3,Table13813141516[[#This Row],[Allowed Hours]])} -> 26.86 | K26: 48.79 | L26: =K26-Table13813141516[[#This Row],[Adj Allowed Hrs]] -> 21.93
E27: Baton Rouge South | F27: 531 | G27: 24 | H27: 0.79 | I27: =Table13813141516[[#This Row],[LHC]]*Table13813141516[[#This Row],[Cars WTD (EDIT)]] -> 18.96 | J27: {=_xlfn.IFS(Table13813141516[[#This Row],[Allowed Hours]]=0,0,Table13813141516[[#This Row],[Allowed Hours]]<25.3,25.3,Table13813141516[[#This Row],[Allowed Hours]]>25.3,Table13813141516[[#This Row],[Allowed Hours]])} -> 25.3 | K27: 24.18 | L27: =K27-Table13813141516[[#This Row],[Adj Allowed Hrs]] -> -1.12
