Workbook
Name Slicer_District: #N/A
Name Slicer_District1: #N/A
Name Slicer_District2: #N/A
Name Slicer_District3: #N/A
Name Slicer_District4: #N/A
Name Slicer_District5: #N/A

Sheet P10 - 10-04
A1: District | B1: Lubricants/Oil +/- | C1: Oil +/- | D1: Oil Filters +/- | E1: Air Filters +/- | F1: Wipers +/- | G1: Cabins +/- | H1: Adjustment Variance | I1: On Time Counts | J1: Count Compliance | L1: Comp Sales | M1: Comp Attainment | N1: Big 4 | O1: Coolant | S1: Total Count Target | T1: 10
A2: =A12 -> Baton Rouge North | B2: =SUM(C12:C19) -> 1873.86 | C2: =SUM(D12:D19) -> 1258.76 | D2: =SUM(E12:E19) -> 3120 | E2: =SUM(F12:F19) -> 1848 | F2: =SUM(G12:G19) -> 98 | G2: =SUM(H12:H19) -> 375 | H2: =SUM(I12:I19) -> 10715.433 | I2: =SUM(J12:J19) -> 26 | J2: =I2/SUM(S12:S19) -> 0.43333333 | L2: =SUM(L12:L12) -> 4238.98 | M2: =((F2-G12)/L2)-100% -> -1.0087285 | N2: =SUM(N12:N12)/C2 -> 0 | O2: =SUM(P12:P12)/C2 -> 0.00015888652
A3: =A20 -> Baton Rouge South | B3: =SUM(C20:C26) -> 8854.1 | C3: =SUM(D20:D26) -> 8877.1 | D3: =SUM(E20:E26) -> -98 | E3: =SUM(F20:F26) -> -221 | F3: =SUM(G20:G26) -> -6 | G3: =SUM(H20:H26) -> 59 | H3: =SUM(I20:I26) -> 24224.69 | I3: =SUM(J20:J26) -> 50 | J3: =I3/SUM(S20:S26) -> 0.71428571 | L3: =SUM(L13:L13) -> 5844.34 | M3: =((F3-G13)/L3)-100% -> -0.99914447 | N3: =SUM(N13:N13)/C3 -> 0 | O3: =SUM(P13:P13)/C3 -> 9.0119521e-05
A4: =A27 -> Gulf Coast North | B4: =SUM(C27:C35) -> 2359 | C4: =SUM(D27:D35) -> 1764 | D4: =SUM(E27:E35) -> 251 | E4: =SUM(F27:F35) -> 27 | F4: =SUM(G27:G35) -> 35 | G4: =SUM(H27:H35) -> 1 | H4: =SUM(I27:I35) -> 7304.62 | I4: =SUM(J27:J35) -> 64 | J4: =I4/SUM(S27:S35) -> 0.71111111 | L4: =SUM(L14:L23) -> 52541.38 | M4: =(F4/L4)-100% -> -0.99933386 | N4: =SUM(N14:N23)/C4 -> 0 | O4: =SUM(P14:P23)/C4 -> #DIV/0!
A5: =A36 -> Gulf Coast West | B5: =SUM(C36:C42) -> 250 | C5: =SUM(D36:D42) -> 335 | D5: =SUM(E36:E42) -> -67 | E5: =SUM(F36:F42) -> 20 | F5: =SUM(G36:G42) -> -27 | G5: =SUM(H36:H42) -> 9 | H5: =SUM(I36:I42) -> 2935.66 | I5: =SUM(J36:J42) -> 43 | J5: =I5/SUM(S36:S42) -> 0.61428571 | L5: =SUM(L24:L36) -> 80972.98 | M5: =((F5-G34-G35-G36)/L5)-100% -> -1.0006792 | N5: =SUM(N24:N36)/C5 -> 0 | O5: =SUM(P24:P36)/C5 -> 0.028358209
A6: =A43 -> Lafayette | B6: =SUM(C43:C50) -> 360 | C6: =SUM(D43:D50) -> 222 | D6: =SUM(E43:E50) -> -55 | E6: =SUM(F43:F50) -> 18 | F6: =SUM(G43:G50) -> -20 | G6: =SUM(H43:H50) -> 15 | H6: =SUM(I43:I50) -> 1339.84 | I6: =SUM(J43:J50) -> 55 | J6: =I6/SUM(S43:S50) -> 0.6875
A7: =A51 -> NOLA North | B7: =SUM(C51:C59) -> 10467 | C7: =SUM(D51:D59) -> 4176 | D7: =SUM(E51:E59) -> 19 | E7: =SUM(F51:F59) -> -18 | F7: =SUM(G51:G59) -> -17 | G7: =SUM(H51:H59) -> -2 | H7: =SUM(I51:I59) -> 12242.56 | I7: =SUM(J51:J59) -> 71 | J7: =I7/SUM(S51:S59) -> 0.8875 | L7: =SUM(L37:L45) -> 38554.76 | M7: =(F7/L7)-100% -> -1.0004409 | N7: =SUM(N37:N45)/C7 -> 0 | O7: =SUM(P37:P45)/C7 -> 0.0014128352
A8: =A60 -> NOLA South | B8: =SUM(C60:C68) -> 3069 | C8: =SUM(D60:D68) -> 2143 | D8: =SUM(E60:E68) -> 44 | E8: =SUM(F60:F68) -> 1 | F8: =SUM(G60:G68) -> 37 | G8: =SUM(H60:H68) -> 16 | H8: =SUM(I60:I68) -> 7552.56 | I8: =SUM(J60:J68) -> 67 | J8: =I8/SUM(S60:S68) -> 0.74444444 | L8: =SUM(L46:L54) -> 19465.43 | M8: =((F8-G54)/L8)-100% -> -0.99804782 | N8: =SUM(N46:N54)/C8 -> 0.00046663556 | O8: =SUM(P46:P54)/C8 -> 0.0031264582
A9: Gulf Coast | B9: =SUM(B2:B8) -> 27232.96 | C9: =SUM(C2:C8) -> 18775.86 | D9: =SUM(D2:D8) -> 3214 | E9: =SUM(E2:E8) -> 1675 | F9: =SUM(F2:F8) -> 100 | G9: =SUM(G2:G8) -> 473 | H9: =SUM(H2:H8) -> 66315.363 | I9: =SUM(I2:I8) -> 376 | J9: =I9/SUM(S12:S68) -> 0.6962963 | L9: =SUM(L2:L8) -> 201617.87 | M9: =((F9-G12-G13-G34-G35-G36-G54)/L9)-100% -> -1.000253 | N9: {=SUM(Table17891011121323578[Big 4 Items]/C9)} -> 5.3259877e-05 | O9: =SUM(Table17891011121323578[Count Compliance2])/C9 -> #DIV/0!
A11: District | B11: Store | C11: Lubricants/Oil +/- | D11: Oil +/- | E11: Oil Filters +/- | F11: Air Filters +/- | G11: Wipers +/- | H11: Cabins +/- | I11: Adjustment Variance | J11: On Time Counts | K11: Count Compliance | L11: Comp Sales | M11: Comp Sales Attainment | N11: Big 4 Items | O11: Big 4 | P11: Count Compliance2
A12: Baton Rouge North | B12: 17 | C12: 48 | E12: 3112 | F12: 1835 | G12: 135 | H12: 348 | I12: 8483.27 | J12: 2 | K12: =Table17891011121323578[[#This Row],[On Time Counts]]/45 -> 0.044444444 | L12: 4238.98 | M12: =Table17891011121323578[[#This Row],[Wipers +/-]]/Table17891011121323578[[#This Row],[Comp Sales]] -> 0.031847284 | N12: 0 | O12: =Table17891011121323578[[#This Row],[Big 4 Items]]/Table17891011121323578[[#This Row],[Oil +/- ]] -> #DIV/0! | P12: =J12/S12 -> 0.2 | S12: =$T$1 -> 10
A13: Baton Rouge North | B13: 22 | C13: 256.77 | D13: -182.33 | E13: 239 | F13: 8 | G13: -11 | H13: 18 | I13: 283.3616 | J13: 8 | K13: =Table17891011121323578[[#This Row],[On Time Counts]]/45 -> 0.17777778 | L13: 5844.34 | M13: =Table17891011121323578[[#This Row],[Wipers +/-]]/Table17891011121323578[[#This Row],[Comp Sales]] -> -0.0018821629 | N13: 0 | O13: =Table17891011121323578[[#This Row],[Big 4 Items]]/Table17891011121323578[[#This Row],[Oil +/- ]] -> 0 | P13: =J13/S13 -> 0.8 | S13: =$T$1 -> 10
A14: Baton Rouge North | B14: 641 | C14: -137.53 | D14: -153.23 | E14: -87 | F14: -2 | G14: 5 | H14: 21 | I14: -628.635 | J14: 8 | K14: =Table17891011121323578[[#This Row],[On Time Counts]]/45 -> 0.17777778 | L14: 3219.34 | M14: =Table17891011121323578[[#This Row],[Wipers +/-]]/Table17891011121323578[[#This Row],[Comp Sales]] -> 0.0015531134 | N14: 0 | O14: =Table17891011121323578[[#This Row],[Big 4 Items]]/Table17891011121323578[[#This Row],[Oil +/- ]] -> 0 | P14: =J14/S14 -> 0.8 | S14: =$T$1 -> 10
A15: Baton Rouge North | B15: 717 | C15: 1012.4 | D15: 900.1 | E15: -144 | F15: 14 | G15: -29 | H15: -12 | I15: 890.639 | J15: 0 | K15: =Table17891011121323578[[#This Row],[On Time Counts]]/45 -> 0 | L15: 8034.77 | M15: =Table17891011121323578[[#This Row],[Wipers +/-]]/Table17891011121323578[[#This Row],[Comp Sales]] -> -0.003609313 | N15: 0 | O15: =Table17891011121323578[[#This Row],[Big 4 Items]]/Table17891011121323578[[#This Row],[Oil +/- ]] -> 0 | P15: =J15/S15 -> 0 | S15: =$T$1 -> 10
A16: Baton Rouge North | B16: 843 | C16: 465.22 | D16: 465.22 | F16: -7 | H16: -1 | I16: 1022.2972 | J16: 2 | K16: =Table17891011121323578[[#This Row],[On Time Counts]]/45 -> 0.044444444 | L16: 6497.34 | M16: =Table17891011121323578[[#This Row],[Wipers +/-]]/Table17891011121323578[[#This Row],[Comp Sales]] -> 0 | N16: 0 | O16: =Table17891011121323578[[#This Row],[Big 4 Items]]/Table17891011121323578[[#This Row],[Oil +/- ]] -> 0 | P16: =J16/S16 -> 0.2 | S16: =$T$1 -> 10
A17: Baton Rouge North | B17: 881 | C17: 229 | D17: 229 | E17: 0 | G17: -2 | H17: 1 | I17: 664.5 | J17: 6 | K17: =Table17891011121323578[[#This Row],[On Time Counts]]/45 -> 0.13333333 | M17: =Table17891011121323578[[#This Row],[Wipers +/-]]/Table17891011121323578[[#This Row],[Comp Sales]] -> #DIV/0! | O17: =Table17891011121323578[[#This Row],[Big 4 Items]]/Table17891011121323578[[#This Row],[Oil +/- ]] -> 0 | P17: =J17/S17 -> 0.6 | S17: =$T$1 -> 10
A18: Baton Rouge North | B18: 953 | C18: 0 | D18: 0 | E18: 0 | F18: 0 | G18: 0 | H18: 0 | I18: 0 | J18: 0 | K18: =Table17891011121323578[[#This Row],[On Time Counts]]/45 -> 0 | L18: 7185.39 | M18: =Table17891011121323578[[#This Row],[Wipers +/-]]/Table17891011121323578[[#This Row],[Comp Sales]] -> 0 | N18: 0 | O18: =Table17891011121323578[[#This Row],[Big 4 Items]]/Table17891011121323578[[#This Row],[Oil +/- ]] -> #DIV/0! | P18: =J18/S18 -> #DIV/0! | S18: 0
A19: Baton Rouge North | B19: 3040 | C19: 0 | D19: 0 | E19: 0 | F19: 0 | G19: 0 | H19: 0 | I19: 0 | J19: 0 | K19: =Table17891011121323578[[#This Row],[On Time Counts]]/45 -> 0 | L19: 6083.18 | M19: =Table17891011121323578[[#This Row],[Wipers +/-]]/Table17891011121323578[[#This Row],[Comp Sales]] -> 0 | N19: 0 | O19: =Table17891011121323578[[#This Row],[Big 4 Items]]/Table17891011121323578[[#This Row],[Oil +/- ]] -> #DIV/0! | P19: =J19/S19 -> #DIV/0! | S19: 0
A20: Baton Rouge South | B20: 18 | C20: 2786.62 | D20: 2786.62 | E20: -366 | F20: -39 | G20: -8 | H20: 90 | I20: 6361.9176 | J20: 6 | K20: =Table17891011121323578[[#This Row],[On Time Counts]]/45 -> 0.13333333 | L20: 4849.02 | M20: =Table17891011121323578[[#This Row],[Wipers +/-]]/Table17891011121323578[[#This Row],[Comp Sales]] -> -0.0016498179 | N20: 0 | O20: =Table17891011121323578[[#This Row],[Big 4 Items]]/Table17891011121323578[[#This Row],[Oil +/- ]] -> 0 | P20: =J20/S20 -> 0.6 | S20: =$T$1 -> 10
A21: Baton Rouge South | B21: 19 | C21: -442.92 | D21: -442.92 | E21: -34 | F21: -1 | G21: 5 | H21: -4 | I21: -2209.3892 | J21: 7 | K21: =Table17891011121323578[[#This Row],[On Time Counts]]/45 -> 0.15555556 | L21: 2994.56 | M21: =Table17891011121323578[[#This Row],[Wipers +/-]]/Table17891011121323578[[#This Row],[Comp Sales]] -> 0.0016696944 | N21: 0 | O21: =Table17891011121323578[[#This Row],[Big 4 Items]]/Table17891011121323578[[#This Row],[Oil +/- ]] -> 0 | P21: =J21/S21 -> 0.7 | S21: =$T$1 -> 10
A22: Baton Rouge South | B22: 282 | C22: 66.72 | D22: 89.72 | E22: 189 | F22: -17 | G22: 28 | H22: -32 | I22: 566.553 | J22: 7 | K22: =Table17891011121323578[[#This Row],[On Time Counts]]/45 -> 0.15555556 | L22: 6870.99 | M22: =Table17891011121323578[[#This Row],[Wipers +/-]]/Table17891011121323578[[#This Row],[Comp Sales]] -> 0.0040751042 | N22: 0 | O22: =Table17891011121323578[[#This Row],[Big 4 Items]]/Table17891011121323578[[#This Row],[Oil +/- ]] -> 0 | P22: =J22/S22 -> 0.7 | S22: =$T$1 -> 10
A23: Baton Rouge South | B23: 447 | C23: -65.7 | D23: -65.7 | E23: 91 | F23: -164 | I23: -828.548 | J23: 6 | K23: =Table17891011121323578[[#This Row],[On Time Counts]]/45 -> 0.13333333 | L23: 6806.79 | M23: =Table17891011121323578[[#This Row],[Wipers +/-]]/Table17891011121323578[[#This Row],[Comp Sales]] -> 0 | N23: 0 | O23: =Table17891011121323578[[#This Row],[Big 4 Items]]/Table17891011121323578[[#This Row],[Oil +/- ]] -> 0 | P23: =J23/S23 -> 0.6 | S23: =$T$1 -> 10
A24: Baton Rouge South | B24: 448 | C24: 5943.08 | D24: 5943.08 | E24: 15 | F24: 1 | G24: -7 | H24: 6 | I24: 18487.379 | J24: 8 | K24: =Table17891011121323578[[#This Row],[On Time Counts]]/45 -> 0.17777778 | L24: 3933.29 | M24: =Table17891011121323578[[#This Row],[Wipers +/-]]/Table17891011121323578[[#This Row],[Comp Sales]] -> -0.0017796806 | N24: 0 | O24: =Table17891011121323578[[#This Row],[Big 4 Items]]/Table17891011121323578[[#This Row],[Oil +/- ]] -> 0 | P24: =J24/S24 -> 0.8 | S24: =$T$1 -> 10
A25: Baton Rouge South | B25: 531 | C25: 275.3 | D25: 275.3 | E25: -11 | G25: -25 | H25: -5 | I25: 741.448 | J25: 8 | K25: =Table17891011121323578[[#This Row],[On Time Counts]]/45 -> 0.17777778 | L25: 6987.69 | M25: =Table17891011121323578[[#This Row],[Wipers +/-]]/Table17891011121323578[[#This Row],[Comp Sales]] -> -0.0035777202 | N25: 0 | O25: =Table17891011121323578[[#This Row],[Big 4 Items]]/Table17891011121323578[[#This Row],[Oil +/- ]] -> 0 | P25: =J25/S25 -> 0.8 | S25: =$T$1 -> 10
A26: Baton Rouge South | B26: 832 | C26: 291 | D26: 291 | E26: 18 | F26: -1 | G26: 1 | H26: 4 | I26: 1105.33 | J26: 8 | K26: =Table17891011121323578[[#This Row],[On Time Counts]]/45 -> 0.17777778 | L26: 5562.48 | M26: =Table17891011121323578[[#This Row],[Wipers +/-]]/Table17891011121323578[[#This Row],[Comp Sales]] -> 0.00017977593 | N26: 0 | O26: =Table17891011121323578[[#This Row],[Big 4 Items]]/Table17891011121323578[[#This Row],[Oil +/- ]] -> 0 | P26: =J26/S26 -> 0.8 | S26: =$T$1 -> 10
A27: Gulf Coast North | B27: 3 | K27: =Table17891011121323578[[#This Row],[On Time Counts]]/45 -> 0 | L27: 10385.27 | M27: =Table17891011121323578[[#This Row],[Wipers +/-]]/Table17891011121323578[[#This Row],[Comp Sales]] -> 0 | N27: 0 | O27: =Table17891011121323578[[#This Row],[Big 4 Items]]/Table17891011121323578[[#This Row],[Oil +/- ]] -> #DIV/0! | P27: =J27/S27 -> 0 | S27: =$T$1 -> 10
A28: Gulf Coast North | B28: 5 | C28: -132 | D28: -132 | E28: 20 | F28: 0 | G28: 4 | H28: 8 | I28: -347.87 | J28: 9 | K28: =Table17891011121323578[[#This Row],[On Time Counts]]/45 -> 0.2 | L28: 5512.41 | M28: =Table17891011121323578[[#This Row],[Wipers +/-]]/Table17891011121323578[[#This Row],[Comp Sales]] -> 0.00072563543 | N28: 0 | O28: =Table17891011121323578[[#This Row],[Big 4 Items]]/Table17891011121323578[[#This Row],[Oil +/- ]] -> 0 | P28: =J28/S28 -> 0.9 | S28: =$T$1 -> 10
A29: Gulf Coast North | B29: 11 | C29: -114 | D29: -51 | E29: -6 | F29: 0 | G29: 2 | H29: 0 | I29: -1307.92 | J29: 10 | K29: =Table17891011121323578[[#This Row],[On Time Counts]]/45 -> 0.22222222 | L29: 7892.5 | M29: =Table17891011121323578[[#This Row],[Wipers +/-]]/Table17891011121323578[[#This Row],[Comp Sales]] -> 0.00025340513 | N29: 0 | O29: =Table17891011121323578[[#This Row],[Big 4 Items]]/Table17891011121323578[[#This Row],[Oil +/- ]] -> 0 | P29: =J29/S29 -> 1 | S29: =$T$1 -> 10
A30: Gulf Coast North | B30: 14 | C30: 1132 | D30: 893 | E30: 8 | F30: -3 | G30: 2 | H30: 1 | I30: 4441.76 | J30: 9 | K30: =Table17891011121323578[[#This Row],[On Time Counts]]/45 -> 0.2 | L30: 3854.43 | M30: =Table17891011121323578[[#This Row],[Wipers +/-]]/Table17891011121323578[[#This Row],[Comp Sales]] -> 0.00051888347 | N30: 0 | O30: =Table17891011121323578[[#This Row],[Big 4 Items]]/Table17891011121323578[[#This Row],[Oil +/- ]] -> 0 | P30: =J30/S30 -> 0.9 | S30: =$T$1 -> 10
A31: Gulf Coast North | B31: 20 | C31: 20 | D31: 20 | E31: 9 | F31: -2 | G31: 0 | H31: 1 | I31: 54.75 | J31: 5 | K31: =Table17891011121323578[[#This Row],[On Time Counts]]/45 -> 0.11111111 | L31: 6979.44 | M31: =Table17891011121323578[[#This Row],[Wipers +/-]]/Table17891011121323578[[#This Row],[Comp Sales]] -> 0 | N31: 0 | O31: =Table17891011121323578[[#This Row],[Big 4 Items]]/Table17891011121323578[[#This Row],[Oil +/- ]] -> 0 | P31: =J31/S31 -> 0.5 | S31: =$T$1 -> 10
A32: Gulf Coast North | B32: 21 | C32: -251 | D32: -261 | E32: -1 | F32: 0 | G32: 0 | H32: 0 | I32: -595.38 | J32: 10 | K32: =Table17891011121323578[[#This Row],[On Time Counts]]/45 -> 0.22222222 | L32: 7573.54 | M32: =Table17891011121323578[[#This Row],[Wipers +/-]]/Table17891011121323578[[#This Row],[Comp Sales]] -> 0 | N32: 0 | O32: =Table17891011121323578[[#This Row],[Big 4 Items]]/Table17891011121323578[[#This Row],[Oil +/- ]] -> 0 | P32: =J32/S32 -> 1 | S32: =$T$1 -> 10
A33: Gulf Coast North | B33: 23 | C33: 907 | D33: 500 | E33: 221 | F33: 10 | H33: 0 | I33: 2238.84 | J33: 4 | K33: =Table17891011121323578[[#This Row],[On Time Counts]]/45 -> 0.088888889 | L33: 5842.02 | M33: =Table17891011121323578[[#This Row],[Wipers +/-]]/Table17891011121323578[[#This Row],[Comp Sales]] -> 0 | N33: 0 | O33: =Table17891011121323578[[#This Row],[Big 4 Items]]/Table17891011121323578[[#This Row],[Oil +/- ]] -> 0 | P33: =J33/S33 -> 0.4 | S33: =$T$1 -> 10
A34: Gulf Coast North | B34: 24 | C34: 775 | D34: 775 | E34: 0 | F34: -4 | G34: -4 | H34: -10 | I34: 3040.69 | J34: 8 | K34: =Table17891011121323578[[#This Row],[On Time Counts]]/45 -> 0.17777778 | L34: 6567.35 | M34: =Table17891011121323578[[#This Row],[Wipers +/-]]/Table17891011121323578[[#This Row],[Comp Sales]] -> -0.00060907368 | N34: 0 | O34: =Table17891011121323578[[#This Row],[Big 4 Items]]/Table17891011121323578[[#This Row],[Oil +/- ]] -> 0 | P34: =J34/S34 -> 0.8 | S34: =$T$1 -> 10
A35: Gulf Coast North | B35: 26 | C35: 22 | D35: 20 | F35: 26 | G35: 31 | H35: 1 | I35: -220.25 | J35: 9 | K35: =Table17891011121323578[[#This Row],[On Time Counts]]/45 -> 0.2 | L35: 5286.48 | M35: =Table17891011121323578[[#This Row],[Wipers +/-]]/Table17891011121323578[[#This Row],[Comp Sales]] -> 0.0058640154 | N35: 0 | O35: =Table17891011121323578[[#This Row],[Big 4 Items]]/Table17891011121323578[[#This Row],[Oil +/- ]] -> 0 | P35: =J35/S35 -> 0.9 | S35: =$T$1 -> 10
A36: Gulf Coast West | B36: 46 | C36: -142 | D36: -142 | E36: -7 | F36: 2 | G36: 1 | H36: 1 | I36: -332.42 | J36: 7 | K36: =Table17891011121323578[[#This Row],[On Time Counts]]/45 -> 0.15555556 | L36: 4596.08 | M36: =Table17891011121323578[[#This Row],[Wipers +/-]]/Table17891011121323578[[#This Row],[Comp Sales]] -> 0.00021757672 | N36: 0 | O36: =Table17891011121323578[[#This Row],[Big 4 Items]]/Table17891011121323578[[#This Row],[Oil +/- ]] -> 0 | P36: =J36/S36 -> 0.7 | S36: =$T$1 -> 10
A37: Gulf Coast West | B37: 283 | C37: 37 | D37: 33 | E37: -122 | I37: 54.5 | J37: 4 | K37: =Table17891011121323578[[#This Row],[On Time Counts]]/45 -> 0.088888889 | L37: 7096.63 | M37: =Table17891011121323578[[#This Row],[Wipers +/-]]/Table17891011121323578[[#This Row],[Comp Sales]] -> 0 | N37: 0 | O37: =Table17891011121323578[[#This Row],[Big 4 Items]]/Table17891011121323578[[#This Row],[Oil +/- ]] -> 0 | P37: =J37/S37 -> 0.4 | S37: =$T$1 -> 10
A38: Gulf Coast West | B38: 847 | C38: 41 | D38: 41 | E38: 86 | F38: 21 | G38: -24 | H38: 8 | I38: 707.47 | J38: 5 | K38: =Table17891011121323578[[#This Row],[On Time Counts]]/45 -> 0.11111111 | L38: 6662.04 | M38: =Table17891011121323578[[#This Row],[Wipers +/-]]/Table17891011121323578[[#This Row],[Comp Sales]] -> -0.0036025001 | N38: 0 | O38: =Table17891011121323578[[#This Row],[Big 4 Items]]/Table17891011121323578[[#This Row],[Oil +/- ]] -> 0 | P38: =J38/S38 -> 0.5 | S38: =$T$1 -> 10
A39: Gulf Coast West | B39: 865 | C39: -75 | D39: 9 | E39: -2 | F39: -2 | G39: -2 | H39: 2 | I39: 371.71 | J39: 10 | K39: =Table17891011121323578[[#This Row],[On Time Counts]]/45 -> 0.22222222 | L39: 3219.44 | M39: =Table17891011121323578[[#This Row],[Wipers +/-]]/Table17891011121323578[[#This Row],[Comp Sales]] -> -0.00062122605 | N39: 0 | O39: =Table17891011121323578[[#This Row],[Big 4 Items]]/Table17891011121323578[[#This Row],[Oil +/- ]] -> 0 | P39: =J39/S39 -> 1 | S39: =$T$1 -> 10
A40: Gulf Coast West | B40: 919 | C40: 32 | D40: 33 | E40: -1 | G40: -2 | H40: -1 | I40: 98.66 | J40: 8 | K40: =Table17891011121323578[[#This Row],[On Time Counts]]/45 -> 0.17777778 | L40: 3981.57 | M40: =Table17891011121323578[[#This Row],[Wipers +/-]]/Table17891011121323578[[#This Row],[Comp Sales]] -> -0.00050231441 | N40: 0 | O40: =Table17891011121323578[[#This Row],[Big 4 Items]]/Table17891011121323578[[#This Row],[Oil +/- ]] -> 0 | P40: =J40/S40 -> 0.8 | S40: =$T$1 -> 10
A41: Gulf Coast West | B41: 954 | C41: 15 | D41: 11 | E41: -10 | F41: -1 | I41: 15.53 | J41: 2 | K41: =Table17891011121323578[[#This Row],[On Time Counts]]/45 -> 0.044444444 | M41: =Table17891011121323578[[#This Row],[Wipers +/-]]/Table17891011121323578[[#This Row],[Comp Sales]] -> #DIV/0! | O41: =Table17891011121323578[[#This Row],[Big 4 Items]]/Table17891011121323578[[#This Row],[Oil +/- ]] -> 0 | P41: =J41/S41 -> 0.2 | S41: =$T$1 -> 10
...

Sheet P10 - 10-11
A1: District | B1: Lubricants/Oil +/- | C1: Oil +/- | D1: Oil Filters +/- | E1: Air Filters +/- | F1: Wipers +/- | G1: Cabins +/- | H1: Adjustment Variance | I1: On Time Counts | J1: Count Compliance | L1: Comp Sales | M1: Comp Attainment | N1: Big 4 | O1: Coolant | S1: Total Count Target | T1: 11
A2: =A12 -> Baton Rouge North | B2: =SUM(C12:C19) -> 1818.2 | C2: =SUM(D12:D19) -> 1744.2 | D2: =SUM(E12:E19) -> 223 | E2: =SUM(F12:F19) -> 9 | F2: =SUM(G12:G19) -> 31 | G2: =SUM(H12:H19) -> 50 | H2: =SUM(I12:I19) -> 7068.3628 | I2: =SUM(J12:J19) -> 25 | J2: =I2/SUM(S12:S19) -> 0.37878788 | L2: =SUM(L12:L12) -> 4238.98 | M2: =((F2-G12)/L2)-100% -> -0.99268692 | N2: =SUM(N12:N12)/C2 -> 0 | O2: =SUM(P12:P12)/C2 -> 0
A3: =A20 -> Baton Rouge South | B3: =SUM(C20:C26) -> 3946.26 | C3: =SUM(D20:D26) -> 3268.26 | D3: =SUM(E20:E26) -> 440 | E3: =SUM(F20:F26) -> -28 | F3: =SUM(G20:G26) -> 129 | G3: =SUM(H20:H26) -> -136 | H3: =SUM(I20:I26) -> 10237.581 | I3: =SUM(J20:J26) -> 43 | J3: =I3/SUM(S20:S26) -> 0.55844156 | L3: =SUM(L13:L13) -> 5844.34 | M3: =((F3-G13)/L3)-100% -> -0.98596933 | N3: =SUM(N13:N13)/C3 -> 0 | O3: =SUM(P13:P13)/C3 -> 0.00019471022
A4: =A27 -> Gulf Coast North | B4: =SUM(C27:C35) -> 3094 | C4: =SUM(D27:D35) -> 2338 | D4: =SUM(E27:E35) -> 342 | E4: =SUM(F27:F35) -> 56 | F4: =SUM(G27:G35) -> -12 | G4: =SUM(H27:H35) -> 76 | H4: =SUM(I27:I35) -> 14304.36 | I4: =SUM(J27:J35) -> 54 | J4: =I4/SUM(S27:S35) -> 0.54545455 | L4: =SUM(L14:L23) -> 52541.38 | M4: =(F4/L4)-100% -> -1.0002284 | N4: =SUM(N14:N23)/C4 -> 0 | O4: =SUM(P14:P23)/C4 -> #DIV/0!
A5: =A36 -> Gulf Coast West | B5: =SUM(C36:C42) -> 792 | C5: =SUM(D36:D42) -> 163 | D5: =SUM(E36:E42) -> -277 | E5: =SUM(F36:F42) -> 11 | F5: =SUM(G36:G42) -> -24 | G5: =SUM(H36:H42) -> -5 | H5: =SUM(I36:I42) -> 222.93 | I5: =SUM(J36:J42) -> 56 | J5: =I5/SUM(S36:S42) -> 0.72727273 | L5: =SUM(L24:L36) -> 80972.98 | M5: =((F5-G34-G35-G36)/L5)-100% -> -0.99976535 | N5: =SUM(N24:N36)/C5 -> 0 | O5: =SUM(P24:P36)/C5 -> 0.050752928
A6: =A43 -> Lafayette | B6: =SUM(C43:C50) -> 951 | C6: =SUM(D43:D50) -> 302 | D6: =SUM(E43:E50) -> 56 | E6: =SUM(F43:F50) -> -55 | F6: =SUM(G43:G50) -> 30 | G6: =SUM(H43:H50) -> 9 | H6: =SUM(I43:I50) -> 3106.88 | I6: =SUM(J43:J50) -> 66 | J6: =I6/SUM(S43:S50) -> 0.75
A7: =A51 -> NOLA North | B7: =SUM(C51:C59) -> 2526 | C7: =SUM(D51:D59) -> -228 | D7: =SUM(E51:E59) -> -16 | E7: =SUM(F51:F59) -> 24 | F7: =SUM(G51:G59) -> 38 | G7: =SUM(H51:H59) -> -6 | H7: =SUM(I51:I59) -> 6251.48 | I7: =SUM(J51:J59) -> 71 | J7: =I7/SUM(S51:S59) -> 0.80681818 | L7: =SUM(L37:L45) -> 38554.76 | M7: =(F7/L7)-100% -> -0.99901439 | N7: =SUM(N37:N45)/C7 -> 0 | O7: =SUM(P37:P45)/C7 -> -0.027113238
A8: =A60 -> NOLA South | B8: =SUM(C60:C68) -> 4836 | C8: =SUM(D60:D68) -> 5199 | D8: =SUM(E60:E68) -> 490 | E8: =SUM(F60:F68) -> -5766 | F8: =SUM(G60:G68) -> -22 | G8: =SUM(H60:H68) -> 7 | H8: =SUM(I60:I68) -> 1236.93 | I8: =SUM(J60:J68) -> 74 | J8: =I8/SUM(S60:S68) -> 0.74747475 | L8: =SUM(L46:L54) -> 19465.43 | M8: =((F8-G54)/L8)-100% -> -1.0011302 | N8: =SUM(N46:N54)/C8 -> 0.00019234468 | O8: =SUM(P46:P54)/C8 -> 0.0014862998
A9: Gulf Coast | B9: =SUM(B2:B8) -> 17963.46 | C9: =SUM(C2:C8) -> 12786.46 | D9: =SUM(D2:D8) -> 1258 | E9: =SUM(E2:E8) -> -5749 | F9: =SUM(F2:F8) -> 170 | G9: =SUM(G2:G8) -> -5 | H9: =SUM(H2:H8) -> 42428.524 | I9: =SUM(I2:I8) -> 389 | J9: =I9/SUM(S12:S68) -> 0.65488215 | L9: =SUM(L2:L8) -> 201617.87 | M9: =((F9-G12-G13-G34-G35-G36-G54)/L9)-100% -> -0.99917666 | N9: {=SUM(Table178910111213235787[Big 4 Items]/C9)} -> 7.8207729e-05 | O9: =SUM(Table178910111213235787[Count Compliance2])/C9 -> #DIV/0!
A11: District | B11: Store | C11: Lubricants/Oil +/- | D11: Oil +/- | E11: Oil Filters +/- | F11: Air Filters +/- | G11: Wipers +/- | H11: Cabins +/- | I11: Adjustment Variance | J11: On Time Counts | K11: Count Compliance | L11: Comp Sales | M11: Comp Sales Attainment | N11: Big 4 Items | O11: Big 4 | P11: Count Compliance2
A12: Baton Rouge North | B12: 17 | K12: =Table178910111213235787[[#This Row],[On Time Counts]]/45 -> 0 | L12: 4238.98 | M12: =Table178910111213235787[[#This Row],[Wipers +/-]]/Table178910111213235787[[#This Row],[Comp Sales]] -> 0 | N12: 0 | O12: =Table178910111213235787[[#This Row],[Big 4 Items]]/Table178910111213235787[[#This Row],[Oil +/- ]] -> #DIV/0! | P12: =J12/S12 -> 0 | S12: =$T$1 -> 11
A13: Baton Rouge North | B13: 22 | C13: 423.4 | D13: 423.4 | E13: 196 | F13: 1 | G13: 47 | H13: 46 | I13: 1868.57 | J13: 7 | K13: =Table178910111213235787[[#This Row],[On Time Counts]]/45 -> 0.15555556 | L13: 5844.34 | M13: =Table178910111213235787[[#This Row],[Wipers +/-]]/Table178910111213235787[[#This Row],[Comp Sales]] -> 0.0080419688 | N13: 0 | O13: =Table178910111213235787[[#This Row],[Big 4 Items]]/Table178910111213235787[[#This Row],[Oil +/- ]] -> 0 | P13: =J13/S13 -> 0.63636364 | S13: =$T$1 -> 11
A14: Baton Rouge North | B14: 641 | C14: 25.6 | D14: 29.6 | E14: -25 | F14: 4 | G14: -9 | H14: 0 | I14: 537.5668 | J14: 8 | K14: =Table178910111213235787[[#This Row],[On Time Counts]]/45 -> 0.17777778 | L14: 3219.34 | M14: =Table178910111213235787[[#This Row],[Wipers +/-]]/Table178910111213235787[[#This Row],[Comp Sales]] -> -0.0027956041 | N14: 0 | O14: =Table178910111213235787[[#This Row],[Big 4 Items]]/Table178910111213235787[[#This Row],[Oil +/- ]] -> 0 | P14: =J14/S14 -> 0.72727273 | S14: =$T$1 -> 11
A15: Baton Rouge North | B15: 717 | C15: -26.1 | D15: -26.1 | E15: 28 | I15: -38.877 | J15: 2 | K15: =Table178910111213235787[[#This Row],[On Time Counts]]/45 -> 0.044444444 | L15: 8034.77 | M15: =Table178910111213235787[[#This Row],[Wipers +/-]]/Table178910111213235787[[#This Row],[Comp Sales]] -> 0 | N15: 0 | O15: =Table178910111213235787[[#This Row],[Big 4 Items]]/Table178910111213235787[[#This Row],[Oil +/- ]] -> 0 | P15: =J15/S15 -> 0.18181818 | S15: =$T$1 -> 11
A16: Baton Rouge North | B16: 843 | C16: 252.3 | D16: 186.3 | F16: 4 | G16: -7 | H16: 4 | I16: 823.843 | J16: 5 | K16: =Table178910111213235787[[#This Row],[On Time Counts]]/45 -> 0.11111111 | L16: 6497.34 | M16: =Table178910111213235787[[#This Row],[Wipers +/-]]/Table178910111213235787[[#This Row],[Comp Sales]] -> -0.001077364 | N16: 0 | O16: =Table178910111213235787[[#This Row],[Big 4 Items]]/Table178910111213235787[[#This Row],[Oil +/- ]] -> 0 | P16: =J16/S16 -> 0.45454545 | S16: =$T$1 -> 11
A17: Baton Rouge North | B17: 881 | C17: 1143 | D17: 1131 | E17: 24 | I17: 3877.26 | J17: 3 | K17: =Table178910111213235787[[#This Row],[On Time Counts]]/45 -> 0.066666667 | M17: =Table178910111213235787[[#This Row],[Wipers +/-]]/Table178910111213235787[[#This Row],[Comp Sales]] -> #DIV/0! | O17: =Table178910111213235787[[#This Row],[Big 4 Items]]/Table178910111213235787[[#This Row],[Oil +/- ]] -> 0 | P17: =J17/S17 -> 0.27272727 | S17: =$T$1 -> 11
A18: Baton Rouge North | B18: 953 | C18: 0 | D18: 0 | E18: 0 | F18: 0 | G18: 0 | H18: 0 | I18: 0 | J18: 0 | K18: =Table178910111213235787[[#This Row],[On Time Counts]]/45 -> 0 | L18: 7185.39 | M18: =Table178910111213235787[[#This Row],[Wipers +/-]]/Table178910111213235787[[#This Row],[Comp Sales]] -> 0 | N18: 0 | O18: =Table178910111213235787[[#This Row],[Big 4 Items]]/Table178910111213235787[[#This Row],[Oil +/- ]] -> #DIV/0! | P18: =J18/S18 -> #DIV/0! | S18: 0
A19: Baton Rouge North | B19: 3040 | C19: 0 | D19: 0 | E19: 0 | F19: 0 | G19: 0 | H19: 0 | I19: 0 | J19: 0 | K19: =Table178910111213235787[[#This Row],[On Time Counts]]/45 -> 0 | L19: 6083.18 | M19: =Table178910111213235787[[#This Row],[Wipers +/-]]/Table178910111213235787[[#This Row],[Comp Sales]] -> 0 | N19: 0 | O19: =Table178910111213235787[[#This Row],[Big 4 Items]]/Table178910111213235787[[#This Row],[Oil +/- ]] -> #DIV/0! | P19: =J19/S19 -> #DIV/0! | S19: 0
A20: Baton Rouge South | B20: 18 | C20: 3729.93 | D20: 3315.93 | E20: 205 | F20: 33 | G20: 180 | H20: -66 | I20: 10215.658 | J20: 7 | K20: =Table178910111213235787[[#This Row],[On Time Counts]]/45 -> 0.15555556 | L20: 4849.02 | M20: =Table178910111213235787[[#This Row],[Wipers +/-]]/Table178910111213235787[[#This Row],[Comp Sales]] -> 0.037120903 | N20: 0 | O20: =Table178910111213235787[[#This Row],[Big 4 Items]]/Table178910111213235787[[#This Row],[Oil +/- ]] -> 0 | P20: =J20/S20 -> 0.63636364 | S20: =$T$1 -> 11
A21: Baton Rouge South | B21: 19 | C21: 111.32 | D21: 111.32 | E21: -12 | F21: -10 | H21: -5 | I21: 277.9802 | J21: 4 | K21: =Table178910111213235787[[#This Row],[On Time Counts]]/45 -> 0.088888889 | L21: 2994.56 | M21: =Table178910111213235787[[#This Row],[Wipers +/-]]/Table178910111213235787[[#This Row],[Comp Sales]] -> 0 | N21: 0 | O21: =Table178910111213235787[[#This Row],[Big 4 Items]]/Table178910111213235787[[#This Row],[Oil +/- ]] -> 0 | P21: =J21/S21 -> 0.36363636 | S21: =$T$1 -> 11
A22: Baton Rouge South | B22: 282 | C22: 293 | D22: 29 | E22: 3 | F22: 15 | I22: 596.373 | J22: 4 | K22: =Table178910111213235787[[#This Row],[On Time Counts]]/45 -> 0.088888889 | L22: 6870.99 | M22: =Table178910111213235787[[#This Row],[Wipers +/-]]/Table178910111213235787[[#This Row],[Comp Sales]] -> 0 | N22: 0 | O22: =Table178910111213235787[[#This Row],[Big 4 Items]]/Table178910111213235787[[#This Row],[Oil +/- ]] -> 0 | P22: =J22/S22 -> 0.36363636 | S22: =$T$1 -> 11
A23: Baton Rouge South | B23: 447 | C23: -267.96 | D23: -267.96 | I23: -980.5714 | J23: 1 | K23: =Table178910111213235787[[#This Row],[On Time Counts]]/45 -> 0.022222222 | L23: 6806.79 | M23: =Table178910111213235787[[#This Row],[Wipers +/-]]/Table178910111213235787[[#This Row],[Comp Sales]] -> 0 | N23: 0 | O23: =Table178910111213235787[[#This Row],[Big 4 Items]]/Table178910111213235787[[#This Row],[Oil +/- ]] -> 0 | P23: =J23/S23 -> 0.090909091 | S23: =$T$1 -> 11
A24: Baton Rouge South | B24: 448 | C24: 991.25 | D24: 991.25 | E24: 45 | F24: -54 | G24: -60 | H24: -44 | I24: 3838.0006 | J24: 8 | K24: =Table178910111213235787[[#This Row],[On Time Counts]]/45 -> 0.17777778 | L24: 3933.29 | M24: =Table178910111213235787[[#This Row],[Wipers +/-]]/Table178910111213235787[[#This Row],[Comp Sales]] -> -0.015254405 | N24: 0 | O24: =Table178910111213235787[[#This Row],[Big 4 Items]]/Table178910111213235787[[#This Row],[Oil +/- ]] -> 0 | P24: =J24/S24 -> 0.72727273 | S24: =$T$1 -> 11
A25: Baton Rouge South | B25: 531 | C25: -396.28 | D25: -396.28 | E25: 0 | F25: -20 | G25: 13 | H25: -13 | I25: -1468.9196 | J25: 9 | K25: =Table178910111213235787[[#This Row],[On Time Counts]]/45 -> 0.2 | L25: 6987.69 | M25: =Table178910111213235787[[#This Row],[Wipers +/-]]/Table178910111213235787[[#This Row],[Comp Sales]] -> 0.0018604145 | N25: 0 | O25: =Table178910111213235787[[#This Row],[Big 4 Items]]/Table178910111213235787[[#This Row],[Oil +/- ]] -> 0 | P25: =J25/S25 -> 0.81818182 | S25: =$T$1 -> 11
A26: Baton Rouge South | B26: 832 | C26: -515 | D26: -515 | E26: 199 | F26: 8 | G26: -4 | H26: -8 | I26: -2240.94 | J26: 10 | K26: =Table178910111213235787[[#This Row],[On Time Counts]]/45 -> 0.22222222 | L26: 5562.48 | M26: =Table178910111213235787[[#This Row],[Wipers +/-]]/Table178910111213235787[[#This Row],[Comp Sales]] -> -0.00071910371 | N26: 0 | O26: =Table178910111213235787[[#This Row],[Big 4 Items]]/Table178910111213235787[[#This Row],[Oil +/- ]] -> 0 | P26: =J26/S26 -> 0.90909091 | S26: =$T$1 -> 11
A27: Gulf Coast North | B27: 3 | K27: =Table178910111213235787[[#This Row],[On Time Counts]]/45 -> 0 | L27: 10385.27 | M27: =Table178910111213235787[[#This Row],[Wipers +/-]]/Table178910111213235787[[#This Row],[Comp Sales]] -> 0 | N27: 0 | O27: =Table178910111213235787[[#This Row],[Big 4 Items]]/Table178910111213235787[[#This Row],[Oil +/- ]] -> #DIV/0! | P27: =J27/S27 -> 0 | S27: =$T$1 -> 11
A28: Gulf Coast North | B28: 5 | C28: 1117 | D28: 749 | E28: 40 | F28: 32 | G28: 24 | H28: 60 | I28: 2329.12 | J28: 7 | K28: =Table178910111213235787[[#This Row],[On Time Counts]]/45 -> 0.15555556 | L28: 5512.41 | M28: =Table178910111213235787[[#This Row],[Wipers +/-]]/Table178910111213235787[[#This Row],[Comp Sales]] -> 0.0043538126 | N28: 0 | O28: =Table178910111213235787[[#This Row],[Big 4 Items]]/Table178910111213235787[[#This Row],[Oil +/- ]] -> 0 | P28: =J28/S28 -> 0.63636364 | S28: =$T$1 -> 11
A29: Gulf Coast North | B29: 11 | C29: 58 | D29: -15 | E29: 3 | F29: 0 | G29: -4 | H29: -3 | I29: 492.22 | J29: 11 | K29: =Table178910111213235787[[#This Row],[On Time Counts]]/45 -> 0.24444444 | L29: 7892.5 | M29: =Table178910111213235787[[#This Row],[Wipers +/-]]/Table178910111213235787[[#This Row],[Comp Sales]] -> -0.00050681026 | N29: 0 | O29: =Table178910111213235787[[#This Row],[Big 4 Items]]/Table178910111213235787[[#This Row],[Oil +/- ]] -> 0 | P29: =J29/S29 -> 1 | S29: =$T$1 -> 11
A30: Gulf Coast North | B30: 14 | C30: 171 | D30: 171 | E30: 25 | F30: 6 | G30: 9 | H30: 0 | I30: 901.9 | J30: 7 | K30: =Table178910111213235787[[#This Row],[On Time Counts]]/45 -> 0.15555556 | L30: 3854.43 | M30: =Table178910111213235787[[#This Row],[Wipers +/-]]/Table178910111213235787[[#This Row],[Comp Sales]] -> 0.0023349756 | N30: 0 | O30: =Table178910111213235787[[#This Row],[Big 4 Items]]/Table178910111213235787[[#This Row],[Oil +/- ]] -> 0 | P30: =J30/S30 -> 0.63636364 | S30: =$T$1 -> 11
A31: Gulf Coast North | B31: 20 | F31: 6 | H31: -2 | I31: 18.91 | J31: 1 | K31: =Table178910111213235787[[#This Row],[On Time Counts]]/45 -> 0.022222222 | L31: 6979.44 | M31: =Table178910111213235787[[#This Row],[Wipers +/-]]/Table178910111213235787[[#This Row],[Comp Sales]] -> 0 | N31: 0 | O31: =Table178910111213235787[[#This Row],[Big 4 Items]]/Table178910111213235787[[#This Row],[Oil +/- ]] -> #DIV/0! | P31: =J31/S31 -> 0.090909091 | S31: =$T$1 -> 11
A32: Gulf Coast North | B32: 21 | C32: -22 | D32: -16 | E32: 7 | F32: 0 | G32: 0 | H32: 1 | I32: -117.47 | J32: 10 | K32: =Table178910111213235787[[#This Row],[On Time Counts]]/45 -> 0.22222222 | L32: 7573.54 | M32: =Table178910111213235787[[#This Row],[Wipers +/-]]/Table178910111213235787[[#This Row],[Comp Sales]] -> 0 | N32: 0 | O32: =Table178910111213235787[[#This Row],[Big 4 Items]]/Table178910111213235787[[#This Row],[Oil +/- ]] -> 0 | P32: =J32/S32 -> 0.90909091 | S32: =$T$1 -> 11
A33: Gulf Coast North | B33: 23 | C33: 253 | D33: 40 | E33: 3 | G33: 1 | H33: 1 | I33: 305.62 | J33: 3 | K33: =Table178910111213235787[[#This Row],[On Time Counts]]/45 -> 0.066666667 | L33: 5842.02 | M33: =Table178910111213235787[[#This Row],[Wipers +/-]]/Table178910111213235787[[#This Row],[Comp Sales]] -> 0.00017117367 | N33: 0 | O33: =Table178910111213235787[[#This Row],[Big 4 Items]]/Table178910111213235787[[#This Row],[Oil +/- ]] -> 0 | P33: =J33/S33 -> 0.27272727 | S33: =$T$1 -> 11
A34: Gulf Coast North | B34: 24 | C34: 1386 | D34: 1177 | E34: 264 | F34: -20 | G34: 9 | H34: 11 | I34: 9143.54 | J34: 6 | K34: =Table178910111213235787[[#This Row],[On Time Counts]]/45 -> 0.13333333 | L34: 6567.35 | M34: =Table178910111213235787[[#This Row],[Wipers +/-]]/Table178910111213235787[[#This Row],[Comp Sales]] -> 0.0013704158 | N34: 0 | O34: =Table178910111213235787[[#This Row],[Big 4 Items]]/Table178910111213235787[[#This Row],[Oil +/- ]] -> 0 | P34: =J34/S34 -> 0.54545455 | S34: =$T$1 -> 11
A35: Gulf Coast North | B35: 26 | C35: 131 | D35: 232 | F35: 32 | G35: -51 | H35: 8 | I35: 1230.52 | J35: 9 | K35: =Table178910111213235787[[#This Row],[On Time Counts]]/45 -> 0.2 | L35: 5286.48 | M35: =Table178910111213235787[[#This Row],[Wipers +/-]]/Table178910111213235787[[#This Row],[Comp Sales]] -> -0.0096472511 | N35: 0 | O35: =Table178910111213235787[[#This Row],[Big 4 Items]]/Table178910111213235787[[#This Row],[Oil +/- ]] -> 0 | P35: =J35/S35 -> 0.81818182 | S35: =$T$1 -> 11
A36: Gulf Coast West | B36: 46 | C36: -101 | D36: -101 | E36: -10 | F36: 1 | G36: -1 | H36: -1 | I36: -314.54 | J36: 10 | K36: =Table178910111213235787[[#This Row],[On Time Counts]]/45 -> 0.22222222 | L36: 4596.08 | M36: =Table178910111213235787[[#This Row],[Wipers +/-]]/Table178910111213235787[[#This Row],[Comp Sales]] -> -0.00021757672 | N36: 0 | O36: =Table178910111213235787[[#This Row],[Big 4 Items]]/Table178910111213235787[[#This Row],[Oil +/- ]] -> 0 | P36: =J36/S36 -> 0.90909091 | S36: =$T$1 -> 11
A37: Gulf Coast West | B37: 283 | C37: 470 | D37: -40 | E37: -292 | F37: 1 | G37: 1 | I37: -576.56 | J37: 6 | K37: =Table178910111213235787[[#This Row],[On Time Counts]]/45 -> 0.13333333 | L37: 7096.63 | M37: =Table178910111213235787[[#This Row],[Wipers +/-]]/Table178910111213235787[[#This Row],[Comp Sales]] -> 0.00014091195 | N37: 0 | O37: =Table178910111213235787[[#This Row],[Big 4 Items]]/Table178910111213235787[[#This Row],[Oil +/- ]] -> 0 | P37: =J37/S37 -> 0.54545455 | S37: =$T$1 -> 11
A38: Gulf Coast West | B38: 847 | C38: 72 | D38: 72 | E38: 70 | F38: -3 | G38: -34 | I38: 588.9 | J38: 5 | K38: =Table178910111213235787[[#This Row],[On Time Counts]]/45 -> 0.11111111 | L38: 6662.04 | M38: =Table178910111213235787[[#This Row],[Wipers +/-]]/Table178910111213235787[[#This Row],[Comp Sales]] -> -0.0051035419 | N38: 0 | O38: =Table178910111213235787[[#This Row],[Big 4 Items]]/Table178910111213235787[[#This Row],[Oil +/- ]] -> 0 | P38: =J38/S38 -> 0.45454545 | S38: =$T$1 -> 11
A39: Gulf Coast West | B39: 865 | C39: 112 | D39: 34 | E39: 3 | F39: 24 | G39: 10 | H39: 1 | I39: 385.26 | J39: 10 | K39: =Table178910111213235787[[#This Row],[On Time Counts]]/45 -> 0.22222222 | L39: 3219.44 | M39: =Table178910111213235787[[#This Row],[Wipers +/-]]/Table178910111213235787[[#This Row],[Comp Sales]] -> 0.0031061303 | N39: 0 | O39: =Table178910111213235787[[#This Row],[Big 4 Items]]/Table178910111213235787[[#This Row],[Oil +/- ]] -> 0 | P39: =J39/S39 -> 0.90909091 | S39: =$T$1 -> 11
A40: Gulf Coast West | B40: 919 | C40: -138 | D40: -146 | E40: -2 | F40: 1 | I40: -405.8 | J40: 8 | K40: =Table178910111213235787[[#This Row],[On Time Counts]]/45 -> 0.17777778 | L40: 3981.57 | M40: =Table178910111213235787[[#This Row],[Wipers +/-]]/Table178910111213235787[[#This Row],[Comp Sales]] -> 0 | N40: 0 | O40: =Table178910111213235787[[#This Row],[Big 4 Items]]/Table178910111213235787[[#This Row],[Oil +/- ]] -> 0 | P40: =J40/S40 -> 0.72727273 | S40: =$T$1 -> 11
A41: Gulf Coast West | B41: 954 | C41: 413 | D41: 408 | E41: -13 | F41: -12 | I41: 989.57 | J41: 7 | K41: =Table178910111213235787[[#This Row],[On Time Counts]]/45 -> 0.15555556 | M41: =Table178910111213235787[[#This Row],[Wipers +/-]]/Table178910111213235787[[#This Row],[Comp Sales]] -> #DIV/0! | O41: =Table178910111213235787[[#This Row],[Big 4 Items]]/Table178910111213235787[[#This Row],[Oil +/- ]] -> 0 | P41: =J41/S41 -> 0.63636364 | S41: =$T$1 -> 11
...

Sheet P10 - 10-18
A1: District | B1: Lubricants/Oil +/- | C1: Oil +/- | D1: Oil Filters +/- | E1: Air Filters +/- | F1: Wipers +/- | G1: Cabins +/- | H1: Adjustment Variance | I1: On Time Counts | J1: Count Compliance | L1: Comp Sales | M1: Comp Attainment | N1: Big 4 | O1: Coolant | S1: Total Count Target | T1: 11
A2: =A12 -> Baton Rouge North | B2: =SUM(C12:C19) -> 1401.18 | C2: =SUM(D12:D19) -> 1354.18 | D2: =SUM(E12:E19) -> 135 | E2: =SUM(F12:F19) -> 0 | F2: =SUM(G12:G19) -> 41 | G2: =SUM(H12:H19) -> 13 | H2: =SUM(I12:I19) -> 3750.256 | I2: =SUM(J12:J19) -> 25 | J2: =I2/SUM(S12:S19) -> 0.37878788 | L2: =SUM(L12:L12) -> 4238.98 | M2: =((F2-G12)/L2)-100% -> -0.99032786 | N2: =SUM(N12:N12)/C2 -> 0 | O2: =SUM(P12:P12)/C2 -> 0
A3: =A20 -> Baton Rouge South | B3: =SUM(C20:C26) -> 4091.46 | C3: =SUM(D20:D26) -> 4253.46 | D3: =SUM(E20:E26) -> 1062 | E3: =SUM(F20:F26) -> -57 | F3: =SUM(G20:G26) -> 212 | G3: =SUM(H20:H26) -> 182 | H3: =SUM(I20:I26) -> 14837.2 | I3: =SUM(J20:J26) -> 46 | J3: =I3/SUM(S20:S26) -> 0.5974026 | L3: =SUM(L13:L13) -> 5844.34 | M3: =((F3-G13)/L3)-100% -> -0.9731364 | N3: =SUM(N13:N13)/C3 -> 0 | O3: =SUM(P13:P13)/C3 -> 0.00014961082
A4: =A27 -> Gulf Coast North | B4: =SUM(C27:C35) -> 308 | C4: =SUM(D27:D35) -> -68 | D4: =SUM(E27:E35) -> 381 | E4: =SUM(F27:F35) -> 8 | F4: =SUM(G27:G35) -> 0 | G4: =SUM(H27:H35) -> 6 | H4: =SUM(I27:I35) -> 2246.95 | I4: =SUM(J27:J35) -> 52 | J4: =I4/SUM(S27:S35) -> 0.52525253 | L4: =SUM(L14:L23) -> 52541.38 | M4: =(F4/L4)-100% -> -1 | N4: =SUM(N14:N23)/C4 -> 0 | O4: =SUM(P14:P23)/C4 -> #DIV/0!
A5: =A36 -> Gulf Coast West | B5: =SUM(C36:C42) -> 782 | C5: =SUM(D36:D42) -> 873 | D5: =SUM(E36:E42) -> -2 | E5: =SUM(F36:F42) -> 32 | F5: =SUM(G36:G42) -> 71 | G5: =SUM(H36:H42) -> 28 | H5: =SUM(I36:I42) -> 3679.82 | I5: =SUM(J36:J42) -> 45 | J5: =I5/SUM(S36:S42) -> 0.58441558 | L5: =SUM(L24:L36) -> 80972.98 | M5: =((F5-G34-G35-G36)/L5)-100% -> -0.99912316 | N5: =SUM(N24:N36)/C5 -> 0 | O5: =SUM(P24:P36)/C5 -> 0.0085389982
A6: =A43 -> Lafayette | B6: =SUM(C43:C50) -> 1827 | C6: =SUM(D43:D50) -> 1063 | D6: =SUM(E43:E50) -> 107 | E6: =SUM(F43:F50) -> 14 | F6: =SUM(G43:G50) -> 11 | G6: =SUM(H43:H50) -> -19 | H6: =SUM(I43:I50) -> 4548.93 | I6: =SUM(J43:J50) -> 72 | J6: =I6/SUM(S43:S50) -> 0.81818182
A7: =A51 -> NOLA North | B7: =SUM(C51:C59) -> 3446 | C7: =SUM(D51:D59) -> 863 | D7: =SUM(E51:E59) -> 49 | E7: =SUM(F51:F59) -> -11 | F7: =SUM(G51:G59) -> 2 | G7: =SUM(H51:H59) -> 14 | H7: =SUM(I51:I59) -> 6704.25 | I7: =SUM(J51:J59) -> 74 | J7: =I7/SUM(S51:S59) -> 0.84090909 | L7: =SUM(L37:L45) -> 38554.76 | M7: =(F7/L7)-100% -> -0.99994813 | N7: =SUM(N37:N45)/C7 -> 0 | O7: =SUM(P37:P45)/C7 -> 0.0071631729
A8: =A60 -> NOLA South | B8: =SUM(C60:C68) -> 3798 | C8: =SUM(D60:D68) -> 2817 | D8: =SUM(E60:E68) -> 136 | E8: =SUM(F60:F68) -> -21 | F8: =SUM(G60:G68) -> -21 | G8: =SUM(H60:H68) -> 31 | H8: =SUM(I60:I68) -> 14680.57 | I8: =SUM(J60:J68) -> 60 | J8: =I8/SUM(S60:S68) -> 0.60606061 | L8: =SUM(L46:L54) -> 19465.43 | M8: =((F8-G54)/L8)-100% -> -1.0009247 | N8: =SUM(N46:N54)/C8 -> 0.00035498758 | O8: =SUM(P46:P54)/C8 -> 0.0027108142
A9: Gulf Coast | B9: =SUM(B2:B8) -> 15653.64 | C9: =SUM(C2:C8) -> 11155.64 | D9: =SUM(D2:D8) -> 1868 | E9: =SUM(E2:E8) -> -35 | F9: =SUM(F2:F8) -> 316 | G9: =SUM(G2:G8) -> 255 | H9: =SUM(H2:H8) -> 50447.976 | I9: =SUM(I2:I8) -> 374 | J9: =I9/SUM(S12:S68) -> 0.62962963 | L9: =SUM(L2:L8) -> 201617.87 | M9: =((F9-G12-G13-G34-G35-G36-G54)/L9)-100% -> -0.99869059 | N9: {=SUM(Table178910111213235783[Big 4 Items]/C9)} -> 8.9640756e-05 | O9: =SUM(Table178910111213235783[Count Compliance2])/C9 -> #DIV/0!
A11: District | B11: Store | C11: Lubricants/Oil +/- | D11: Oil +/- | E11: Oil Filters +/- | F11: Air Filters +/- | G11: Wipers +/- | H11: Cabins +/- | I11: Adjustment Variance | J11: On Time Counts | K11: Count Compliance | L11: Comp Sales | M11: Comp Sales Attainment | N11: Big 4 Items | O11: Big 4 | P11: Count Compliance2
A12: Baton Rouge North | B12: 17 | K12: =Table178910111213235783[[#This Row],[On Time Counts]]/45 -> 0 | L12: 4238.98 | M12: =Table178910111213235783[[#This Row],[Wipers +/-]]/Table178910111213235783[[#This Row],[Comp Sales]] -> 0 | N12: 0 | O12: =Table178910111213235783[[#This Row],[Big 4 Items]]/Table178910111213235783[[#This Row],[Oil +/- ]] -> #DIV/0! | P12: =J12/S12 -> 0 | S12: =$T$1 -> 11
A13: Baton Rouge North | B13: 22 | C13: 2.64 | D13: 2.64 | E13: 0 | F13: 1 | G13: 55 | H13: 21 | I13: 259.8654 | J13: 7 | K13: =Table178910111213235783[[#This Row],[On Time Counts]]/45 -> 0.15555556 | L13: 5844.34 | M13: =Table178910111213235783[[#This Row],[Wipers +/-]]/Table178910111213235783[[#This Row],[Comp Sales]] -> 0.0094108146 | N13: 0 | O13: =Table178910111213235783[[#This Row],[Big 4 Items]]/Table178910111213235783[[#This Row],[Oil +/- ]] -> 0 | P13: =J13/S13 -> 0.63636364 | S13: =$T$1 -> 11
A14: Baton Rouge North | B14: 641 | C14: -88.68 | D14: -88.68 | E14: 135 | F14: -1 | G14: -15 | H14: -1 | I14: -189.6878 | J14: 9 | K14: =Table178910111213235783[[#This Row],[On Time Counts]]/45 -> 0.2 | L14: 3219.34 | M14: =Table178910111213235783[[#This Row],[Wipers +/-]]/Table178910111213235783[[#This Row],[Comp Sales]] -> -0.0046593401 | N14: 0 | O14: =Table178910111213235783[[#This Row],[Big 4 Items]]/Table178910111213235783[[#This Row],[Oil +/- ]] -> 0 | P14: =J14/S14 -> 0.81818182 | S14: =$T$1 -> 11
A15: Baton Rouge North | B15: 717 | C15: 746.7 | D15: 746.7 | H15: -8 | I15: 2370.981 | J15: 2 | K15: =Table178910111213235783[[#This Row],[On Time Counts]]/45 -> 0.044444444 | L15: 8034.77 | M15: =Table178910111213235783[[#This Row],[Wipers +/-]]/Table178910111213235783[[#This Row],[Comp Sales]] -> 0 | N15: 0 | O15: =Table178910111213235783[[#This Row],[Big 4 Items]]/Table178910111213235783[[#This Row],[Oil +/- ]] -> 0 | P15: =J15/S15 -> 0.18181818 | S15: =$T$1 -> 11
A16: Baton Rouge North | B16: 843 | C16: 133.52 | D16: 86.52 | I16: 234.1374 | J16: 1 | K16: =Table178910111213235783[[#This Row],[On Time Counts]]/45 -> 0.022222222 | L16: 6497.34 | M16: =Table178910111213235783[[#This Row],[Wipers +/-]]/Table178910111213235783[[#This Row],[Comp Sales]] -> 0 | N16: 0 | O16: =Table178910111213235783[[#This Row],[Big 4 Items]]/Table178910111213235783[[#This Row],[Oil +/- ]] -> 0 | P16: =J16/S16 -> 0.090909091 | S16: =$T$1 -> 11
A17: Baton Rouge North | B17: 881 | C17: 607 | D17: 607 | G17: 1 | H17: 1 | I17: 1074.96 | J17: 6 | K17: =Table178910111213235783[[#This Row],[On Time Counts]]/45 -> 0.13333333 | M17: =Table178910111213235783[[#This Row],[Wipers +/-]]/Table178910111213235783[[#This Row],[Comp Sales]] -> #DIV/0! | O17: =Table178910111213235783[[#This Row],[Big 4 Items]]/Table178910111213235783[[#This Row],[Oil +/- ]] -> 0 | P17: =J17/S17 -> 0.54545455 | S17: =$T$1 -> 11
A18: Baton Rouge North | B18: 953 | C18: 0 | D18: 0 | E18: 0 | F18: 0 | G18: 0 | H18: 0 | I18: 0 | J18: 0 | K18: =Table178910111213235783[[#This Row],[On Time Counts]]/45 -> 0 | L18: 7185.39 | M18: =Table178910111213235783[[#This Row],[Wipers +/-]]/Table178910111213235783[[#This Row],[Comp Sales]] -> 0 | N18: 0 | O18: =Table178910111213235783[[#This Row],[Big 4 Items]]/Table178910111213235783[[#This Row],[Oil +/- ]] -> #DIV/0! | P18: =J18/S18 -> #DIV/0! | S18: 0
A19: Baton Rouge North | B19: 3040 | C19: 0 | D19: 0 | E19: 0 | F19: 0 | G19: 0 | H19: 0 | I19: 0 | J19: 0 | K19: =Table178910111213235783[[#This Row],[On Time Counts]]/45 -> 0 | L19: 6083.18 | M19: =Table178910111213235783[[#This Row],[Wipers +/-]]/Table178910111213235783[[#This Row],[Comp Sales]] -> 0 | N19: 0 | O19: =Table178910111213235783[[#This Row],[Big 4 Items]]/Table178910111213235783[[#This Row],[Oil +/- ]] -> #DIV/0! | P19: =J19/S19 -> #DIV/0! | S19: 0
A20: Baton Rouge South | B20: 18 | C20: 453.74 | D20: 554.74 | E20: 328 | F20: 35 | G20: 27 | H20: 161 | I20: 968.9704 | J20: 8 | K20: =Table178910111213235783[[#This Row],[On Time Counts]]/45 -> 0.17777778 | L20: 4849.02 | M20: =Table178910111213235783[[#This Row],[Wipers +/-]]/Table178910111213235783[[#This Row],[Comp Sales]] -> 0.0055681354 | N20: 0 | O20: =Table178910111213235783[[#This Row],[Big 4 Items]]/Table178910111213235783[[#This Row],[Oil +/- ]] -> 0 | P20: =J20/S20 -> 0.72727273 | S20: =$T$1 -> 11
A21: Baton Rouge South | B21: 19 | C21: 1070.62 | D21: 1070.62 | E21: 120 | F21: -89 | I21: 5508.206 | J21: 4 | K21: =Table178910111213235783[[#This Row],[On Time Counts]]/45 -> 0.088888889 | L21: 2994.56 | M21: =Table178910111213235783[[#This Row],[Wipers +/-]]/Table178910111213235783[[#This Row],[Comp Sales]] -> 0 | N21: 0 | O21: =Table178910111213235783[[#This Row],[Big 4 Items]]/Table178910111213235783[[#This Row],[Oil +/- ]] -> 0 | P21: =J21/S21 -> 0.36363636 | S21: =$T$1 -> 11
A22: Baton Rouge South | B22: 282 | C22: 125.92 | D22: 186.92 | E22: -3 | I22: -314.0978 | J22: 3 | K22: =Table178910111213235783[[#This Row],[On Time Counts]]/45 -> 0.066666667 | L22: 6870.99 | M22: =Table178910111213235783[[#This Row],[Wipers +/-]]/Table178910111213235783[[#This Row],[Comp Sales]] -> 0 | N22: 0 | O22: =Table178910111213235783[[#This Row],[Big 4 Items]]/Table178910111213235783[[#This Row],[Oil +/- ]] -> 0 | P22: =J22/S22 -> 0.27272727 | S22: =$T$1 -> 11
A23: Baton Rouge South | B23: 447 | C23: -279.96 | D23: -279.96 | E23: -44 | F23: -5 | I23: -1079.8533 | J23: 6 | K23: =Table178910111213235783[[#This Row],[On Time Counts]]/45 -> 0.13333333 | L23: 6806.79 | M23: =Table178910111213235783[[#This Row],[Wipers +/-]]/Table178910111213235783[[#This Row],[Comp Sales]] -> 0 | N23: 0 | O23: =Table178910111213235783[[#This Row],[Big 4 Items]]/Table178910111213235783[[#This Row],[Oil +/- ]] -> 0 | P23: =J23/S23 -> 0.54545455 | S23: =$T$1 -> 11
A24: Baton Rouge South | B24: 448 | C24: 2414.24 | D24: 2414.24 | E24: 645 | F24: 21 | G24: 169 | H24: 8 | I24: 7957.1074 | J24: 8 | K24: =Table178910111213235783[[#This Row],[On Time Counts]]/45 -> 0.17777778 | L24: 3933.29 | M24: =Table178910111213235783[[#This Row],[Wipers +/-]]/Table178910111213235783[[#This Row],[Comp Sales]] -> 0.042966575 | N24: 0 | O24: =Table178910111213235783[[#This Row],[Big 4 Items]]/Table178910111213235783[[#This Row],[Oil +/- ]] -> 0 | P24: =J24/S24 -> 0.72727273 | S24: =$T$1 -> 11
A25: Baton Rouge South | B25: 531 | C25: -112.1 | D25: -112.1 | E25: 17 | F25: 0 | G25: 17 | H25: 8 | I25: -522.243 | J25: 7 | K25: =Table178910111213235783[[#This Row],[On Time Counts]]/45 -> 0.15555556 | L25: 6987.69 | M25: =Table178910111213235783[[#This Row],[Wipers +/-]]/Table178910111213235783[[#This Row],[Comp Sales]] -> 0.0024328498 | N25: 0 | O25: =Table178910111213235783[[#This Row],[Big 4 Items]]/Table178910111213235783[[#This Row],[Oil +/- ]] -> 0 | P25: =J25/S25 -> 0.63636364 | S25: =$T$1 -> 11
A26: Baton Rouge South | B26: 832 | C26: 419 | D26: 419 | E26: -1 | F26: -19 | G26: -1 | H26: 5 | I26: 2319.11 | J26: 10 | K26: =Table178910111213235783[[#This Row],[On Time Counts]]/45 -> 0.22222222 | L26: 5562.48 | M26: =Table178910111213235783[[#This Row],[Wipers +/-]]/Table178910111213235783[[#This Row],[Comp Sales]] -> -0.00017977593 | N26: 0 | O26: =Table178910111213235783[[#This Row],[Big 4 Items]]/Table178910111213235783[[#This Row],[Oil +/- ]] -> 0 | P26: =J26/S26 -> 0.90909091 | S26: =$T$1 -> 11
A27: Gulf Coast North | B27: 3 | K27: =Table178910111213235783[[#This Row],[On Time Counts]]/45 -> 0 | L27: 10385.27 | M27: =Table178910111213235783[[#This Row],[Wipers +/-]]/Table178910111213235783[[#This Row],[Comp Sales]] -> 0 | N27: 0 | O27: =Table178910111213235783[[#This Row],[Big 4 Items]]/Table178910111213235783[[#This Row],[Oil +/- ]] -> #DIV/0! | P27: =J27/S27 -> 0 | S27: =$T$1 -> 11
A28: Gulf Coast North | B28: 5 | C28: -201 | D28: -526 | E28: 149 | G28: -3 | H28: -1 | I28: 103.54 | J28: 9 | K28: =Table178910111213235783[[#This Row],[On Time Counts]]/45 -> 0.2 | L28: 5512.41 | M28: =Table178910111213235783[[#This Row],[Wipers +/-]]/Table178910111213235783[[#This Row],[Comp Sales]] -> -0.00054422657 | N28: 0 | O28: =Table178910111213235783[[#This Row],[Big 4 Items]]/Table178910111213235783[[#This Row],[Oil +/- ]] -> 0 | P28: =J28/S28 -> 0.81818182 | S28: =$T$1 -> 11
A29: Gulf Coast North | B29: 11 | C29: -138 | D29: -13 | F29: 0 | G29: -2 | H29: 0 | I29: -1360.72 | J29: 8 | K29: =Table178910111213235783[[#This Row],[On Time Counts]]/45 -> 0.17777778 | L29: 7892.5 | M29: =Table178910111213235783[[#This Row],[Wipers +/-]]/Table178910111213235783[[#This Row],[Comp Sales]] -> -0.00025340513 | N29: 0 | O29: =Table178910111213235783[[#This Row],[Big 4 Items]]/Table178910111213235783[[#This Row],[Oil +/- ]] -> 0 | P29: =J29/S29 -> 0.72727273 | S29: =$T$1 -> 11
A30: Gulf Coast North | B30: 14 | C30: 406 | D30: 513 | G30: 0 | H30: 9 | I30: 2499.58 | J30: 6 | K30: =Table178910111213235783[[#This Row],[On Time Counts]]/45 -> 0.13333333 | L30: 3854.43 | M30: =Table178910111213235783[[#This Row],[Wipers +/-]]/Table178910111213235783[[#This Row],[Comp Sales]] -> 0 | N30: 0 | O30: =Table178910111213235783[[#This Row],[Big 4 Items]]/Table178910111213235783[[#This Row],[Oil +/- ]] -> 0 | P30: =J30/S30 -> 0.54545455 | S30: =$T$1 -> 11
A31: Gulf Coast North | B31: 20 | E31: 12 | F31: 2 | G31: 5 | H31: -1 | I31: 48.46 | J31: 2 | K31: =Table178910111213235783[[#This Row],[On Time Counts]]/45 -> 0.044444444 | L31: 6979.44 | M31: =Table178910111213235783[[#This Row],[Wipers +/-]]/Table178910111213235783[[#This Row],[Comp Sales]] -> 0.00071638985 | N31: 0 | O31: =Table178910111213235783[[#This Row],[Big 4 Items]]/Table178910111213235783[[#This Row],[Oil +/- ]] -> #DIV/0! | P31: =J31/S31 -> 0.18181818 | S31: =$T$1 -> 11
A32: Gulf Coast North | B32: 21 | C32: -8 | D32: -24 | E32: 18 | G32: -2 | H32: -1 | I32: 557.72 | J32: 10 | K32: =Table178910111213235783[[#This Row],[On Time Counts]]/45 -> 0.22222222 | L32: 7573.54 | M32: =Table178910111213235783[[#This Row],[Wipers +/-]]/Table178910111213235783[[#This Row],[Comp Sales]] -> -0.0002640773 | N32: 0 | O32: =Table178910111213235783[[#This Row],[Big 4 Items]]/Table178910111213235783[[#This Row],[Oil +/- ]] -> 0 | P32: =J32/S32 -> 0.90909091 | S32: =$T$1 -> 11
A33: Gulf Coast North | B33: 23 | C33: 339 | D33: 45 | G33: 2 | H33: 1 | I33: 481.92 | J33: 5 | K33: =Table178910111213235783[[#This Row],[On Time Counts]]/45 -> 0.11111111 | L33: 5842.02 | M33: =Table178910111213235783[[#This Row],[Wipers +/-]]/Table178910111213235783[[#This Row],[Comp Sales]] -> 0.00034234734 | N33: 0 | O33: =Table178910111213235783[[#This Row],[Big 4 Items]]/Table178910111213235783[[#This Row],[Oil +/- ]] -> 0 | P33: =J33/S33 -> 0.45454545 | S33: =$T$1 -> 11
A34: Gulf Coast North | B34: 24 | C34: -95 | D34: -95 | F34: 27 | I34: -424.94 | J34: 4 | K34: =Table178910111213235783[[#This Row],[On Time Counts]]/45 -> 0.088888889 | L34: 6567.35 | M34: =Table178910111213235783[[#This Row],[Wipers +/-]]/Table178910111213235783[[#This Row],[Comp Sales]] -> 0 | N34: 0 | O34: =Table178910111213235783[[#This Row],[Big 4 Items]]/Table178910111213235783[[#This Row],[Oil +/- ]] -> 0 | P34: =J34/S34 -> 0.36363636 | S34: =$T$1 -> 11
A35: Gulf Coast North | B35: 26 | C35: 5 | D35: 32 | E35: 202 | F35: -21 | H35: -1 | I35: 341.39 | J35: 8 | K35: =Table178910111213235783[[#This Row],[On Time Counts]]/45 -> 0.17777778 | L35: 5286.48 | M35: =Table178910111213235783[[#This Row],[Wipers +/-]]/Table178910111213235783[[#This Row],[Comp Sales]] -> 0 | N35: 0 | O35: =Table178910111213235783[[#This Row],[Big 4 Items]]/Table178910111213235783[[#This Row],[Oil +/- ]] -> 0 | P35: =J35/S35 -> 0.72727273 | S35: =$T$1 -> 11
A36: Gulf Coast West | B36: 46 | C36: 19 | D36: 19 | E36: 0 | I36: 42.51 | J36: 5 | K36: =Table178910111213235783[[#This Row],[On Time Counts]]/45 -> 0.11111111 | L36: 4596.08 | M36: =Table178910111213235783[[#This Row],[Wipers +/-]]/Table178910111213235783[[#This Row],[Comp Sales]] -> 0 | N36: 0 | O36: =Table178910111213235783[[#This Row],[Big 4 Items]]/Table178910111213235783[[#This Row],[Oil +/- ]] -> 0 | P36: =J36/S36 -> 0.45454545 | S36: =$T$1 -> 11
A37: Gulf Coast West | B37: 283 | C37: -1213 | D37: -1067 | E37: -21 | I37: -4140.53 | J37: 4 | K37: =Table178910111213235783[[#This Row],[On Time Counts]]/45 -> 0.088888889 | L37: 7096.63 | M37: =Table178910111213235783[[#This Row],[Wipers +/-]]/Table178910111213235783[[#This Row],[Comp Sales]] -> 0 | N37: 0 | O37: =Table178910111213235783[[#This Row],[Big 4 Items]]/Table178910111213235783[[#This Row],[Oil +/- ]] -> 0 | P37: =J37/S37 -> 0.36363636 | S37: =$T$1 -> 11
A38: Gulf Coast West | B38: 847 | C38: -147 | D38: -147 | G38: 83 | H38: -2 | I38: 29.3 | J38: 4 | K38: =Table178910111213235783[[#This Row],[On Time Counts]]/45 -> 0.088888889 | L38: 6662.04 | M38: =Table178910111213235783[[#This Row],[Wipers +/-]]/Table178910111213235783[[#This Row],[Comp Sales]] -> 0.012458646 | N38: 0 | O38: =Table178910111213235783[[#This Row],[Big 4 Items]]/Table178910111213235783[[#This Row],[Oil +/- ]] -> 0 | P38: =J38/S38 -> 0.36363636 | S38: =$T$1 -> 11
A39: Gulf Coast West | B39: 865 | C39: 1465 | D39: 1405 | E39: -1 | F39: 32 | G39: -1 | H39: 34 | I39: 4262.84 | J39: 10 | K39: =Table178910111213235783[[#This Row],[On Time Counts]]/45 -> 0.22222222 | L39: 3219.44 | M39: =Table178910111213235783[[#This Row],[Wipers +/-]]/Table178910111213235783[[#This Row],[Comp Sales]] -> -0.00031061303 | N39: 0 | O39: =Table178910111213235783[[#This Row],[Big 4 Items]]/Table178910111213235783[[#This Row],[Oil +/- ]] -> 0 | P39: =J39/S39 -> 0.90909091 | S39: =$T$1 -> 11
A40: Gulf Coast West | B40: 919 | C40: -22 | D40: -9 | F40: 0 | G40: -1 | H40: 4 | I40: 28.47 | J40: 8 | K40: =Table178910111213235783[[#This Row],[On Time Counts]]/45 -> 0.17777778 | L40: 3981.57 | M40: =Table178910111213235783[[#This Row],[Wipers +/-]]/Table178910111213235783[[#This Row],[Comp Sales]] -> -0.00025115721 | N40: 0 | O40: =Table178910111213235783[[#This Row],[Big 4 Items]]/Table178910111213235783[[#This Row],[Oil +/- ]] -> 0 | P40: =J40/S40 -> 0.72727273 | S40: =$T$1 -> 11
A41: Gulf Coast West | B41: 954 | C41: 111 | D41: 103 | E41: 2 | G41: -10 | H41: -8 | I41: 681.01 | J41: 7 | K41: =Table178910111213235783[[#This Row],[On Time Counts]]/45 -> 0.15555556 | M41: =Table178910111213235783[[#This Row],[Wipers +/-]]/Table178910111213235783[[#This Row],[Comp Sales]] -> #DIV/0! | O41: =Table178910111213235783[[#This Row],[Big 4 Items]]/Table178910111213235783[[#This Row],[Oil +/- ]] -> 0 | P41: =J41/S41 -> 0.63636364 | S41: =$T$1 -> 11
...

Sheet P10 - 10-25
A1: District | B1: Lubricants/Oil +/- | C1: Oil +/- | D1: Oil Filters +/- | E1: Air Filters +/- | F1: Wipers +/- | G1: Cabins +/- | H1: Adjustment Variance | I1: On Time Counts | J1: Count Compliance | L1: Comp Sales | M1: Comp Attainment | N1: Big 4 | O1: Coolant | S1: Total Count Target | T1: 11
A2: =A12 -> Baton Rouge North | B2: =SUM(C12:C19) -> -997.84 | C2: =SUM(D12:D19) -> -897.84 | D2: =SUM(E12:E19) -> 5 | E2: =SUM(F12:F19) -> 114 | F2: =SUM(G12:G19) -> -371 | G2: =SUM(H12:H19) -> -17 | H2: =SUM(I12:I19) -> -3300.3574 | I2: =SUM(J12:J19) -> 25 | J2: =I2/SUM(S12:S19) -> 0.37878788 | L2: =SUM(L12:L12) -> 4238.98 | M2: =((F2-G12)/L2)-100% -> -1.0875211 | N2: =SUM(N12:N12)/C2 -> 0 | O2: =SUM(P12:P12)/C2 -> -0.00010125311
A3: =A20 -> Baton Rouge South | B3: =SUM(C20:C26) -> 1829.87 | C3: =SUM(D20:D26) -> 2131.87 | D3: =SUM(E20:E26) -> 33 | E3: =SUM(F20:F26) -> 148 | F3: =SUM(G20:G26) -> -224 | G3: =SUM(H20:H26) -> -68 | H3: =SUM(I20:I26) -> 5757.8316 | I3: =SUM(J20:J26) -> 49 | J3: =I3/SUM(S20:S26) -> 0.63636364 | L3: =SUM(L13:L13) -> 5844.34 | M3: =((F3-G13)/L3)-100% -> -1.0491073 | N3: =SUM(N13:N13)/C3 -> 0 | O3: =SUM(P13:P13)/C3 -> 0.00034114309
A4: =A27 -> Gulf Coast North | B4: =SUM(C27:C35) -> 8225 | C4: =SUM(D27:D35) -> 3288 | D4: =SUM(E27:E35) -> -38 | E4: =SUM(F27:F35) -> -18 | F4: =SUM(G27:G35) -> -43 | G4: =SUM(H27:H35) -> 55 | H4: =SUM(I27:I35) -> 20698.06 | I4: =SUM(J27:J35) -> 54 | J4: =I4/SUM(S27:S35) -> 0.54545455 | L4: =SUM(L14:L23) -> 52541.38 | M4: =(F4/L4)-100% -> -1.0008184 | N4: =SUM(N14:N23)/C4 -> 0 | O4: =SUM(P14:P23)/C4 -> #DIV/0!
A5: =A36 -> Gulf Coast West | B5: =SUM(C36:C42) -> -349 | C5: =SUM(D36:D42) -> -743 | D5: =SUM(E36:E42) -> 51 | E5: =SUM(F36:F42) -> 91 | F5: =SUM(G36:G42) -> 34 | G5: =SUM(H36:H42) -> 1 | H5: =SUM(I36:I42) -> -913.58 | I5: =SUM(J36:J42) -> 47 | J5: =I5/SUM(S36:S42) -> 0.61038961 | L5: =SUM(L24:L36) -> 80972.98 | M5: =((F5-G34-G35-G36)/L5)-100% -> -0.99943191 | N5: =SUM(N24:N36)/C5 -> 0 | O5: =SUM(P24:P36)/C5 -> -0.010522452
A6: =A43 -> Lafayette | B6: =SUM(C43:C50) -> 583 | C6: =SUM(D43:D50) -> 435 | D6: =SUM(E43:E50) -> -10 | E6: =SUM(F43:F50) -> 16 | F6: =SUM(G43:G50) -> -10 | G6: =SUM(H43:H50) -> -3 | H6: =SUM(I43:I50) -> 1867.82 | I6: =SUM(J43:J50) -> 68 | J6: =I6/SUM(S43:S50) -> 0.77272727
A7: =A51 -> NOLA North | B7: =SUM(C51:C59) -> 727 | C7: =SUM(D51:D59) -> 613 | D7: =SUM(E51:E59) -> -8 | E7: =SUM(F51:F59) -> 12 | F7: =SUM(G51:G59) -> 1 | G7: =SUM(H51:H59) -> 0 | H7: =SUM(I51:I59) -> 3347.6 | I7: =SUM(J51:J59) -> 72 | J7: =I7/SUM(S51:S59) -> 0.81818182 | L7: =SUM(L37:L45) -> 38554.76 | M7: =(F7/L7)-100% -> -0.99997406 | N7: =SUM(N37:N45)/C7 -> 0 | O7: =SUM(P37:P45)/C7 -> 0.0094913243
A8: =A60 -> NOLA South | B8: =SUM(C60:C68) -> 4305 | C8: =SUM(D60:D68) -> 2262 | D8: =SUM(E60:E68) -> 31 | E8: =SUM(F60:F68) -> 21 | F8: =SUM(G60:G68) -> 109 | G8: =SUM(H60:H68) -> 46 | H8: =SUM(I60:I68) -> 10430.82 | I8: =SUM(J60:J68) -> 75 | J8: =I8/SUM(S60:S68) -> 0.75757576 | L8: =SUM(L46:L54) -> 19465.43 | M8: =((F8-G54)/L8)-100% -> -0.99440033 | N8: =SUM(N46:N54)/C8 -> 0.00044208665 | O8: =SUM(P46:P54)/C8 -> 0.0032553653
A9: Gulf Coast | B9: =SUM(B2:B8) -> 14323.03 | C9: =SUM(C2:C8) -> 7089.03 | D9: =SUM(D2:D8) -> 64 | E9: =SUM(E2:E8) -> 384 | F9: =SUM(F2:F8) -> -504 | G9: =SUM(G2:G8) -> 14 | H9: =SUM(H2:H8) -> 37888.194 | I9: =SUM(I2:I8) -> 390 | J9: =I9/SUM(S12:S68) -> 0.65656566 | L9: =SUM(L2:L8) -> 201617.87 | M9: =((F9-G12-G13-G34-G35-G36-G54)/L9)-100% -> -1.0027527 | N9: {=SUM(Table1789101112132357834[Big 4 Items]/C9)} -> 0.00014106302 | O9: =SUM(Table1789101112132357834[Count Compliance2])/C9 -> #DIV/0!
A11: District | B11: Store | C11: Lubricants/Oil +/- | D11: Oil +/- | E11: Oil Filters +/- | F11: Air Filters +/- | G11: Wipers +/- | H11: Cabins +/- | I11: Adjustment Variance | J11: On Time Counts | K11: Count Compliance | L11: Comp Sales | M11: Comp Sales Attainment | N11: Big 4 Items | O11: Big 4 | P11: Count Compliance2
A12: Baton Rouge North | B12: 17 | F12: -33 | I12: -74.95 | J12: 1 | K12: =Table1789101112132357834[[#This Row],[On Time Counts]]/45 -> 0.022222222 | L12: 4238.98 | M12: =Table1789101112132357834[[#This Row],[Wipers +/-]]/Table1789101112132357834[[#This Row],[Comp Sales]] -> 0 | N12: 0 | O12: =Table1789101112132357834[[#This Row],[Big 4 Items]]/Table1789101112132357834[[#This Row],[Oil +/- ]] -> #DIV/0! | P12: =J12/S12 -> 0.090909091 | S12: =$T$1 -> 11
