Workbook
Name Slicer_Your_Name: #N/A

Sheet Dashboard
A1: Gulf Goast Region Recognition Dashboard
A3: 2025 | B3: Quarter 1 | D3: Quarter 2 | F3: Quarter 3 | H3: Quarter 4 | K3: 2025 | N3: YTD | Q3: Achievers Results | R3: YOUR HeartBeat | S3: Per Employee | T3: Per Shop
B4: KPI Award | C4: DM awards | D4: KPI Award | E4: DM awards | F4: KPI Award | G4: DM awards | H4: KPI Award | I4: DM awards | N4: KPI Award | O4: DM awards
A5: Baton Rouge North | B5: =SUM(B20+D20+F20) -> 12 | C5: =SUM(C20+E20+G20) -> 4 | K5: Baton Rouge North | N5: =SUM(B5+D5+F5+H5) -> 12 | O5: =SUM(C5+E5+G5+I5) -> 4 | Q5: 183 | R5: =Q5+O5+N5 -> 199
A6: Baton Rouge South | B6: =SUM(B21+D21+F21) -> 8 | C6: =SUM(C21+E21+G21) -> 8 | K6: Baton Rouge South | N6: =SUM(B6+D6+F6+H6) -> 8 | O6: =SUM(C6+E6+G6+I6) -> 8 | Q6: 128 | R6: =Q6+O6+N6 -> 144
A7: Gulf Coast North | B7: =SUM(B22+D22+F22) -> 4 | C7: =SUM(C22+E22+G22) -> 10 | K7: Gulf Coast North | N7: =SUM(B7+D7+F7+H7) -> 4 | O7: =SUM(C7+E7+G7+I7) -> 10 | Q7: 56 | R7: =Q7+O7+N7 -> 70
A8: Gulf Coast West | B8: =SUM(B23+D23+F23) -> 15 | C8: =SUM(C23+E23+G23) -> 3 | K8: Gulf Coast West | N8: =SUM(B8+D8+F8+H8) -> 15 | O8: =SUM(C8+E8+G8+I8) -> 3 | Q8: 31 | R8: =Q8+O8+N8 -> 49
A9: Lafayette | B9: =SUM(B24+D24+F24) -> 7 | C9: =SUM(C24+E24+G24) -> 6 | K9: Lafayette | N9: =SUM(B9+D9+F9+H9) -> 7 | O9: =SUM(C9+E9+G9+I9) -> 6 | Q9: 35 | R9: =Q9+O9+N9 -> 48
A10: NOLA North | B10: =SUM(B25+D25+F25) -> 5 | C10: =SUM(C25+E25+G25) -> 8 | K10: NOLA North | N10: =SUM(B10+D10+F10+H10) -> 5 | O10: =SUM(C10+E10+G10+I10) -> 8 | Q10: 74 | R10: =Q10+O10+N10 -> 87
A11: NOLA South | B11: =SUM(B26+D26+F26) -> 17 | C11: =SUM(C26+E26+G26) -> 4 | K11: NOLA South | N11: =SUM(B11+D11+F11+H11) -> 17 | O11: =SUM(C11+E11+G11+I11) -> 4 | Q11: 145 | R11: =Q11+O11+N11 -> 166
A12: Region Totals | B12: =SUM(B5:B11) -> 68 | C12: =SUM(C5:C11) -> 43 | D12: =SUM(D5:D11) -> 0 | E12: =SUM(E5:E11) -> 0 | F12: =SUM(F5:F11) -> 0 | G12: =SUM(G5:G11) -> 0 | H12: =SUM(H5:H11) -> 0 | I12: =SUM(I5:I11) -> 0 | K12: Region Totals | N12: =SUM(N5:N11) -> 68 | O12: =SUM(O5:O11) -> 43 | Q12: =SUM(Q5:Q11) -> 652 | R12: =Q12+O12+N12 -> 763
A13: Region HeartBeat | B13: =SUM(B12:C12) -> 111 | D13: =SUM(D12:E12) -> 0 | F13: =SUM(F12:G12) -> 0 | H13: =SUM(H12:I12) -> 0 | K13: Region Heartbeat | N13: =SUM(N12:O12) -> 111 | Q13: =N13+Q12 -> 763
A14: Heart Beats | C14: =B13/C16 -> 2.1764706 | E14: 0 | G14: 0 | I14: 0 | N14: =N13/350 -> 0.31714286 | O14: =N13/51 -> 2.1764706 | Q14: =Q13/346 -> 2.2052023 | S14: =Q13/51 -> 14.960784
B15: per Employee | C15: Per Shop | D15: per Employee | E15: Per Shop | F15: per Employee | G15: Per Shop | H15: per Employee | I15: Per Shop | N15: per Employee | O15: Per Shop | Q15: per Employee | S15: Per Shop
B16: =C16*6.8 -> 346.8 | C16: 51
A18: Q1 | B18: Period 1 | D18: Period 2 | F18: Period 3 | I18: Q2 | J18: Period 4 | L18: Period 5 | N18: Period 6
B19: KPI Award | C19: DM awards | D19: KPI Award | E19: DM awards | F19: KPI Award | G19: DM awards | J19: KPI Award | K19: DM awards | L19: KPI Award | M19: DM awards | N19: KPI Award | O19: DM awards
A20: Baton Rouge North | B20: 1 | C20: 0 | D20: 5 | E20: 3 | F20: 6 | G20: 1 | I20: Baton Rouge North
A21: Baton Rouge South | B21: 3 | C21: 0 | D21: 1 | E21: 5 | F21: 4 | G21: 3 | I21: Baton Rouge South
A22: Gulf Coast North | B22: 1 | C22: 0 | D22: 1 | E22: 5 | F22: 2 | G22: 5 | I22: Gulf Coast North
A23: Gulf Coast West | B23: 7 | C23: 0 | D23: 4 | E23: 0 | F23: 4 | G23: 3 | I23: Gulf Coast West
A24: Lafayette | B24: 1 | C24: 0 | D24: 5 | E24: 0 | F24: 1 | G24: 6 | I24: Lafayette
A25: NOLA North | B25: 1 | C25: 0 | D25: 3 | E25: 2 | F25: 1 | G25: 6 | I25: NOLA North
A26: NOLA South | B26: 6 | C26: 0 | D26: 5 | E26: 3 | F26: 6 | G26: 1 | I26: NOLA South
A27: Region Totals | B27: =SUM(B20:B26) -> 20 | C27: =SUM(C20:C26) -> 0 | D27: =SUM(D20:D26) -> 24 | E27: =SUM(E20:E26) -> 18 | F27: =SUM(F20:F26) -> 24 | G27: =SUM(G20:G26) -> 25
A28: Region | B28: =SUM(B27:C27) -> 20 | D28: =SUM(D27:E27) -> 42 | F28: =SUM(F27:G27) -> 49 | I28: Region
A31: Q3 | B31: Period 7 | D31: Period 8 | F31: Period 9 | I31: Q4 | J31: Period 10 | L31: Period 11 | N31: Period 12
B32: KPI Award | C32: DM awards | D32: KPI Award | E32: DM awards | F32: KPI Award | G32: DM awards | J32: KPI Award | K32: DM awards | L32: KPI Award | M32: DM awards | N32: KPI Award | O32: DM awards
A33: Baton Rouge North | I33: Baton Rouge North
A34: Baton Rouge South | I34: Baton Rouge South
A35: Gulf Coast North | I35: Gulf Coast North
A36: Gulf Coast West | I36: Gulf Coast West
A37: Lafayette | I37: Lafayette
A38: NOLA North | I38: NOLA North
A39: NOLA South | I39: NOLA South
A40: Region | I40: Region

Sheet Repeaters
A1: YTD Regional winners
A2: # | B2: Employee Name | C2: Period 1 | D2: Period 2 | E2: Period 3 | F2: Period 4 | G2: Period 5 | H2: Period 6 | I2: Period 7 | J2: Period 8 | K2: Period 9 | L2: Period 10 | M2: Period 11 | N2: Period 12
A3: 1 | C3: =COUNTIF('p3 DM'!B4:F36, B3) + COUNTIF('P3'!C6:D24, B3) -> 0
A4: =A3+1 -> 2 | B4: {=_xlfn.LET( _xlpm.dmData, _xlfn._xlws.FILTER('p3 DM'!B5:F37, 'p3 DM'!B5:F37<>""), _xlpm.p3Data, _xlfn._xlws.FILTER('P3'!C7:D25, 'P3'!C7:D25<>""), _xlpm.allNames, _xlfn.VSTACK(_xlpm.dmData, _xlpm.p3Data), _xlfn.UNIQUE(_xlpm.allNames) )} -> #VALUE! | C4: {=_xlfn.LET( _xlpm.name, B4, COUNTIF('p3 DM'!B5:F37, _xlpm.name) + COUNTIF('P3'!C7:D25, _xlpm.name) )} -> 0
A5: =A4+1 -> 3 | B5: {=_xlfn.LET( _xlpm.dmData, _xlfn._xlws.FILTER('p3 DM'!B6:F38, 'p3 DM'!B6:F38<>""), _xlpm.p3Data, _xlfn._xlws.FILTER('P3'!C8:D26, 'P3'!C8:D26<>""), _xlpm.allNames, _xlfn.VSTACK(_xlpm.dmData, _xlpm.p3Data), _xlfn.UNIQUE(_xlpm.allNames) )} -> #VALUE! | C5: {=_xlfn.LET( _xlpm.name, B5, COUNTIF('p3 DM'!B6:F38, _xlpm.name) + COUNTIF('P3'!C8:D26, _xlpm.name) )} -> 0
A6: =A5+1 -> 4 | B6: {=_xlfn.LET( _xlpm.dmData, _xlfn._xlws.FILTER('p3 DM'!B7:F39, 'p3 DM'!B7:F39<>""), _xlpm.p3Data, _xlfn._xlws.FILTER('P3'!C9:D27, 'P3'!C9:D27<>""), _xlpm.allNames, _xlfn.VSTACK(_xlpm.dmData, _xlpm.p3Data), _xlfn.UNIQUE(_xlpm.allNames) )} -> #VALUE! | C6: {=_xlfn.LET( _xlpm.name, B6, COUNTIF('p3 DM'!B7:F39, _xlpm.name) + COUNTIF('P3'!C9:D27, _xlpm.name) )} -> 0
A7: =A6+1 -> 5 | B7: {=_xlfn.LET( _xlpm.dmData, _xlfn._xlws.FILTER('p3 DM'!B8:F40, 'p3 DM'!B8:F40<>""), _xlpm.p3Data, _xlfn._xlws.FILTER('P3'!C10:D28, 'P3'!C10:D28<>""), _xlpm.allNames, _xlfn.VSTACK(_xlpm.dmData, _xlpm.p3Data), _xlfn.UNIQUE(_xlpm.allNames) )} -> #VALUE! | C7: {=_xlfn.LET( _xlpm.name, B7, COUNTIF('p3 DM'!B8:F40, _xlpm.name) + COUNTIF('P3'!C10:D28, _xlpm.name) )} -> 0
A8: =A7+1 -> 6 | B8: {=_xlfn.LET( _xlpm.dmData, _xlfn._xlws.FILTER('p3 DM'!B9:F41, 'p3 DM'!B9:F41<>""), _xlpm.p3Data, _xlfn._xlws.FILTER('P3'!C11:D29, 'P3'!C11:D29<>""), _xlpm.allNames, _xlfn.VSTACK(_xlpm.dmData, _xlpm.p3Data), _xlfn.UNIQUE(_xlpm.allNames) )} -> #VALUE! | C8: {=_xlfn.LET( _xlpm.name, B8, COUNTIF('p3 DM'!B9:F41, _xlpm.name) + COUNTIF('P3'!C11:D29, _xlpm.name) )} -> 0
A9: =A8+1 -> 7 | B9: {=_xlfn.LET( _xlpm.dmData, _xlfn._xlws.FILTER('p3 DM'!B10:F42, 'p3 DM'!B10:F42<>""), _xlpm.p3Data, _xlfn._xlws.FILTER('P3'!C12:D30, 'P3'!C12:D30<>""), _xlpm.allNames, _xlfn.VSTACK(_xlpm.dmData, _xlpm.p3Data), _xlfn.UNIQUE(_xlpm.allNames) )} -> #VALUE! | C9: {=_xlfn.LET( _xlpm.name, B9, COUNTIF('p3 DM'!B10:F42, _xlpm.name) + COUNTIF('P3'!C12:D30, _xlpm.name) )} -> 0
A10: =A9+1 -> 8 | B10: {=_xlfn.LET( _xlpm.dmData, _xlfn._xlws.FILTER('p3 DM'!B11:F43, 'p3 DM'!B11:F43<>""), _xlpm.p3Data, _xlfn._xlws.FILTER('P3'!C13:D31, 'P3'!C13:D31<>""), _xlpm.allNames, _xlfn.VSTACK(_xlpm.dmData, _xlpm.p3Data), _xlfn.UNIQUE(_xlpm.allNames) )} -> #VALUE! | C10: {=_xlfn.LET( _xlpm.name, B10, COUNTIF('p3 DM'!B11:F43, _xlpm.name) + COUNTIF('P3'!C13:D31, _xlpm.name) )} -> 0
A11: =A10+1 -> 9 | B11: {=_xlfn.LET( _xlpm.dmData, _xlfn._xlws.FILTER('p3 DM'!B12:F44, 'p3 DM'!B12:F44<>""), _xlpm.p3Data, _xlfn._xlws.FILTER('P3'!C14:D32, 'P3'!C14:D32<>""), _xlpm.allNames, _xlfn.VSTACK(_xlpm.dmData, _xlpm.p3Data), _xlfn.UNIQUE(_xlpm.allNames) )} -> #VALUE! | C11: {=_xlfn.LET( _xlpm.name, B11, COUNTIF('p3 DM'!B12:F44, _xlpm.name) + COUNTIF('P3'!C14:D32, _xlpm.name) )} -> 0
A12: =A11+1 -> 10 | B12: {=_xlfn.LET( _xlpm.dmData, _xlfn._xlws.FILTER('p3 DM'!B13:F45, 'p3 DM'!B13:F45<>""), _xlpm.p3Data, _xlfn._xlws.FILTER('P3'!C15:D33, 'P3'!C15:D33<>""), _xlpm.allNames, _xlfn.VSTACK(_xlpm.dmData, _xlpm.p3Data), _xlfn.UNIQUE(_xlpm.allNames) )} -> #VALUE! | C12: {=_xlfn.LET( _xlpm.name, B12, COUNTIF('p3 DM'!B13:F45, _xlpm.name) + COUNTIF('P3'!C15:D33, _xlpm.name) )} -> 0
A13: =A12+1 -> 11 | B13: {=_xlfn.LET( _xlpm.dmData, _xlfn._xlws.FILTER('p3 DM'!B14:F46, 'p3 DM'!B14:F46<>""), _xlpm.p3Data, _xlfn._xlws.FILTER('P3'!C16:D34, 'P3'!C16:D34<>""), _xlpm.allNames, _xlfn.VSTACK(_xlpm.dmData, _xlpm.p3Data), _xlfn.UNIQUE(_xlpm.allNames) )} -> #VALUE! | C13: {=_xlfn.LET( _xlpm.name, B13, COUNTIF('p3 DM'!B14:F46, _xlpm.name) + COUNTIF('P3'!C16:D34, _xlpm.name) )} -> 0
A14: =A13+1 -> 12 | B14: {=_xlfn.LET( _xlpm.dmData, _xlfn._xlws.FILTER('p3 DM'!B15:F47, 'p3 DM'!B15:F47<>""), _xlpm.p3Data, _xlfn._xlws.FILTER('P3'!C17:D35, 'P3'!C17:D35<>""), _xlpm.allNames, _xlfn.VSTACK(_xlpm.dmData, _xlpm.p3Data), _xlfn.UNIQUE(_xlpm.allNames) )} -> #VALUE! | C14: {=_xlfn.LET( _xlpm.name, B14, COUNTIF('p3 DM'!B15:F47, _xlpm.name) + COUNTIF('P3'!C17:D35, _xlpm.name) )} -> 0
A15: =A14+1 -> 13 | B15: {=_xlfn.LET( _xlpm.dmData, _xlfn._xlws.FILTER('p3 DM'!B16:F48, 'p3 DM'!B16:F48<>""), _xlpm.p3Data, _xlfn._xlws.FILTER('P3'!C18:D36, 'P3'!C18:D36<>""), _xlpm.allNames, _xlfn.VSTACK(_xlpm.dmData, _xlpm.p3Data), _xlfn.UNIQUE(_xlpm.allNames) )} -> #VALUE! | C15: {=_xlfn.LET( _xlpm.name, B15, COUNTIF('p3 DM'!B16:F48, _xlpm.name) + COUNTIF('P3'!C18:D36, _xlpm.name) )} -> 0
... A34: =A33+1 -> 32 | B34: {=_xlfn.LET( _xlpm.dmData, _xlfn._xlws.FILTER('p3 DM'!B35:F67, 'p3 DM'!B35:F67<>""), _xlpm.p3Data, _xlfn._xlws.FILTER('P3'!C37:D55, 'P3'!C37:D55<>""), _xlpm.allNames, _xlfn.VSTACK(_xlpm.dmData, _xlpm.p3Data), _xlfn.UNIQUE(_xlpm.allNames) )} -> #VALUE! | C34: {=_xlfn.LET( _xlpm.name, B34, COUNTIF('p3 DM'!B35:F67, _xlpm.name) + COUNTIF('P3'!C37:D55, _xlpm.name) )} -> 0
A35: 33 | B35: {=_xlfn.LET( _xlpm.dmData, _xlfn._xlws.FILTER('p3 DM'!B36:F68, 'p3 DM'!B36:F68<>""), _xlpm.p3Data, _xlfn._xlws.FILTER('P3'!C38:D56, 'P3'!C38:D56<>""), _xlpm.allNames, _xlfn.VSTACK(_xlpm.dmData, _xlpm.p3Data), _xlfn.UNIQUE(_xlpm.allNames) )} -> #VALUE! | C35: {=_xlfn.LET( _xlpm.name, B35, COUNTIF('p3 DM'!B36:F68, _xlpm.name) + COUNTIF('P3'!C38:D56, _xlpm.name) )} -> 0

Sheet P1
A1: Gulf Coast Region Period 1 Winners
A8: KPI | B8: Qualifier | C8: Name | D8: Shop
A9: Over ALL | B9: All 3s or below are omitted | C9: Kyler Pierre | D9: 832
A10: NPS | B10: 85% or better Tie goes to survey count | C10: Colby Smith | D10: 20
A11: Email Collection | B11: highest email 50 changes min. | C11: Kyler Pierre | D11: 832
A12: Pmix | B12: highest pmix 50 changes min. | C12: Amanda Herbert | D12: 865
A13: Big 4 | B13: Highest overall 50 changes min. | C13: Cory Brathbury | D13: 12
A14: Bay Time | B14: Highest overall 50 changes min. | C14: Blake Theriot | D14: 8
A15: Total Oil Changes | B15: Min of 50 to qualify | C15: Scott Tillis
A16: Net ARO | B16: Highest over all 50 changes min | C16: Michael Martinez | D16: 12
A17: Coolants | B17: Highest overall 50 changes min. | C17: Jason Thompson | D17: 12
A18: Discounts | B18: Lowest discounts overall 50 changes min. | C18: Blake Matte | D18: 843
A19: Cars vs bud | B19: Highest overall % over budget | D19: 865
A20: cars vs comp | B20: Highest overall over % over Comp cars
A21: sales vs budget | B21: Highest overall % over budget | D21: 448
A22: sales vs comp | B22: Highest overall % over Comp
A23: Claims by district | B23: NA | C23: NA
A24: Claims by shop | B24: NA | C24: NA
A26: District Manager Awards
A27: Most Improved | B27: District Manager Selection
A28: Best Audits | B28: District Manager Selection
A29: Best Visits | B29: District Manager Selection
A30: Turnover | B30: District Manager Selection
A31: Compliance | B31: District Manager Selection
B32: District Manager Selection
B33: District Manager Selection

Sheet p2
A1: Gulf Coast Region Period 2 Winners
A5: KPI | B5: Qualifier | C5: TOP KPIs | D5: Shop Winner
A6: Over ALL Top TECH | B6: Ranked overall NPS 85% or better | C6: Jessica Simmions 5.0
A7: Power Ranker #1 | B7: Rank in top 3 for period on power ranking | C7: Steven Strickland | D7: Shop 12
A8: Power Ranker #2 | B8: Rank in top 3 for period on power ranking | C8: Anthony Loyal | D8: Shop 448
A9: Power Ranker #3 | B9: Rank in top 3 for period on power ranking | C9: Mason Champagne | D9: Shop 26
A10: NPS | B10: 85% or better Tie goes to survey count | C10: Ronald Santos 100% | D10: 100 %Shop 12
A11: Email Collection | B11: highest email 50 changes min. | C11: Jessica Simmions 92% | D11: 86% Shop 31
A12: Pmix | B12: highest pmix 50 changes min. | C12: Amanda Hebert 99% | D12: 98.3% Shop 6
A13: Big 4 | B13: Highest overall 50 changes min. | C13: Thaij James Shop 113% | D13: 117.1% Shop 843
A14: Total Oil Changes | B14: Min of 50 to qualify | C14: Blake Theriot 385
A15: Net ARO | B15: Highest over all 50 changes min | C15: Carl Arnold $171.62 | D15: $175.44 Shop 843
A16: Coolants | B16: Highest overall 50 changes min. | C16: Jason Thompson 29% | D16: 22% Shop 17
A17: Discounts | B17: Lowest discounts overall 50 changes min. | C17: Thaij James Shop $6.19 | D17: 4.2% Shop 720
A18: Differentials | B18: Shop with the highest overall Differential % | C18: Kirby Swan | D18: 7.3% Shop 843
A19: Cars vs Budget | B19: Highest overall % over budget | C19: Heather Roberts | D19: +180 Shop 865
A20: cars vs comp | B20: Highest overall over % over Comp cars | C20: Loren Parfait | D20: +135 Shop 116
A21: sales vs budget | B21: Highest overall % over budget | C21: Brandon Vega | D21: +$5429 Shop 92
A22: sales vs comp | B22: Highest overall % over Comp | C22: Heather Roberts | D22: +43.9% Shop 865
A24: District Maanger Awards
A25: Kirby Swan Shop # 843 | B25: Desi White Shop #832 | C25: Dimitri Clark Shop #8 | D25: Barnell Tatum Shop #11
A26: Clyde Williamson Shop #717 | B26: Dee Kirst Shop #282 | C26: Joe Billiot Shop #20 | D26: Brandon Vega Shop #92
A27: Dekotah Coley Shop #641 | B27: Miguel Alix Shop #4 | C27: Ash Wilcox Shop #14 | D27: Anthony Loyal Shop # 448
A28: Christian Broussard Shop #531 | B28: Taylor harris Shop #2 | C28: Anthony Mury Shop #24

Sheet P3
A1: Gulf Coast Region Period 3 Winners
A5: KPI | B5: Qualifier
A6: Top Tech Over ALL | B6: Ranked overall NPS 85% or better | C6: Jessica Simmions 5.0 | F6: District Manager instructions
A7: Total Oil Changes | B7: Min of 50 to qualify | C7: Anthony McCarthy Shop 4
A8: Power Ranker #1 | B8: Rank in top 3 for period on power ranking | C8: Anthony Loyal | D8: Shop 448 | G8: Look to see how many slots you have and go to "tab" P3 DM to fill in your awards
A9: Power Ranker #2 | B9: Rank in top 3 for period on power ranking | C9: Loren Parfait | D9: Shop 116 | G9: Slots for D.M awards
A10: Power Ranker #3 | B10: Rank in top 3 for period on power ranking | C10: Cory Brathbury | D10: Shop 12 | G10: Baton Rouge North | H10: Baton Rouge South | I10: Gulf Coast North | J10: Gulf Coast West | K10: Lafayette | L10: NOLA North | M10: NOLA South
A11: KPI | C11: Top Shop | G11: 1 | H11: 3 | I11: 5 | J11: 3 | K11: 6 | L11: 6 | M11: 1 | N11: =SUM(G11:M11) -> 25
A12: Cars vs Budget | B12: Highest overall % over budget | C12: Heather Roberts | D12: Shop 865 + 25.98
A13: cars vs comp | B13: Highest overall over % over Comp cars | C13: Heather Roberts | D13: Shop 865 +25.98 | G13: Correct Name and spelling for all your shop winners & confirm still employed
A14: sales vs budget | B14: Highest overall % over budget | C14: Heather Roberts | D14: Shop 865 + 42.4% | G14: Shop and Tech KPI Winners
A15: sales vs comp | B15: Highest overall % over Comp | C15: Heather Roberts | D15: Shop 865 25.5% | G15: Baton Rouge North | H15: Baton Rouge South | I15: Gulf Coast North | J15: Gulf Coast West | K15: Lafayette | L15: NOLA North | M15: NOLA South
A16: KPI | B16: Qualifier | C16: Top Tech | D16: Top Shop | G16: 6 | H16: 4 | I16: 2 | J16: 4 | K16: 1 | L16: 1 | M16: 6 | N16: =SUM(G16:M16) -> 24
A17: NPS | B17: 85% or better Tie goes to survey count | C17: Lauren Witty Shop 12 | D17: Shop 12 100%
A18: Email Collection | B18: highest email 50 changes min. | C18: Devin Lepine -Shop 26 | D18: Shop 26 76% | G18: Donald | H18: Kelly | I18: Garrett
A19: Pmix | B19: highest pmix 75 changes min. total Changes Break Tie | C19: Dyniesha Johnson - Shop 22 | D19: Shop 832 98.1% | G19: Baton Rouge North | H19: Baton Rouge South | I19: Gulf Coast North | J19: Gulf Coast West | K19: Lafayette | L19: NOLA North | M19: NOLA South | N19: Total DM given
A20: Big 4 | B20: Highest overall 50 changes min. | C20: Dyniesha Johnson - Shop 22 | D20: Shop 843 - 80.1% | G20: =G11+G16 -> 7 | H20: =H11+H16 -> 7 | I20: =I11+I16 -> 7 | J20: =J11+J16 -> 7 | K20: =K11+K16 -> 7 | L20: =L11+L16 -> 7 | M20: =M11+M16 -> 7 | N20: =SUM(G20:M20) -> 49
A21: Net ARO | B21: Highest over all 50 changes min | C21: Dyniesha Johnson- Shop 22 | D21: Shop 12 - $162.21
A22: Coolants | B22: Highest overall 50 changes min. | C22: Corey Washington - Shop 31 | D22: Shop 19 - 14.1%
A23: Discounts | B23: Lowest discounts overall 50 changes min. | C23: Michael Raffety - Shop 641 | D23: Shop 641 6.1%
A24: Differentials | B24: Shop with the highest overall Differential % | C24: Christian Broussard | D24: Shop 531 6.8%
A26: District Manger Awards
A27: =_xlfn.TEXTJOIN(" ", TRUE, 'p3 DM'!B4,'p3 DM'!C4) -> Dee Kirst 282 | B27: =_xlfn.TEXTJOIN(" ", TRUE, 'p3 DM'!B13:C13) -> Barnell Tatum 11 | C27: =_xlfn.TEXTJOIN(" ", TRUE, 'p3 DM'!B22:C22) -> Loren Parfait 116 | D27: =_xlfn.TEXTJOIN(" ", TRUE, 'p3 DM'!B31:C31) -> Giovanni Morris 32
A28: =_xlfn.TEXTJOIN(" ", TRUE, 'p3 DM'!B5,'p3 DM'!C5) -> Kenneth Elliot 1 | B28: =_xlfn.TEXTJOIN(" ", TRUE, 'p3 DM'!B14:C14) -> Sharwood Harrison 11 | C28: =_xlfn.TEXTJOIN(" ", TRUE, 'p3 DM'!B23:C23) -> Darrell Vaughn 870 | D28: =_xlfn.TEXTJOIN(" ", TRUE, 'p3 DM'!B32:C32) -> James Schuster 2
A29: =_xlfn.TEXTJOIN(" ", TRUE, 'p3 DM'!B6,'p3 DM'!C6) -> Christian Broussrd 531 | B29: =_xlfn.TEXTJOIN(" ", TRUE, 'p3 DM'!B15:C15) -> Shawn Goodman 23 | C29: =_xlfn.TEXTJOIN(" ", TRUE, 'p3 DM'!B24:C24) -> Matthew McCarter 10 | D29: =_xlfn.TEXTJOIN(" ", TRUE, 'p3 DM'!B33:C33) -> Jason Thompson 4
A30: =_xlfn.TEXTJOIN(" ", TRUE, 'p3 DM'!B7,'p3 DM'!C7) -> Desi White 832 | B30: =_xlfn.TEXTJOIN(" ", TRUE, 'p3 DM'!B16:C16) -> Jay Caston 3 | C30: =_xlfn.TEXTJOIN(" ", TRUE, 'p3 DM'!B25:C25) -> Thaij James 720 | D30: =_xlfn.TEXTJOIN(" ", TRUE, 'p3 DM'!B28:C28) -> Brandin Cormier 599
A31: =_xlfn.TEXTJOIN(" ", TRUE, 'p3 DM'!B8,'p3 DM'!C8) -> Kirby Swan 843 | B31: =_xlfn.TEXTJOIN(" ", TRUE, 'p3 DM'!B17:C17) -> Mason Champagne 26 | C31: =_xlfn.TEXTJOIN(" ", TRUE, 'p3 DM'!B26:C26) -> Kerry Malveaux 280 | D31: =_xlfn.TEXTJOIN(" ", TRUE, 'p3 DM'!B21:C21) -> Dimitri Clark 8
A32: =_xlfn.TEXTJOIN(" ", TRUE, 'p3 DM'!B9,'p3 DM'!C9) -> Clyde Williamson 717 | B32: =_xlfn.TEXTJOIN(" ", TRUE, 'p3 DM'!B18:C18) -> Devin Lepine 26 | C32: =_xlfn.TEXTJOIN(" ", TRUE, 'p3 DM'!B27:C27) -> Matthew Guillott 728 | D32: =_xlfn.TEXTJOIN(" ", TRUE, 'p3 DM'!B12,'p3 DM'!C12) -> Jamaryon Tatney 881
A33: =_xlfn.TEXTJOIN(" ", TRUE, 'p3 DM'!B10,'p3 DM'!C10) -> Percy Jones 22 | B33: =_xlfn.TEXTJOIN(" ", TRUE, 'p3 DM'!B19:C19) -> Darrell Vaughn 870 | C33: =_xlfn.TEXTJOIN(" ", TRUE, 'p3 DM'!B29:C29) -> Ali Abdullahi 6 | D33: =_xlfn.TEXTJOIN(" ", TRUE, 'p3 DM'!B30:C30) -> Taylor Harris 2
B34: =_xlfn.TEXTJOIN(" ", TRUE, 'p3 DM'!B20:C20) -> Cory Brathbury 12 | C34: =_xlfn.TEXTJOIN(" ", TRUE, 'p3 DM'!B11,'p3 DM'!C11) -> Carl Arnold 641 | D34: =_xlfn.TEXTJOIN(" ", TRUE, 'p3 DM'!B38:C38)

Sheet p3 DM
A1: Period 3 District Manager Winners
A3: # | B3: Employee Name | C3: Shop # | D3: Position | E3: Given for | F3: Your Name | H3: PPT cmpt
A4: 1 | B4: Dee Kirst | C4: 282 | D4: SM | E4: company Contest Winner | F4: Kelly O'Neill | H4: TRUE
A5: =A4+1 -> 2 | B5: Kenneth Elliot | C5: 1 | D5: SM | E5: Missy's Weekend Contest | F5: Brandon Lange | H5: TRUE
A6: =A5+1 -> 3 | B6: Christian Broussrd | C6: 531 | D6: SM | E6: KPI Quartly Trends | F6: Kelly O'Neill | H6: TRUE
A7: =A6+1 -> 4 | B7: Desi White | C7: 832 | D7: SM | E7: KPIs , sales & cars | F7: Kelly O'Neill | H7: TRUE
A8: =A7+1 -> 5 | B8: Kirby Swan | C8: 843 | D8: SM | E8: Q1 #1 Shop District Ranking | F8: Donald Roy | H8: TRUE
A9: =A8+1 -> 6 | B9: Clyde Williamson | C9: 717 | D9: SM | E9: DMIT Graduate | F9: Donald Roy | H9: TRUE
A10: =A9+1 -> 7 | B10: Percy Jones | C10: 22 | D10: SM | E10: Brand Standards Execution | F10: Donald Roy | H10: FALSE
A11: =A10+1 -> 8 | B11: Carl Arnold | C11: 641 | D11: ASM | E11: Employee W/ Highest NPS - BRN | F11: Donald Roy | H11: FALSE
A12: =A11+1 -> 9 | B12: Jamaryon Tatney | C12: 881 | D12: Tech | E12: Q1 KPIS W/ Most Service Writes | F12: Donald Roy | H12: TRUE
A13: =A12+1 -> 10 | B13: Barnell Tatum | C13: 11 | D13: SM | E13: #1 in KPIs / Sales / Diffs | F13: Garrett Gee | H13: TRUE
A14: =A13+1 -> 11 | B14: Sharwood Harrison | C14: 11 | D14: ASM | E14: Big-4 and Coolants | F14: Garrett Gee | H14: TRUE
A15: =A14+1 -> 12 | B15: Shawn Goodman | C15: 23 | D15: SM | E15: Cars vs PY & #1 Fuel Filters | F15: Garrett Gee | H15: TRUE
A16: =A15+1 -> 13 | B16: Jay Caston | C16: 3 | D16: SM | E16: #1 NPS | F16: Garrett Gee | H16: TRUE
... A35: =A34+1 -> 32 | B35: Jason Wallmuth | C35: 46 | D35: SM | E35: Best District Email Collection - 73% | F35: Cole | H35: FALSE
A36: 33 | B36: Dalton Harrington | C36: 847 | D36: SM | E36: Going the extra mile | F36: Cole | H36: FALSE

Sheet P4
A1: Gulf Coast Region Period 4 Winners
A2: KPI | C2: Qualifier | E2: Top Tech / Shop
A3: Over ALL (TOP TECH) | C3: Ranked overall NPS 85% or better | E3: Jessica Simonis | G3: Shop 280 | J3: District Manager instructions
A4: Power Ranker #1 | C4: Rank in top 3 for period on power ranking | E4: Barnell Tatum | G4: Shop 11
A5: Power Ranker #2 | C5: Rank in top 3 for period on power ranking | E5: Mason Champagne | G5: Shop 26 | K5: Look to see how many slots you have and go to "tab" P4 DM to fill in your awards
A6: Power Ranker #3 | C6: Rank in top 3 for period on power ranking | E6: Clyde Williamson | G6: Shop 717 | K6: Slots for D.M awards
K7: Baton Rouge North | L7: Baton Rouge South | M7: Gulf Coast North | N7: Gulf Coast West | O7: Lafayette | P7: NOLA North | Q7: NOLA South
A8: Cars vs Budget | C8: Highest overall % over budget | E8: Heather Roberts | G8: Shop 865 + 160 cars | K8: 4 | L8: 5 | M8: 2 | N8: 0 | O8: 5 | P8: 6 | Q8: 5 | R8: 26
A9: cars vs comp | C9: Highest overall over % over Comp cars | E9: Heather Roberts | G9: Shop 865 + 44.8%
A10: sales vs budget | C10: Highest overall % over budget | E10: Anthony Loyal | G10: Shop 448 +$38,620 | K10: Correct Name and spelling for all your shop winners & confirm still employed
A11: sales vs comp | C11: Highest overall % over Comp | E11: Heather Roberts | G11: Shop 865 + 53.1% | K11: Shop and Tech KPI Winners
E12: Top Tech | G12: Top Shop | K12: Baton Rouge North | L12: Baton Rouge South | M12: Gulf Coast North | N12: Gulf Coast West | O12: Lafayette | P12: NOLA North | Q12: NOLA South
A13: NPS | C13: 85% or better Tie goes to survey count | E13: Amanda Hebert | F13: # 865 100% | G13: Heather Roberts | H13: Shop 865 100% / 54 surveys | K13: 3 | L13: 2 | M13: 5 | N13: 8 | O13: 2 | P13: 1 | Q13: 2 | R13: 24
A14: Email Collection | C14: highest email 50 changes min. | E14: Cory Washington | F14: #31 91% | G14: Diogenes Fresh | H14: Shop 31 90%
A15: Pmix | C15: highest pmix 75 changes min. total Changes Break Tie | E15: Amanda Hebert | F15: #830 100%/ 155 changes | G15: Michael Parhams | H15: Shop 283 98 % | K15: Donald | L15: Kelly | M15: Garrett | N15: Cole | O15: Des | P15: brandon | Q15: james
A16: Big 4 | C16: Highest overall 50 changes min. | E16: Natiqua Johnson | F16: #18 116.5% | G16: Barnell Tatum | H16: Shop 11 79.7% | K16: Baton Rouge North | L16: Baton Rouge South | M16: Gulf Coast North | N16: Gulf Coast West | O16: Lafayette | P16: NOLA North | Q16: NOLA South | R16: Total DM given
A17: Total Oil Changes | C17: Min of 50 to qualify | E17: Isaiah Davis | F17: #865 723 changes | K17: 7 | L17: 7 | M17: 7 | N17: 8 | O17: 7 | P17: 7 | Q17: 7 | R17: 50
A18: Net ARO | C18: Highest over all 50 changes min | E18: Carl Arnold | F18: #641 $170.53 161 changes | G18: Barnell Tatum | H18: Shop 11 157.19
A19: Coolants | C19: Highest overall 50 changes min. | E19: David Shaw | F19: #29 24% | G19: Barnell Tatum | H19: Shop 11 15.2%
A20: Discounts | C20: Lowest discounts overall 50 changes min. | E20: Austin Cuevas | F20: #6 $7.50 | G20: Carl Arnold | H20: Shop 641 6.3%
A21: Differentials | C21: Shop with the highest overall Differential % | G21: Michael Parhams | H21: Shop 283 6.1%
A23: District Maanger Awards
A25: Rocke Chan | D25: Shawn Goodman | G25: Robert Mitchell
A26: Christian B | D26: Thaij James | G26: Chris Webster
A27: Kelsie Flintroy | D27: Jessica Simonis | G27: Cory Brathbury
A28: Lance Green | D28: Blaze Miller | G28: Darrell Vaughn
A29: Natiqua Johnson | D29: Ali Abdullahi | G29: Diogenes Fresh
A30: Clyde Williamson IV | D30: Jordan Bryant | G30: Matthew McCarter
A31: Kirby Swan | D31: Giovanni Morris | G31: Clarence Ray
A32: Carl Arnold | D32: Will Torns | G32: Brelle Lewis
A33: Djuan Flemings | D33: Raquel Carmadelle | G33: Rydell Washington
A34: Ash Wilcox | D34: Claudell McDonald

Sheet p4 DM
A1: Period 4 District Manager Winners
A3: # | B3: Employee Name | C3: Shop # | D3: Position | E3: Given for | F3: Your Name | H3: PPT cmpt
B4: Antonio G | C4: 447 | D4: SM | E4: 100 % NPS period 4 | F4: Kelly ONeill | H4: TRUE
B5: Rocke Chan | C5: 19 | D5: SM | E5: Highest District big 4 p4 58.3% | F5: Kelly ONeill | H5: TRUE
B6: Christian B | C6: 531 | D6: SM | E6: Highest Diif % #1 District #2 Region P4 & Highest FF % 57.1% | F6: Kelly ONeill | H6: TRUE
B7: Kelsie Flintroy | C7: 448 | D7: Tech | E7: Highest District NPS | F7: Kelly ONeill | H7: TRUE
B8: Lance Green | C8: 531 | D8: ASM | E8: TOP performing ASM on KPIs P4 | F8: Kelly ONeill | H8: TRUE
B9: Natiqua Johnson | C9: 18 | D9: Tech | E9: Highest ARO for the District P4 | F9: Kelly ONeill | H9: TRUE
B10: Clyde Williamson IV | C10: 717 | D10: SM | E10: Highest Sales Beat P4 | F10: Donald Roy | H10: TRUE
B11: Kirby Swan | C11: 843 | D11: SM | E11: 400% Fuel Filters | F11: Donald Roy | H11: TRUE
B12: Carl Arnold | C12: 641 | D12: Acting SM | E12: Highest District NPS P4 | F12: Donald Roy | H12: TRUE
B13: Djuan Flemings | C13: 881 | D13: SM | E13: Most Improved P3 to P4 | F13: Donald Roy | H13: TRUE
B14: Ash Wilcox | C14: 14 | D14: SM | E14: Big-4 at 60.9% and 11.8% Coolants | F14: Garrett Gee | H14: TRUE
B15: Shawn Goodman | C15: 23 | D15: SM | E15: Top district Fuel Filters at 47.6% | F15: Garrett Gee | H15: TRUE
... B34: Rydell Washington | C34: 31 | D34: CT | E34: Nola South Employee of the Month! | F34: James Cranch | H34: TRUE
H35: FALSE
H36: FALSE

Sheet P5
A1: Gulf Coast Region Period 5 Winners
A2: KPI | C2: Qualifier | E2: Top Tech / Shop
A3: Over ALL (TOP TECH) | C3: Ranked overall NPS 85% or better | E3: Logan Mooty | G3: Shop 865 | J3: District Manager instructions
A4: Power Ranker #1 | C4: Rank in top 3 for period on power ranking | E4: Giovanni Morris | G4: Shop 32
A5: Power Ranker #2 | C5: Rank in top 3 for period on power ranking | E5: Tameka Lewis | G5: Shop 870 | K5: Look to see how many slots you have and go to "tab" P4 DM to fill in your awards
A6: Power Ranker #3 | C6: Rank in top 3 for period on power ranking | E6: Christopher Wentworth | G6: Shop 847 | K6: Slots for D.M awards
K7: Baton Rouge North | L7: Baton Rouge South | M7: Gulf Coast North | N7: Gulf Coast West | O7: Lafayette | P7: NOLA North | Q7: NOLA South
A8: Cars vs Budget | C8: Highest overall % over budget | E8: Heather Roberts | G8: Shop 865 +106 cars | K8: 5 | L8: 1 | M8: 3 | N8: 2 | O8: 5 | P8: 4 | Q8: 3 | R8: 26
A9: cars vs comp | C9: Highest overall over % over Comp cars | E9: Anthony Loyal | G9: Shop 448 + 109 cars 11.9%
A10: sales vs budget | C10: Highest overall % over budget | E10: Anthony Loyal | G10: Shop 448 +$23,086 / +22.6% | K10: Correct Name and spelling for all your shop winners & confirm still employed
A11: sales vs comp | C11: Highest overall % over Comp | E11: Christopher Wentworth | G11: Shop 847 +$9,47 / 42.7% | K11: Shop and Tech KPI Winners
C12: All Require 80% min NPS | E12: Top Tech | G12: Top Shop | K12: Baton Rouge North | L12: Baton Rouge South | M12: Gulf Coast North | N12: Gulf Coast West | O12: Lafayette | P12: NOLA North | Q12: NOLA South
A13: NPS | C13: 85% or better Tie goes to survey count | E13: Amanda Hebert | F13: # 865 25/100% | G13: Tameka Lewis | H13: Shop 870 100% | K13: 2 | L13: 6 | M13: 4 | N13: 5 | O13: 2 | P13: 3 | Q13: 4 | R13: 24
A14: Email Collection | C14: highest email 50 changes min. | E14: Blaze Miller | F14: #728 91% | G14: Giovanni Morris | H14: Shop 32 89%
A15: Pmix | C15: highest pmix 75 changes min. total Changes Break Tie | E15: Chan Herndon | F15: #26 98.86% | G15: Christian Broussard | H15: Shop 531 97.6 % | K15: Donald | L15: Kelly | M15: Garrett | N15: Cole | O15: Des | P15: brandon | Q15: james
A16: Big 4 | C16: Highest overall 50 changes min. | E16: Herman Flintroy | F16: #448 133/118.56% | G16: Giovanni Morris | H16: Shop 32 /68.8% | K16: Baton Rouge North | L16: Baton Rouge South | M16: Gulf Coast North | N16: Gulf Coast West | O16: Lafayette | P16: NOLA North | Q16: NOLA South | R16: Total DM given
A17: Total Oil Changes | C17: Min of 50 to qualify | E17: Brandon Place | F17: #21 | K17: 7 | L17: 7 | M17: 7 | N17: 7 | O17: 7 | P17: 7 | Q17: 7 | R17: 49
A18: Net ARO | C18: Highest over all 50 changes min | E18: Wadee Hodges | F18: #22 $171.08 125 changes | G18: Barnell Tatum | H18: Shop 11 / $149.97
A19: Coolants | C19: Highest overall 50 changes min. | E19: Joe Jeanfreau | F19: #14 22.5% | G19: Rocke Chan | H19: Shop 19 13.9%
A20: Discounts | C20: Lowest discounts overall 50 changes min. | E20: Blaze Miller | F20: #728 $9.0 | G20: Kevin Sartin | H20: Shop 17 / 7.2%
A21: Differentials | C21: Shop with the highest overall Differential % | G21: Christian Broussard | H21: Shop 531 4.7%
A22: Donations | C22: Highest Donations | E22: Rydell Washington | F22: Shop 31 $609 | G22: Brandon Vega | H22: Shop 92 $1850.50
A24: District Maanger Awards

Sheet P5 DM
A1: Period 4 District Manager Winners
A3: # | B3: Employee Name | C3: Shop # | D3: Position | E3: Given for | F3: Your Name | H3: PPT cmpt
B4: James Long | C4: 881 | D4: CT | E4: Highest Performance Score | F4: Donald Roy | H4: TRUE
B5: Calin Labbe | C5: 641 | D5: LT | E5: 100% NPS Most Surveys | F5: Donald Roy | H5: TRUE
B6: Clyde Williamson IV | C6: 717 | D6: SM | E6: Highest Sales Beat Baton Rouge North | F6: Donald Roy | H6: TRUE
B7: Kevin Sartin | C7: 17 | D7: SM | E7: 100% NPS 826 Oil Changes | F7: Donald Roy | H7: TRUE
B8: Noah Jourdan | C8: 717 | D8: LT | E8: Promoted to Lead Tech | F8: Donald Roy | H8: TRUE
B9: Hayden Smith | C9: 22 | D9: ASM | E9: Promoted to ASM | F9: Donald Roy | H9: TRUE
B10: Joe Billiot | C10: 20 | D10: SM | E10: District NPS Leader | F10: Garrett Gee | H10: TRUE
B11: Kevin Arthur | C11: 21 | D11: SM | E11: Big-4 and Coolant Record | F11: Garrett Gee | H11: TRUE
B12: Shawn Goodman | C12: 23 | D12: SM | E12: District Leader in Sales Comp | F12: Garrett Gee | H12: TRUE
B13: Ash Wilcox | C13: 14 | D13: SM | E13: Big-4 and Coolant Performance | F13: Garrett Gee | H13: TRUE
B14: Christopher Webster | C14: 919 | D14: SM | E14: Training New SM's | F14: Cole Couvillion | H14: TRUE
B15: Ryan White | C15: 919 | D15: ASM | E15: Maintained 64% Big 4 as a store with SM out | F15: Cole Couvillion | H15: TRUE
... B27: Blake Theriot | C27: 12 | D27: ASM | E27: Employee of the Month | F27: James Cranch | H27: TRUE
H28: FALSE
H29: FALSE
H30: FALSE
H31: FALSE
H32: FALSE
H33: FALSE
H34: FALSE
H35: FALSE
H36: FALSE

Sheet P6
A1: Gulf Coast Region Period 6 Winners
A2: KPI | C2: District | D2: Top Shop
A3: Over ALL (TOP TECH) | I3: District Manager instructions
A4: Power Ranker #1 | C4: Nola S | D4: Shop 12 - Cory Brathbury | F4: Power Ranker #1
A5: Power Ranker #2 | C5: GCW | D5: Shop 919 - Chris Webster | F5: Power Ranker #2 | J5: Look to see how many slots you have and go to "tab" P4 DM to fill in your awards
A6: Power Ranker #3 | C6: Nola s | D6: Shop 13 - Mike Dear | F6: Power Ranker #3 | J6: Slots for D.M awards
J7: Baton Rouge North | K7: Baton Rouge South | L7: Gulf Coast North | M7: Gulf Coast West | N7: Lafayette | O7: NOLA North | P7: NOLA South
A8: Cars vs Budget | C8: GCW | D8: 865 - Heather Roberts | F8: 113 | J8: =J17-J13 -> 6 | K8: =K17-K13 -> 7 | L8: =L17-L13 -> 7 | M8: =M17-M13 -> 3 | N8: =N17-N13 -> 4 | O8: =O17-O13 -> 5 | P8: =P17-P13 -> 3 | Q8: 26
A9: cars vs comp | C9: GCW | D9: 865 - Heather Roberts | F9: 0.164
A10: sales vs budget | C10: Nola S | D10: Shop 870 - Tameka Lewis | F10: 0.25 | J10: Correct Name and spelling for all your shop winners & confirm still employed
A11: sales vs comp | C11: NOLA N | D11: Shop 32 Giovanni Morris | F11: 0.493 | J11: Shop and Tech KPI Winners
C12: District | D12: Shop | F12: Result | J12: Baton Rouge North | K12: Baton Rouge South | L12: Gulf Coast North | M12: Gulf Coast West | N12: Lafayette | O12: NOLA North | P12: NOLA South
A13: NPS | C13: GCW | D13: Shop 847 Chris Wentworth | F13: 11 / 100% | J13: 1 | K13: 0 | L13: 0 | M13: 4 | N13: 3 | O13: 2 | P13: 4 | Q13: =SUM(J13:P13) -> 14
A14: Email Collection | C14: LAF | D14: Shop 728 Blaze Miller | F14: 0.835
A15: Pmix | C15: GCW | D15: Shop 283 Team | F15: 0.988 | J15: Donald | K15: Kelly | L15: Garrett | M15: Cole | N15: Des | O15: brandon | P15: james
A16: Big 4 | C16: LAF | D16: Shop 720 Kadarius Moss | F16: 0.707 | J16: Baton Rouge North | K16: Baton Rouge South | L16: Gulf Coast North | M16: Gulf Coast West | N16: Lafayette | O16: NOLA North | P16: NOLA South | Q16: Total DM given
A17: Fuel Filters | C17: BRN | D17: Shop 843 | F17: 1.2 | J17: 7 | K17: 7 | L17: 7 | M17: 7 | N17: 7 | O17: 7 | P17: 7 | Q17: 49
A18: Net ARO | C18: Nola S | D18: Shop 12 - Cory Brathbury | F18: 148
A19: Coolants | C19: NOla N | D19: Shop 32 Giovanni Morris | F19: 0.168
A20: Discounts | C20: LAF | D20: Shop 728 Blaze Miller | F20: 0.065
A21: Differentials | C21: LAF | D21: Shop 280 Jessica Simionis | F21: 0.066
A22: Donations | D22: Shop 5 | F22: 1021.5
A24: District Maanger Awards

Sheet P6 DM
A1: # | B1: Employee Name | C1: Shop # | D1: Position | E1: Given for | F1: Your Name | K1: Region recognition PPT
B2: Clyde Williamson IV | C2: 717 | D2: SM | E2: Highest Sales Beat - P6 | F2: Donald Roy
B3: Kirby Swan | C3: 22 | D3: SM | E3: Best KPI Performance - P6 | F3: Donald Roy
B4: Elisha Mcgee | C4: 843 | D4: SM | E4: Highest Fuel Filter % - P6 | F4: Donald Roy
B5: Djuan Fleming | C5: 881 | D5: SM | E5: Highest Comp Sales - P6 | F5: Donald Roy | K5: District shoutouts - intro movie only
B6: Clyde Williamson IV | C6: 717 | D6: SM | E6: District's #1 Power Ranker - P6 | F6: Donald Roy
B7: Carl Arnold | C7: 641 | D7: SM | E7: District's Highest Donations - P6 | F7: Donald Roy
B8: Diana Webb | C8: 641 | D8: Tech | E8: Highest Employee Score P6 | F8: Donald Roy
B9: Diana Webb | C9: 641 | D9: Tech | E9: Highest NPS w/ Most Oil Changes | F9: Donald Roy
B10: Jeremy Barrett | C10: 717 | D10: Tech | E10: 100% Prem Oil - P6 | F10: Donald Roy
B11: Tionna Hodges | C11: 22 | D11: Tech | E11: Highest ARO - P6 | F11: Donald Roy
B12: Allonzo Clark | C12: 17 | D12: ASM | E12: Highest Donations - P6 | F12: Donald Roy
B13: Tanner Billings | C13: 22 | D13: Tech | E13: Lowest Discounts - P6 | F13: Donald Roy
B14: Tionna Hodges | C14: 22 | D14: Tech | E14: Highest Coolant % - P6 | F14: Donald Roy
B15: Tionna Hodges | C15: 22 | D15: Tech | E15: Highest Big 4 - P6 | F15: Donald Roy
B16: Kerry Malveaux | C16: 975 | D16: SM | E16: Best KPI Performance - P6 | F16: Des Batiste
B17: Keith Sonnier | C17: 830 | D17: SM | E17: District's #1 Power Ranker - P6 | F17: Des Batiste
... B37: Kai Stanley | C37: 3 | D37: SM | E37: Top Sales vs Budget | F37: Garrett Gee
B38: Barnell Tatum | C38: 11 & 26 | D38: SM | E38: Top ARO $147.47 | F38: Garrett Gee
B39: Barnell Tatum | C39: 11 & 26 | D39: SM | E39: Top Coolants 11.9% | F39: Garrett Gee
B40: Kevin Arthur | C40: 21 | D40: SM | E40: Top Big-4 63.9% | F40: Garrett Gee
B41: Terrence Douglas | C41: 5 | D41: SM | E41: Top NPS 85% | F41: Garrett Gee
B42: Joe Jeanfreau | C42: 14 | D42: ASM | E42: Big-4 Performance 93.2% | F42: Garrett Gee
B43: Sharwood Harrison | C43: 11 | D43: ASM | E43: Big-4 Performance 90.7% | F43: Garrett Gee
B44: Giovanni Morris | C44: 32 | D44: SM | E44: $137.19 T/A | F44: Brandon Lange
B45: Rocky Carmadelle | C45: 606 | D45: SM | E45: 55% Fuel Filters | F45: Brandon Lange
B46: Jordan Bryant | C46: 32 | D46: ASM | E46: 4.6 Employee Performance Score | F46: Brandon Lange
B47: Hailey Higginbotham | C47: 4 | D47: Tech | E47: Highest T/A in district $153 | F47: Brandon Lange
B48: Justin Smith | C48: 4 | D48: Tech | E48: 100% NPS 12 surveys | F48: Brandon Lange
B49: Justin Smith | C49: 4 | D49: Tech | E49: 94% Big 4 on 233 writes | F49: Brandon Lange
B50: Taylor Harris | C50: 2 | D50: SM | E50: Helping Hand with District | F50: Brandon Lange
B51: Lake Charles Team | C51: 283 | D51: Techs | E51: Big-4 Performance 69.8% | F51: Cole Couvillion
... B53: Chris Wentworth | C53: 847 | D53: SM | E53: Top Sales vs Budget +26.5% | F53: Cole Couvillion

Sheet P7
A1: Gulf Coast Region Period 6 Winners
A2: KPI | C2: District | D2: Top Shop
A3: Over ALL (TOP TECH) | I3: District Manager instructions
A4: Power Ranker #1
A5: Power Ranker #2 | J5: Look to see how many slots you have and go to "tab" P4 DM to fill in your awards
A6: Power Ranker #3 | J6: Slots for D.M awards
J7: Baton Rouge North | K7: Baton Rouge South | L7: Gulf Coast North | M7: Gulf Coast West | N7: Lafayette | O7: NOLA North | P7: NOLA South
A8: Cars vs Budget | C8: GCW | J8: =J17-J13 -> 6 | K8: =K17-K13 -> 7 | L8: =L17-L13 -> 7 | M8: =M17-M13 -> 3 | N8: =N17-N13 -> 4 | O8: =O17-O13 -> 5 | P8: =P17-P13 -> 3 | Q8: 26
A9: cars vs comp | C9: GCW
A10: sales vs budget | C10: Nola S | J10: Correct Name and spelling for all your shop winners & confirm still employed
A11: sales vs comp | C11: NOLA N | J11: Shop and Tech KPI Winners
C12: District | D12: employee top spot | F12: Shop Top Spot | J12: Baton Rouge North | K12: Baton Rouge South | L12: Gulf Coast North | M12: Gulf Coast West | N12: Lafayette | O12: NOLA North | P12: NOLA South
A13: NPS | C13: GCW | J13: 1 | K13: 0 | L13: 0 | M13: 4 | N13: 3 | O13: 2 | P13: 4 | Q13: =SUM(J13:P13) -> 14
A14: Email Collection | C14: LAF
A15: Pmix | C15: GCW | J15: Donald | K15: Kelly | L15: Garrett | M15: Cole | N15: Des | O15: brandon | P15: james
A16: Big 4 | C16: LAF | J16: Baton Rouge North | K16: Baton Rouge South | L16: Gulf Coast North | M16: Gulf Coast West | N16: Lafayette | O16: NOLA North | P16: NOLA South | Q16: Total DM given
A17: Fuel Filters | C17: BRN | J17: 7 | K17: 7 | L17: 7 | M17: 7 | N17: 7 | O17: 7 | P17: 7 | Q17: 49
A18: Net ARO | C18: Nola S
A19: Coolants | C19: NOla N
A20: Discounts | C20: LAF
A21: Differentials | C21: LAF
A22: Donations
A24: District Maanger Awards

Sheet P7 DM (2)
A1: # | B1: Employee Name | C1: Shop # | D1: Position | E1: Given for | F1: Your Name
B2: Tionna Hodges | C2: 22 | E2: Region Winner Top ARO $175.85 | F2: Donald Roy
B3: Djuan Flemings | C3: 881 | D3: SM | E3: P7 Highest Comp Sales - District | F3: Donald Roy
B4: Kirby Swan | C4: 22 | D4: SM | E4: P7 90% Spoke W/ Manager - 81% NPS | F4: Donald Roy
F5: Donald Roy
F6: Donald Roy
F7: Donald Roy
F8: Donald Roy
B9: Davion C | C9: 19 | D9: ASM | E9: Region Winner Top Diffs @ 10% on 186 Changes | F9: Kelly ONeill
B10: Philip Ziegler | C10: 19 | D10: SM | E10: Region Winner Best Big 4 @ 62.4% | F10: Kelly ONeill
B11: Philip Ziegler | C11: 19 | D11: SM | E11: Region Winner Top FF @ 60% | F11: Kelly ONeill
B12: Philip Ziegler | C12: 19 | D12: SM | E12: Region Winner Top Coolants @ 13.2% | F12: Kelly ONeill
B13: Anthony Loyal | C13: 448 | D13: SM | E13: Disrict Power Ranker #1 | F13: Kelly ONeill
B14: Davion Coleman | C14: 19 | D14: ASM | E14: District Winner Highest NPS 100% | F14: Kelly ONeill
B15: Xavier Goldman | C15: 531 | D15: Tech | E15: District Employee Of The Month | F15: Kelly ONeill
B16: Kevin Arthur | C16: 21 | D16: SM | E16: District Winner Big-4 58.6% | F16: Garrett Gee
B17: Sharwood Harrison | C17: 11 | D17: SM | E17: District Winner Coolants 10.2% | F17: Garrett Gee
B18: Anthony Mury | C18: 24 | D18: SM | E18: Highest Qty. Diffs: 70 | F18: Garrett Gee
B19: Ash Wilcox | C19: 14 | D19: SM | E19: Best overall Performance | F19: Garrett Gee
B20: Shawn Goodman | C20: 23 | D20: SM | E20: District Winner Fuel Filters: 43.5% | F20: Garrett Gee
... B22: Kai Stanley | C22: 3 | D22: SM | E22: District Winner NPS: 92.3% | F22: Garrett Gee
B23: Trivia Slide
B24: Thaij James | C24: 720 | D24: CT | E24: Region Winner Best Discounts @ 4.6% | F24: Des Batiste
B25: Dylan Cormier | C25: 40 | D25: CT | E25: Region Winner Top Oil Changes @ 461 | F25: Des Batiste
B26: Brian Reyes | C26: 728 | D26: SM | E26: Region Winner Best Discounts @ 7.4 % | F26: Des Batiste
B27: Lakamion Franklin | C27: 40 | D27: SM | E27: Most Consistent on GSG | F27: Des Batiste
B28: Joseph Duplchein | C28: 975 | D28: ASM | E28: Top Big 4 in District 106% | F28: Des Batiste
B29: Kerry Malveaux | C29: 975 | D29: SM | E29: Best in Region | F29: Des Batiste
B30: Joseph Duplchein | C30: 975 | D30: ASM | E30: Employee of the Month P7 | F30: Des Batiste
B31: Logan Mooty | C31: 865 | D31: Lead Tech | E31: Region Winner Top Tech @ 4.8 | F31: Cole Couvillion
B32: Isaiah Davis | C32: 865 | D32: Lead Tech | E32: Region Winner Top NPS 100% 18 Surveys | F32: Cole Couvillion
B33: Jessie Clemmons | C33: 919 | D33: ASM | E33: Region Winner Big 4 99% on 152 Changes | F33: Cole Couvillion
B34: Amanda Hebert | C34: 865 | D34: ASM | E34: Region Winner Best Pmix @ 99% on 319 changes | F34: Cole Couvillion
B35: Logan Mooty | C35: 865 | D35: Lead Tech | E35: Region Winner Best Email @ 92% | F35: Cole Couvillion
... B39: Heather Roberts | C39: 865 | D39: SM | E39: Region Winner Top Email Collection | F39: Cole Couvillion
B40: Trivia Slide
B41: Taylor Harris | C41: 2 | D41: SM | E41: Regional Power Ranker #2 | F41: Brandon Lange
B42: Miguel Alix | C42: 4 | D42: SM | E42: Regional Power Ranker #3 | F42: Brandon Lange
B43: Miguel Alix | C43: 4 | D43: SM | E43: Region Winner Top Diffs @ 4.4% | F43: Brandon Lange
B44: Robert Mitchell | C44: 4 | D44: Lead | E44: Employee of the Month | F44: Brandon Lange
...

Sheet P8 DM
A1: # | B1: Employee Name | C1: Shop # | D1: Position | E1: Given for | F1: Your Name | H1: Birthdays | K1: Anniversaries
B2: Tionna Hodges | C2: 22 | E2: Region Winner Highest ARO $198.30 / 157 changes | F2: Donald Roy | H2: Name | I2: Shop | K2: Name | L2: Shop
B3: Raydrick Sterling | C3: 641 | E3: Region winner Lowest Discounts | F3: Donald Roy
B4: Tionna Hodges | C4: 22 | E4: Region Winner Highest Diff @ 10% | F4: Donald Roy | H4: Philip Ziegler | I4: 19 | K4: Ali Abdullahi (2 years) | L4: 6
B5: Djuan Flemings | C5: 881 | D5: SM | E5: Region Winner Highest Comp Sales @ 33.8% | F5: Donald Roy | H5: Calvin Singer | I5: 606 | K5: Claudell McDonald (1 year) | L5: 32
B6: Clyde Williamson IV | C6: 717 | D6: SM | E6: Region Winner Power Ranker #3 | F6: Donald Roy | H6: Tre Brown | I6: 1 | K6: Blaze Cole (2 years) | L6: 32
B7: Clyde Williamson IV & 717 | C7: 717 | D7: SM | E7: District Highest Donations .84 Cent per Car | F7: Donald Roy | H7: Lyzeal Marshall | I7: 2 | K7: Tyler Brand (3 years) | L7: 2
B8: Djuan Flemings | C8: 881 | D8: SM | E8: Best NPS 100% / 100% Spoke W Manager | F8: Donald Roy | H8: Emily Bradford | I8: 1 | K8: Marco Acosta (3 years) | L8: 1
B9: Philip Ziegler | C9: 19 | D9: SM | E9: Region Winner Highest Big 4 % | F9: Kelly ONeill | H9: Jamal Johnson | I9: 606 | K9: Keandre Broussard (1 year) | L9: 29
B10: Philip Ziegler | C10: 19 | D10: SM | E10: Region Winner Highest Coolant % 15.7% | F10: Kelly ONeill | H10: Brandon Lange | I10: DM | K10: Brandon Vega (4 Years) | L10: 92
B11: Rocke Chan | C11: 832 | D11: SM | E11: District Winner #1 Power Ranker | F11: Kelly ONeill | H11: Tyler Gilbert | I11: 283 | K11: Wade Lafont (3 Years) | L11: 13
B12: Russell Chambers | C12: 832 | D12: ASM | E12: District Winner Highest Coolant @ 14% | F12: Kelly ONeill | H12: Jerry Clark | I12: 3017 | K12: Thomas Hogan (2 Years) | L12: 10
B13: Davion Coleman | C13: 19 | D13: ASM | E13: District Winner Highest Big4 @ 81% | F13: Kelly ONeill | H13: Tyler Milton | I13: 3004 | K13: Dimitri Clark (2 Years) | L13: 8
B14: Anthony Loyal | C14: 448 | D14: SM | E14: District Winner - Sales Comp 17.7% & budget beat by 38 cars | F14: Kelly ONeill | H14: James Bourdier | I14: 870 | K14: Darrell Vaughn (1 Year) | L14: 116
B15: Leonard Johnson | C15: 282 | D15: SM | E15: District Winner Highest Big4 @ 62.1% | F15: Kelly ONeill | H15: Darrell Vaughn | I15: 116 | K15: James Bourdier (1 Year) | L15: 870
B16: Sharwood Harrison | C16: 11 | D16: SM | E16: #1 Power Rank | F16: Garrett Gee | H16: Wade Lafont | I16: 13 | K16: Scott Tillis (5 yrs) | L16: 21
B17: Sharwood Harrison | C17: 11 | D17: SM | E17: Best NPS: 93.3% | F17: Garrett Gee | H17: John Broussard Jr | I17: 92 | K17: Nate Nulia (1 yr) | L17: 24
B18: Jarod Waters | C18: 3 | D18: SM | E18: Highest Diffs - 5.9% | F18: Garrett Gee | H18: Scott Tillis | I18: 21 | K18: Ray Brown (2 yrs) | L18: 5
B19: Kevin Arthur | C19: 21 | D19: SM | E19: Highest Car Count: 1,911 | F19: Garrett Gee | H19: Marla Miller | I19: 14 | K19: Kirby Swan (2 years) | L19: 22
B20: Anthony Mury | C20: 24 | D20: SM | E20: #1 Fuel Filters: 39% | F20: Garrett Gee | H20: Jerremy Talbot | I20: 11
B21: Barnell Tatum and Sharwood Harrison | C21: 26/11 | D21: SM | E21: #1 in Coolants: 11% | F21: Garrett Gee | H21: Nathan Arbuckle | I21: 24
B22: Sharwood Harrison | C22: 11 | D22: SM | E22: #1 Big-4: 64.8% | F22: Garrett Gee | H22: Donald Roy | I22: DM
B23: Trivia Slide
B24: Brian Reyes | C24: 728 | D24: SM | E24: Region Winner Best Discounts @ 6.8% | F24: Des Batiste
B25: Brian Reyes | C25: 728 | D25: SM | E25: Most Improved Shop | F25: Des Batiste
B26: Kerry Malveaux | C26: 975 | D26: SM | E26: #1 in Power Rank in District | F26: Des Batiste | H26: Region Clubs
B27: Jessica Smionis | C27: 280 | D27: SM | E27: 100% drink score | F27: Des Batiste
B28: Tevin Archon | C28: 280 | D28: ASM | E28: Highest Diffs - 5.9% | F28: Des Batiste
F29: Des Batiste
F30: Des Batiste | H30: Shop Donations $2k Club | K30: NPS - 100%
B31: Yarr | C31: 919 | D31: ASM | E31: Region Winner Highest Coolant % 23% | F31: Cole Couvillion | H31: Name | I31: Amount | K31: Name | L31: Shop
B32: Heather Roberts | C32: 865 | D32: SM | E32: Region Winner Email Collection @ 78% | F32: Cole Couvillion | H32: Shop 4 - Miguel Alix | I32: 3173 | K32: Carl Arnold | L32: 641
B33: Heather Roberts | C33: 865 | D33: SM | E33: Region Winner Highest Budget Sales @ $13,287 | F33: Cole Couvillion | H33: Shop 92 - Brandon Vega | I33: 2676 | K33: Clyde Williamson IV | L33: 717
B34: Heather Roberts | C34: 865 | D34: SM | E34: Region Winner Best Cars Vs Budget @ +117 | F34: Cole Couvillion | H34: 5 - Terrence Douglas | I34: 2115 | K34: Djuan Flemings | L34: 881
B35: Heather Roberts | C35: 865 | D35: SM | E35: Region Winner Cars Vs LY @ +142 | F35: Cole Couvillion | H35: 6 - Ali Abdullahi | I35: 2085 | K35: Dee Kirst | L35: 447
B36: Chris Wentworth | C36: 847 | D36: SM | E36: Region Winner Power Ranker #1 | F36: Cole Couvillion | K36: Chris Wentworth | L36: 847
B37: Chris Webster | C37: 919 | D37: SM | E37: Helping Hand Training New SM @ 283 | F37: Cole Couvillion | K37: Cory Brathbury | L37: 12
F38: Cole Couvillion | H38: Shop Donations $5k Club
B39: Trivia Slide | H39: Name | I39: Amount
B40: Jordan Bryant | C40: 32 | D40: ASM | E40: Region Winner Highest NPS @100% on 16 Surveys | F40: Brandon Lange
...

Sheet P9 DM (2)
A1: # | B1: Employee Name | C1: Shop # | D1: Position | E1: Given for | F1: Your Name | H1: Birthdays | K1: Anniversaries | N1: Welcome to the Team
B2: Tionna Hodges | C2: 22 | D2: LT | E2: Region Winner Highest ARO $198.81 | F2: Donald Roy | H2: Name | I2: Shop | K2: Name | L2: Shop | N2: Name | O2: Shop
B3: Raydrick Sterling Termed | C3: 641 | E3: Region Winner Lowest Discounts @ 2 % | F3: Donald Roy | H3: Dragana Kirst | I3: 447 | K3: Rocke Chan 1 year | L3: 832 | N3: Jerry Clark | O3: 3017
B4: Tionna Hodges | C4: 22 | D4: LT | E4: Region Winner Highest Diff % @ 13% w/ 120 changes | F4: Donald Roy | H4: Kiley Clifton | I4: 18 | K4: Davion Coleman 1 year | L4: 19 | N4: Tyler Gilbert | O4: 283
B5: Carl Arnold | C5: 641 | D5: SM | E5: Region Winner Lowest Discounts @ 5.3 % | F5: Donald Roy | H5: Ray Brown | I5: 5 | K5: Jakoby Davis 1 year | L5: 975 | N5: Erroll Lane | O5: 8
B6: Djuan Fleming | C6: 881 | D6: SM | E6: Region Winner Highest Comp Sales @ 52.9% | F6: Donald Roy | H6: Brandon Smith | I6: 5 | K6: Kevin Arthur (14yrs) | L6: 21 | N6: Triston Snyder | O6: 3004
B7: Djuan Fleming | C7: 881 | D7: SM | E7: Region Winner Highest Car Comp @ 30% | F7: Donald Roy | H7: Matthew Alfred | I7: 5 | K7: Devin Lepine (2yrs) | L7: 14 | N7: Maya Ledet | O7: 12
F8: Donald Roy | H8: Kiffy Robinson | I8: 5 | K8: Camron Weeden (1yr) | L8: 11 | N8: Dylan Guidry | O8: 10
B9: Christian Broussard | C9: 531 | E9: Region Winner Highest Fuel Filters @ 75% | F9: Kelly ONeill | H9: Will Sours | I9: 20 | K9: Dameian McDonald (2yrs) | L9: 21 | N9: Nathaniel Quinones | O9: 31
B10: Leonard Johnson | C10: 282 | E10: District Winner Highest Big4% @ 63.3% | F10: Kelly ONeill | H10: Dameian McDonald | I10: 21 | K10: Tionna Hodges (1 yr) | L10: 22 | N10: Hudson Crotchet | O10: 12
B11: Philip Ziegler | C11: 19 | E11: District Winner Highest ARO @ $128.58 | F11: Kelly ONeill | H11: Anthony Walker | I11: 21 | K11: Djuan Fleming (3yrs) | L11: 717 | N11: Saeed Jamison | O11: 92
B12: Anthony Loyal | C12: 448 | E12: District Winner Highest Sales comp (11.8%) & Budegt (3.4%) P9 | F12: Kelly ONeill | H12: Breyden Magyar | I12: 26 | K12: Kenneth Elliot(4 years) | L12: 1 | N12: Trae Dakin | O12: 92
B13: Christian Broussard | C13: 531 | E13: District Winner Highest Coolant % @ 8.8% | F13: Kelly ONeill | H13: James Achee | I13: 26 | K13: Arselle Cameron(2 years) | L13: 28
B14: Glenn Vann | C14: 19 | E14: District Winner Employee of the Month P9 | F14: Kelly ONeill | H14: Djuan Fleming | I14: 717 | K14: Jay Bryant(1 year) | L14: 28
B15: Lance Green | C15: 531 | E15: District Winner Highest ARO @ $142.11 | F15: Kelly ONeill | H15: Jamaryon Tatney | I15: 881 | K15: Kasey Williams (2 Years) | L15: 870
B16: Sharwood Harrison | C16: 11 | E16: Region Winner highest Big4% @ 69.5% | F16: Garrett Gee | H16: Torrence Vance | I16: 881
B17: Jarod Water | C17: 3 | E17: Region Winner Highest Diff % @ 6.6% | F17: Garrett Gee | H17: Kenneth Elliot | I17: 1
B18: Joe Jeanfreau | C18: 14 | E18: NPS 95.5% | F18: Garrett Gee | H18: Trey King | I18: 6
B19: Terrence Douglas | C19: 5 | E19: 50% Fuel Filters | F19: Garrett Gee | H19: Ian Goebel | I19: 2
B20: Kevin Arthur | C20: 21 | E20: Highest Car count w/65.7% Big-4 | F20: Garrett Gee | H20: Tommy Lee Valerio | I20: 15
B21: Jarod Water | C21: 5 | E21: Best Sales vs Budget +2.5% | F21: Garrett Gee | H21: Adam Abadie | I21: 4
B22: Sharwood Harrison | C22: 11 | E22: #1 Power Rank | F22: Garrett Gee | H22: Paul Wilson | I22: 28
B23: Trivia Slide | H23: Jonathan Coleman | I23: 999
B24: Jerome Jackson | C24: 720 | D24: ASM | E24: Region Winner Most FF sold | F24: Des Batiste | H24: Josiyah Charles | I24: 999
B25: Thaij James | C25: 720 | D25: CT | E25: Region Winner Highest Pmix @ 99% w/232 changes | F25: Des Batiste | H25: Landry, Tyler | I25: 116
B26: Kerry Malveaux | C26: 975 | D26: SM | E26: Last Reported Claim over 90 days ago | F26: Des Batiste | H26: McCarter, Matthew | I26: 10
B27: Ty'Aaron Jenkins | C27: 830 | D27: CT | E27: Highest Coolant 11% | F27: Des Batiste | H27: Voisin, Ernest Junior | I27: 3004
B28: Jerome Jackson | C28: 720 | D28: ASM | E28: Highest Diffs 12% | F28: Des Batiste | H28: Breaux, Chance | I28: 116
B29: Tevin Archon | C29: 280 | D29: ASM | E29: 15 surveys 100% NPS | F29: Des Batiste | H29: Pulido, Simon | I29: 116
F30: Des Batiste | H30: Quinones, Nathaniel | I30: 31
B31: Amanda Hebert | C31: 865 | E31: Region Winner Highest NPS @ 100% W/26 surveys | F31: Cole Couvillion
B32: Tyler Gilbert | C32: 283 | E32: Region Winner Highest Pmix @ 98.5% | F32: Cole Couvillion
B33: Michael Rapp | C33: 954 | E33: Region Winner Highest ARO @ $149.50 | F33: Cole Couvillion
B34: Jason Wallmuth | C34: 46 | E34: Region Winner Highest Email Collection @ 79% | F34: Cole Couvillion
B35: Michael Rapp | C35: 954 | E35: Region Winner Highest sales Budget Beat P9 @ 15.7% | F35: Cole Couvillion
B36: Heather Robberts | C36: 865 | E36: Region Winner Highest cars budget Beat P9 @ +45 cars | F36: Cole Couvillion
B37: Chris Wentworth | C37: 847 | E37: Region Winner power Ranker #1 | F37: Cole Couvillion
B38: Chris Wentworth & Michael Rapp | C38: 847 & 954 | D38: SM | E38: Training Vidor Crew/ Shop Setup | F38: Cole Couvillion
B39: Trivia Slide
B40: Justin Smith | C40: 4 | D40: Lead | E40: Region Winner Highest Coolant Exchange @ 25% | F40: Brandon Lange
...

Sheet P10
A1: # | B1: Employee Name | C1: Shop # | D1: Position | E1: Given for | F1: Your Name | H1: Birthdays | K1: Anniversaries | N1: Welcome to the Team
B2: Tionna Hodges | C2: 22 | D2: LT | E2: Region Winner ARO @ $204.00 w/ 160 Changes | F2: Donald Roy | H2: Name | I2: Shop | K2: Name | L2: Shop | N2: Name | O2: Shop
B3: Blaine Gilmore | C3: 22 | D3: Lube | E3: Region winner Best Discounts @ $8.53 per car | F3: Donald Roy | H3: Kadarius Moss | I3: 720 | K3: Kasey Williams (2 Years) | L3: 870 | N3: Darrius Vallery | O3: 40
B4: Kirby Swan | C4: 22 | D4: SM | E4: District's Highest ARO $140 | F4: Donald Roy | H4: Brian Reyes | I4: 728 | K4: Barnell Tatum (2 Yrs) | L4: 26 | N4: Amar Johnson | O4: 40
B5: Carl Arnold | C5: 641 | D5: SM | E5: District's Highest Fuel Filters 52% | F5: Donald Roy | H5: McCarter, Matthew | I5: 10 | K5: Nathan Arbuckle (1yr) | L5: 24 | N5: Brennen Cole | O5: 29
B6: Allonzo Clark | C6: 641 | D6: ASM | E6: District Highest Coolant 39% | F6: Donald Roy | H6: Garcia-Jimenez, Tito | I6: 116 | K6: Hayden Smith (1yr) | L6: 22 | N6: Robinson, Khobe | O6: 92
B7: Dejontay Wings | C7: 17 | D7: LT | E7: District Highest NPS 100% | F7: Donald Roy | H7: Pulido, Simon | I7: 92 | K7: Miguel Alix (5 years) | L7: 4 | N7: Sonnier, Gage | O7: 116
B8: Calin Labbe | C8: 17 | D8: SM | E8: District Helping Hand | F8: Donald Roy | H8: Breaux, Chance | I8: 116 | K8: Robert Mitchell (1 year) | L8: 4 | N8: Anderson, Travon | O8: 13
B9: Leonard Johnson | C9: 282 | D9: SM | E9: District Winner Highest Big4 @ 58.9% | F9: Kelly ONeill | H9: Voisin, Ernest Junior | I9: 3004 | K9: Xavier Golden 1- Year | L9: 531 | N9: Whaley, Sidney | O9: 8
B10: Philip Ziegler | C10: 19 | D10: SM | E10: District Winner Highest Coolant % P10 @ 8.9% | F10: Kelly ONeill | H10: Quinones, Nathaniel | I10: 31 | N10: Garcia-Jimenez, Tito | O10: 116
B11: Christian Broussard | C11: 531 | D11: SM | E11: District Winner Highest Differentials P10 @ 4% | F11: Kelly ONeill | H11: Landry, Tyler | I11: 116 | N11: Guerin, Adriek | O11: 641
B12: Philip Ziegler | C12: 19 | D12: SM | E12: District Winner Highest ARO P10 @ $130.28 | F12: Kelly ONeill | H12: Jarod Waters | I12: 3 | N12: Banks, Terrance | O12: 3040
B13: Natiqua Johnson | C13: 18 | D13: ASM | E13: District Winner - Employee of the Month P10 | F13: Kelly ONeill | H13: Raven Williams | I13: 20 | N13: Cobb, Aaron | O13: 3040
B14: Charles Jones | C14: 19 | D14: Tech | E14: District Winner Highest ARO P10 @ $166.68 | F14: Kelly ONeill | H14: Michael Juneau | I14: 24 | N14: Gordon, Dragean | O14: 3040
B15: Ashland Gilliam | C15: 19 | D15: Lead | E15: District Winner Best NPS P10 @ 100% | F15: Kelly ONeill | H15: Malcom Moreau | I15: 11 | N15: Henry, Michael | O15: 641
B16: Sharwood Harrison | C16: 11 | E16: Region Winner Power Ranker # 3 | F16: Garrett Gee | H16: Marlon McDonaald | I16: 23
B17: Sharwood Harrison | C17: 11 | E17: Region Winner ARO @ $155.91 | F17: Garrett Gee | H17: Blake Dunaway | I17: 26
B18: Sharwood Harrison | C18: 11 | E18: Region winner Top Differentials @ 6.2% | F18: Garrett Gee | H18: Kirby Swan | I18: 22
B19: Joe Jeanfreau | C19: 14 | E19: #1 District Fuel Filters 61.5% | F19: Garrett Gee | H19: Hayden Smith | I19: 22
B20: Brandon Harris | C20: 20 | E20: #1 District NPS 88.9% | F20: Garrett Gee | H20: Rob Fonzo | I20: 1
B21: Jarod Waters / Justin Husser | C21: 3 | E21: Overall: Big-4 56.8%, 13.4% Coolants, $142.75 ARO, 2.7% Diffs, 94.9% P-Mix | F21: Garrett Gee | H21: Dee Funchess | I21: 4
B22: Kevin Arthur / Scott Tillis | C22: 21 | E22: Highest Qty. Cars (2,079) with 61.9% Big-4 and $128.97 ARO | F22: Garrett Gee | H22: Darrell Carter | I22: 999
H23: JoJo Ward | I23: 2
B24: Blaze Miller | C24: 599 | D24: SM | E24: Region Winner NPS 100% w/ 25 surveys | F24: Des Batiste | H24: Breanna Bechtol | I24: 2
B25: Thaij James | C25: 720 | D25: CT | E25: Region Winner BIG4 @ 101% w/311 changes | F25: Des Batiste | H25: Ali Bradberry | I25: 999
B26: Shantell Pickney | C26: 975 | D26: SM | E26: Promoted to SM | F26: Des Batiste | H26: Austin Hager | I26: 448
B27: Joseph Duplechain | C27: 280 | D27: SM | E27: Promoted to SM | F27: Des Batiste
B28: Lynda Laforge | C28: 975 | D28: LT | E28: Helping Hand | F28: Des Batiste
B29: Blaze Miller | C29: 599 | D29: SM | E29: EOM for October | F29: Des Batiste
B30: Jordan Savoy | C30: 830 | D30: CT | E30: 15.4% coolant | F30: Des Batiste
B31: Chris Wentworth | C31: 847 | E31: Region Winner Power Ranker # 1 | F31: Cole Couvillion
B32: Heather Roberts | C32: 865 | E32: Region Winner Cars vs Comp @ 9% | F32: Cole Couvillion
B33: Heather Roberts | C33: 865 | E33: Region Winner Car vs Budget @ 25 % | F33: Cole Couvillion
B34: Chris Wentworth | C34: 847 | E34: Region Winner Sales vs Budget @ 29.3% | F34: Cole Couvillion
B35: Joshua Strother | C35: 919 | E35: Region Winner 100 % NPS w/ 15 Surveys | F35: Cole Couvillion
B36: Chloe Hamilton | C36: 46 | E36: Region winner Email Collection @ 94% | F36: Cole Couvillion
B37: Jason Wallmuth | C37: 46 | E37: Region Winner Email Collection @ 79 % | F37: Cole Couvillion
B38: Amanda Hebert | C38: 865 | E38: Region Winner PMix @ 99% | F38: Cole Couvillion
B39: Tyler Gilbert | C39: 283 | E39: Region Winner Pmix @ 98.3% | F39: Cole Couvillion
B40: Chris Wentworth | C40: 847 | E40: Region winner Fuel Filters @ 76.9% | F40: Cole Couvillion
...
